Workbook

Sheet Data
A1: BookingID | B1: FlightDate | C1: Passenger | D1: Origin | E1: Destination | F1: Airline | G1: Class | H1: Fare | I1: DelayMinutes | J1: Status | L1: delay filter | M1: year | N1: quarter | O1: o-d
A2: 7000 | B2: 45785 | C2: Ishaan Rao | D2: Mumbai | E2: Delhi | F2: IndiGo | G2: Premium Economy | H2: 5001.29 | I2: 0 | J2: On Time | L2: =IF(J2="Delayed","yes","") | M2: =YEAR(B2) -> 2025 | N2: =ROUNDUP(MONTH(B2)/3,0) -> 2 | O2: =_xlfn.TEXTJOIN("-",,D2,E2) -> Mumbai-Delhi
A3: 7001 | B3: 45933 | C3: Diya Kapoor | D3: Delhi | E3: Goa | F3: AirAsia | G3: Business | H3: 13706.22 | I3: 0 | J3: On Time | L3: =IF(J3="Delayed","yes","") | M3: =YEAR(B3) -> 2025 | N3: =ROUNDUP(MONTH(B3)/3,0) -> 4 | O3: =_xlfn.TEXTJOIN("-",,D3,E3) -> Delhi-Goa
A4: 7002 | B4: 45768 | C4: Ananya Bose | D4: Kolkata | E4: Delhi | F4: Vistara | G4: Economy | H4: 4646.26 | I4: 0 | J4: On Time | L4: =IF(J4="Delayed","yes","") | M4: =YEAR(B4) -> 2025 | N4: =ROUNDUP(MONTH(B4)/3,0) -> 2 | O4: =_xlfn.TEXTJOIN("-",,D4,E4) -> Kolkata-Delhi
A5: 7003 | B5: 45749 | C5: Farhan Ali | D5: Mumbai | E5: Delhi | F5: AirAsia | G5: Business | H5: 11522.54 | I5: 0 | J5: On Time | L5: =IF(J5="Delayed","yes","") | M5: =YEAR(B5) -> 2025 | N5: =ROUNDUP(MONTH(B5)/3,0) -> 2 | O5: =_xlfn.TEXTJOIN("-",,D5,E5) -> Mumbai-Delhi
A6: 7004 | B6: 45702 | C6: Meera Pillai | D6: Chennai | E6: Hyderabad | F6: Vistara | G6: Economy | H6: 4870.82 | I6: 150 | J6: Delayed | L6: =IF(J6="Delayed","yes","") -> yes | M6: =YEAR(B6) -> 2025 | N6: =ROUNDUP(MONTH(B6)/3,0) -> 1 | O6: =_xlfn.TEXTJOIN("-",,D6,E6) -> Chennai-Hyderabad
A7: 7005 | B7: 45762 | C7: Tanvi Joshi | D7: Mumbai | E7: Delhi | F7: AirAsia | G7: Economy | H7: 2526.67 | I7: 0 | J7: On Time | L7: =IF(J7="Delayed","yes","") | M7: =YEAR(B7) -> 2025 | N7: =ROUNDUP(MONTH(B7)/3,0) -> 2 | O7: =_xlfn.TEXTJOIN("-",,D7,E7) -> Mumbai-Delhi
A8: 7006 | B8: 45894 | C8: Aarav Mehta | D8: Delhi | E8: Bangalore | F8: Vistara | G8: Premium Economy | H8: 5109.25 | I8: 0 | J8: On Time | L8: =IF(J8="Delayed","yes","") | M8: =YEAR(B8) -> 2025 | N8: =ROUNDUP(MONTH(B8)/3,0) -> 3 | O8: =_xlfn.TEXTJOIN("-",,D8,E8) -> Delhi-Bangalore
A9: 7007 | B9: 45884 | C9: Nisha Reddy | D9: Mumbai | E9: Chennai | F9: Air India | G9: Economy | H9: 5003.01 | I9: 0 | J9: Cancelled | L9: =IF(J9="Delayed","yes","") | M9: =YEAR(B9) -> 2025 | N9: =ROUNDUP(MONTH(B9)/3,0) -> 3 | O9: =_xlfn.TEXTJOIN("-",,D9,E9) -> Mumbai-Chennai
A10: 7008 | B10: 46008 | C10: Farhan Ali | D10: Mumbai | E10: Chennai | F10: SpiceJet | G10: Economy | H10: 3099.16 | I10: 0 | J10: On Time | L10: =IF(J10="Delayed","yes","") | M10: =YEAR(B10) -> 2025 | N10: =ROUNDUP(MONTH(B10)/3,0) -> 4 | O10: =_xlfn.TEXTJOIN("-",,D10,E10) -> Mumbai-Chennai
A11: 7009 | B11: 45974 | C11: Aarav Mehta | D11: Delhi | E11: Bangalore | F11: SpiceJet | G11: Premium Economy | H11: 4800.3 | I11: 0 | J11: On Time | L11: =IF(J11="Delayed","yes","") | M11: =YEAR(B11) -> 2025 | N11: =ROUNDUP(MONTH(B11)/3,0) -> 4 | O11: =_xlfn.TEXTJOIN("-",,D11,E11) -> Delhi-Bangalore
A12: 7010 | B12: 45686 | C12: Zara Khan | D12: Chennai | E12: Hyderabad | F12: Air India | G12: Economy | H12: 3202.78 | I12: 0 | J12: On Time | L12: =IF(J12="Delayed","yes","") | M12: =YEAR(B12) -> 2025 | N12: =ROUNDUP(MONTH(B12)/3,0) -> 1 | O12: =_xlfn.TEXTJOIN("-",,D12,E12) -> Chennai-Hyderabad
A13: 7011 | B13: 45722 | C13: Tanvi Joshi | D13: Kolkata | E13: Delhi | F13: SpiceJet | G13: Premium Economy | H13: 8620.75 | I13: 0 | J13: On Time | L13: =IF(J13="Delayed","yes","") | M13: =YEAR(B13) -> 2025 | N13: =ROUNDUP(MONTH(B13)/3,0) -> 1 | O13: =_xlfn.TEXTJOIN("-",,D13,E13) -> Kolkata-Delhi
... A126: 7124 | B126: 46018 | C126: Diya Kapoor | D126: Mumbai | E126: Delhi | F126: IndiGo | G126: Business | H126: 16578.3 | I126: 0 | J126: On Time | L126: =IF(J126="Delayed","yes","") | M126: =YEAR(B126) -> 2025 | N126: =ROUNDUP(MONTH(B126)/3,0) -> 4 | O126: =_xlfn.TEXTJOIN("-",,D126,E126) -> Mumbai-Delhi

Sheet Formula Test
A1: Airline Bookings Formula Test
A2: Use the Data sheet (rows 2-126) as your source. Write one formula per answer cell in column B. | E2: ans19
E3: {=_xlfn.UNIQUE(Data!F2:F126)} -> IndiGo | F3: =SUMIF(Data!F2:F126,'Formula Test'!E3,Data!H2:H126) -> 204763.24
A4: Q1. Total Fare collected from 'Business' class bookings on 'Vistara'. | B4: =SUMIFS(Data!H2:H126,Data!F2:F126,"Vistara",Data!G2:G126,"Business") -> 77082.08 | E4: AirAsia | F4: =SUMIF(Data!F3:F127,'Formula Test'!E4,Data!H3:H127) -> 187965.98
A5: Q2. Count of bookings with Status='Delayed' and DelayMinutes greater than 60. | B5: =COUNTIFS(Data!J2:J126,"Delayed",Data!I2:I126,">60") -> 22 | E5: Vistara | F5: =SUMIF(Data!F4:F128,'Formula Test'!E5,Data!H4:H128) -> 196624.98
A6: Q3. Look up the Destination for BookingID 7050, with a safe fallback if it isn't found. | B6: =_xlfn.XLOOKUP(7050,Data!A2:A126,Data!E2:E126,"null",0) -> Chennai | E6: Air India | F6: =SUMIF(Data!F5:F129,'Formula Test'!E6,Data!H5:H129) -> 146267.62
A7: Q4. Average Fare for 'Economy' class bookings from 'Delhi' to 'Mumbai'. | B7: =AVERAGEIFS(Data!H2:H126,Data!G2:G126,"Economy",Data!D2:D126,"Delhi",Data!E2:E126,"Mumbai") -> 4824.868 | E7: SpiceJet | F7: =SUMIF(Data!F6:F130,'Formula Test'!E7,Data!H6:H130) -> 209560.11
A8: Q5. Total fare revenue across the entire dataset for bookings with Status != 'Cancelled', without adding a helper column. | B8: =SUMIF(Data!J2:J126,"<>Cancelled",Data!H2:H126) -> 928035.25
A9: Q6. Classify BookingID 7000's delay as 'None' (DelayMinutes=0), 'Short' (1-60), or 'Long' (60+). | B9: =IF(Data!I2=0,"None",IF(Data!I2<=60,"Short","Long")) -> None
A10: Q7. Extract the month name and year (e.g. 'March 2025') from the FlightDate of BookingID 7010. | B10: =TEXT(Data!B12,"mmmm yyyy") -> January 2025
A11: Q8. Return the Fare where Origin='Mumbai' and Destination='Chennai', using an array-style match (no helper column). | B11: {=SUMPRODUCT((Data!D2:D126="Mumbai")*(Data!E2:E126="Chennai"),Data!H2:H126)} -> 214249.29 | D11: ans9 | E11: ref ans12 | F11: ans10
A12: Q9. Return a unique, alphabetically sorted list of all Airlines as a spilled array. | B12: done in right side | D12: {=_xlfn._xlws.SORT(_xlfn.UNIQUE(Data!F2:F126))} -> Air India | E12: =_xlfn.MAXIFS(Data!I2:I126,Data!F2:F126,'Formula Test'!D12,Data!J2:J126,"Delayed") -> 128 | F12: {=_xlfn._xlws.FILTER(Data!A2:A126,(Data!G2:G126="Business")*(Data!J2:J126="On Time"))} -> 7001
A13: Q10. Return all BookingIDs where Class='Business' AND Status='On Time', as a spilled array. | B13: done in right side | D13: AirAsia | E13: =_xlfn.MAXIFS(Data!I3:I127,Data!F3:F127,'Formula Test'!D13,Data!J3:J127,"Delayed") -> 139 | F13: 7003
A14: Q11. Count how many Passenger names contain 'Iyer' anywhere in the dataset. | B14: =COUNTIF(Data!C2:C126,"*Iyer*") -> 8 | D14: IndiGo | E14: =_xlfn.MAXIFS(Data!I4:I128,Data!F4:F128,'Formula Test'!D14,Data!J4:J128,"Delayed") -> 126 | F14: 7014
A15: Q12. Find the Airline with the highest total DelayMinutes among 'Delayed' bookings, using formulas only (no pivot table). | B15: =_xlfn.XLOOKUP(MAX(E12:E16),E12:E16,D12:D16) -> SpiceJet | D15: SpiceJet | E15: =_xlfn.MAXIFS(Data!I5:I129,Data!F5:F129,'Formula Test'!D15,Data!J5:J129,"Delayed") -> 175 | F15: 7017
A16: Q13. Calculate the total number of unique Passengers who flew 'Business' class. | B16: {=COUNTA(_xlfn.UNIQUE(_xlfn._xlws.FILTER(Data!C2:C126,Data!G2:G126="Business","null")))} -> 14 | D16: Vistara | E16: =_xlfn.MAXIFS(Data!I6:I130,Data!F6:F130,'Formula Test'!D16,Data!J6:J130,"Delayed") -> 152 | F16: 7021
A17: Q14. Find the second-highest Fare in the entire dataset. | B17: =LARGE(Data!H2:H126,2) -> 16578.3 | F17: 7037
A18: Q15. Return the Passenger name associated with the longest single delay on record. | B18: =_xlfn.XLOOKUP(MAX(E20:E34),E20:E34,D20:D34,"null",0) -> Devansh Shah | F18: 7041
A19: Q16. Count the number of bookings made in Q2 2025 (Apr-Jun). | B19: =COUNTIFS(Data!M2:M126,2025,Data!N2:N126,2) -> 32 | D19: ref ans15 | F19: 7050
A20: Q17. Calculate the percentage of bookings that were 'Cancelled'. | B20: =COUNTIF(Data!J2:J126,"Cancelled")/COUNTA(Data!J2:J126) -> 0.024 | D20: {=_xlfn.UNIQUE(Data!C2:C126)} -> Ishaan Rao | E20: =_xlfn.MAXIFS(Data!I2:I126,Data!C2:C126,'Formula Test'!D20) -> 138 | F20: 7052
A21: Q18. Return the most frequently flown route, shown as Origin-Destination (e.g. 'Delhi-Mumbai'). | B21: {=INDEX(Data!O2:O126,MATCH(MAX(COUNTIF(Data!O2:O126,Data!O2:O126)),COUNTIF(Data!O2:O126,Data!O2:O126),0))} -> Mumbai-Chennai | D21: Diya Kapoor | E21: =_xlfn.MAXIFS(Data!I3:I127,Data!C3:C127,'Formula Test'!D21) -> 103 | F21: 7060
A22: Q19. Find the total Fare generated by each Airline, broken out into a small 5-row summary table using formulas (not a pivot table). | B22: done in right side | D22: Ananya Bose | E22: =_xlfn.MAXIFS(Data!I4:I128,Data!C4:C128,'Formula Test'!D22) -> 82 | F22: 7061
A23: Q20. Extract just the day of the week (e.g. 'Monday') for the FlightDate of BookingID 7025. | B23: =TEXT(Data!B27,"dddd") -> Wednesday | D23: Farhan Ali | E23: =_xlfn.MAXIFS(Data!I5:I129,Data!C5:C129,'Formula Test'!D23) -> 88 | F23: 7063
A24: Q21. Return the average DelayMinutes for bookings with Fare greater than 5000. | B24: =AVERAGEIF(Data!H2:H126,">5000",Data!I2:I126) -> 21.736264 | D24: Meera Pillai | E24: =_xlfn.MAXIFS(Data!I6:I130,Data!C6:C130,'Formula Test'!D24) -> 174 | F24: 7064
A25: Q22. Find the Class that appears most often overall. | B25: {=INDEX(Data!G2:G126,MATCH(MAX(COUNTIF(Data!G2:G126,Data!G2:G126)),COUNTIF(Data!G2:G126,Data!G2:G126),0))} -> Economy | D25: Tanvi Joshi | E25: =_xlfn.MAXIFS(Data!I7:I131,Data!C7:C131,'Formula Test'!D25) -> 91 | F25: 7067
A26: Q23. Return the number of distinct Destinations flown to from 'Delhi'. | B26: {=COUNTA(_xlfn.UNIQUE(_xlfn._xlws.FILTER(Data!E2:E126,Data!D2:D126="Delhi")))} -> 3 | D26: Aarav Mehta | E26: =_xlfn.MAXIFS(Data!I8:I132,Data!C8:C132,'Formula Test'!D26) -> 110 | F26: 7072
A27: Q24. Calculate the total number of days between BookingID 7005's FlightDate and today's date. | B27: =DATEDIF(Data!B7,TODAY(),"D") -> 448 | D27: Nisha Reddy | E27: =_xlfn.MAXIFS(Data!I9:I133,Data!C9:C133,'Formula Test'!D27) -> 168 | F27: 7077
A28: Q25. Return TRUE or FALSE for whether every 'SpiceJet' booking has DelayMinutes under 100. | B28: {=SUMPRODUCT((Data!F2:F126="SpiceJet")*(Data!I2:I126>=100))=0} -> FALSE | D28: Zara Khan | E28: =_xlfn.MAXIFS(Data!I10:I134,Data!C10:C134,'Formula Test'!D28) -> 121 | F28: 7078
A29: Q26. Concatenate the Passenger name and Airline into a single string separated by a hyphen for BookingID 7015 (e.g. 'Aarav Mehta-IndiGo'). | B29: =_xlfn.TEXTJOIN("-",TRUE,Data!C17,Data!F17) -> Aarav Mehta-AirAsia | D29: Aditya Iyer | E29: =_xlfn.MAXIFS(Data!I11:I135,Data!C11:C135,'Formula Test'!D29) -> 152 | F29: 7081
A30: Q27. Find the earliest and latest FlightDate in the dataset, displayed as a single text string like 'Jan-2025 to Dec-2025'. | B30: =_xlfn.TEXTJOIN(" to ",TRUE,B34,B35) -> Jan-2025 to Dec-2025 | D30: Devansh Shah | E30: =_xlfn.MAXIFS(Data!I12:I136,Data!C12:C136,'Formula Test'!D30) -> 175 | F30: 7082
D31: Sanjay Verma | E31: =_xlfn.MAXIFS(Data!I13:I137,Data!C13:C137,'Formula Test'!D31) -> 128 | F31: 7085
D32: Rohan Gupta | E32: =_xlfn.MAXIFS(Data!I14:I138,Data!C14:C138,'Formula Test'!D32) -> 168 | F32: 7086
B33: ref ans27 | D33: Kavya Nair | E33: =_xlfn.MAXIFS(Data!I15:I139,Data!C15:C139,'Formula Test'!D33) -> 0 | F33: 7091
B34: =TEXT(MIN(Data!B2:B126),"mmm-yyyy") -> Jan-2025 | D34: Priyanka Rao | E34: =_xlfn.MAXIFS(Data!I16:I140,Data!C16:C140,'Formula Test'!D34) -> 0 | F34: 7092
B35: =TEXT(MAX(Data!B2:B126),"mmm-yyyy") -> Dec-2025 | F35: 7095
F36: 7098
F37: 7106
F38: 7109
F39: 7111
F40: 7112
...
