Workbook

Sheet Sales_Data
A1: Order_ID | B1: Order_Date | C1: Region | D1: Salesperson | E1: Customer | F1: Category | G1: Product | H1: Units | I1: Unit_Price | J1: Discount_% | K1: Sales | L1: Cost | M1: Profit | N1: Payment_Mode | O1: Delivery_Days | P1: Customer_Rating | Q1: rank | R1: product | S1: ans9 | T1: ans10 | AK1: ans12 | BC1: ans14 | BD1: ans19 | BE1: ans21 | BF1: ans23 | BG1: ans24 | BH1: ans25 | BI1: ans26 | BJ1: ans27 | BK1: ans28 | BL1: ans31 | BM1: ans32 | BN1: ans33 | CD1: ans41 | CE1: ans43 | CF1: ans46 | CG1: ans47 | CH1: ans48 | CI1: ans49
A2: 1002 | B2: 45533 | C2: West | D2: Rohan | E2: Customer_46 | F2: Electronics | G2: Phone | H2: 18 | I2: 33295 | J2: 20 | K2: 479448 | L2: 300270 | M2: 179178 | N2: Card | O2: 7 | P2: 4.3 | Q2: =RANK(M2,$M$2:$M$1000) -> 15 | R2: =_xlfn.XLOOKUP(A2,A:A,G:G,"") -> Phone | S2: =INDEX(D:D,MATCH($T$1,A:A,0)) -> #N/A | T2: {=_xlfn._xlws.FILTER(B2:R201,K2:K201>AVERAGE(K2:K201))} -> 45533 | U2: West | V2: Rohan | W2: Customer_46 | X2: Electronics | Y2: Phone | Z2: 18 | AA2: 33295 | AB2: 20 | AC2: 479448 | AD2: 300270 | AE2: 179178 | AF2: Card | AG2: 7 | AH2: 4.3 | AI2: 15 | AJ2: Phone | AK2: {=_xlfn._xlws.SORT(Sales_Data!A1:R201,13,-1)} -> Order_ID | AL2: Order_Date | AM2: Region | AN2: Salesperson | AO2: Customer | AP2: Category | AQ2: Product | AR2: Units | AS2: Unit_Price | AT2: Discount_% | AU2: Sales | AV2: Cost | AW2: Profit | AX2: Payment_Mode | AY2: Delivery_Days | AZ2: Customer_Rating | BA2: rank | BB2: product | BC2: =ROUND(MONTH(B2)/3,0) -> 3 | BD2: =IF(M2>100000,"Bonus!","") -> Bonus! | BE2: =_xlfn.LET(_xlpm.profit,M2,_xlpm.sales,K2,_xlpm.profit/_xlpm.sales) -> 0.37371727 | BF2: {=_xlfn._xlws.SORT(E2:E201,1,1)} -> Customer_1 | BG2: =_xlfn.TEXTJOIN("-",TRUE,C2,G2) -> West-Phone | BH2: =YEAR(B2) -> 2024 | BI2: =TEXT(B2,"mmmm") -> August | BJ2: =NETWORKDAYS(B2,TODAY()) -> 480 | BK2: =M2/K2 -> 0.37371727 | BL2: =_xlfn.XLOOKUP(G2,G:G,I:I,"",0) -> 33295 | BM2: =_xlfn.XMATCH(E2,E:E,0) -> 2 | BN2: {=_xlfn._xlws.FILTER(A1:P201,A1:A201<>"")} -> Order_ID | BO2: Order_Date | BP2: Region | BQ2: Salesperson | BR2: Customer | BS2: Category | BT2: Product | BU2: Units | BV2: Unit_Price | BW2: Discount_% | BX2: Sales | BY2: Cost | BZ2: Profit | CA2: Payment_Mode | CB2: Delivery_Days | CC2: Customer_Rating | CD2: =COUNTIF(Sales_Data!E:E,Sales_Data!E2)>1 -> TRUE | CE2: =SUM(Sales_Data!$K$2:'Sales_Data'!K2) -> 479448 | CF2: =K2*1.15 -> 551365.2 | CG2: =CHOOSE(MATCH(C2,{"North","West","South","East"},0),"Zone 1","Zone 2","Zone 3","Zone 4") -> Zone 2 | CH2: {=_xlfn.SWITCH(N2,"Card","Card Payment","UPI", "UPI Payment","Cash","Cash Payment","NetBanking", "NetBanking Payment", "Unknown")} -> Card Payment | CI2: {=_xlfn.IFS(Sales_Data!J2<=5,"Low",Sales_Data!J2<=10,"Medium",Sales_Data!J2>10,"High")} -> High
A3: 1003 | B3: 45298 | C3: South | D3: Karan | E3: Customer_49 | F3: Office Supplies | G3: Keyboard | H3: 11 | I3: 23829 | J3: 5 | K3: 249013.05 | L3: 170899.83 | M3: 78113.22 | N3: UPI | O3: 3 | P3: 4.7 | Q3: =RANK(M3,$M$2:$M$1000) -> 78 | R3: =_xlfn.XLOOKUP(A3,A:A,G:G,"") -> Keyboard | S3: =INDEX(D:D,MATCH($T$1,A:A,0)) -> #N/A | T3: 45298 | U3: South | V3: Karan | W3: Customer_49 | X3: Office Supplies | Y3: Keyboard | Z3: 11 | AA3: 23829 | AB3: 5 | AC3: 249013.05 | AD3: 170899.83 | AE3: 78113.22 | AF3: UPI | AG3: 3 | AH3: 4.7 | AI3: 78 | AJ3: Keyboard | AK3: 1071 | AL3: 45607 | AM3: North | AN3: Megha | AO3: Customer_30 | AP3: Electronics | AQ3: Keyboard | AR3: 20 | AS3: 38353 | AT3: 10 | AU3: 690354 | AV3: 395833.99 | AW3: 294520.01 | AX3: Cash | AY3: 8 | AZ3: 4.5 | BA3: 1 | BB3: Keyboard | BC3: =ROUND(MONTH(B3)/3,0) -> 0 | BD3: =IF(M3>100000,"Bonus!","") | BE3: =_xlfn.LET(_xlpm.profit,M3,_xlpm.sales,K3,_xlpm.profit/_xlpm.sales) -> 0.31369127 | BF3: Customer_1 | BG3: =_xlfn.TEXTJOIN("-",TRUE,C3,G3) -> South-Keyboard | BH3: =YEAR(B3) -> 2024 | BI3: =TEXT(B3,"mmmm") -> January | BJ3: =NETWORKDAYS(B3,TODAY()) -> 648 | BK3: =M3/K3 -> 0.31369127 | BL3: =_xlfn.XLOOKUP(G3,G:G,I:I,"",0) -> 23829 | BM3: =_xlfn.XMATCH(E3,E:E,0) -> 3 | BN3: 1002 | BO3: 45533 | BP3: West | BQ3: Rohan | BR3: Customer_46 | BS3: Electronics | BT3: Phone | BU3: 18 | BV3: 33295 | BW3: 20 | BX3: 479448 | BY3: 300270 | BZ3: 179178 | CA3: Card | CB3: 7 | CC3: 4.3 | CD3: =COUNTIF(Sales_Data!E:E,Sales_Data!E3)>1 -> TRUE | CE3: =SUM(Sales_Data!$K$2:'Sales_Data'!K3) -> 728461.05 | CF3: =K3*1.15 -> 286365.01 | CG3: =CHOOSE(MATCH(C3,{"North","West","South","East"},0),"Zone 1","Zone 2","Zone 3","Zone 4") -> Zone 3 | CH3: {=_xlfn.SWITCH(N3,"Card","Card Payment","UPI", "UPI Payment","Cash","Cash Payment","NetBanking", "NetBanking Payment", "Unknown")} -> UPI Payment | CI3: {=_xlfn.IFS(Sales_Data!J3<=5,"Low",Sales_Data!J3<=10,"Medium",Sales_Data!J3>10,"High")} -> Low
A4: 1004 | B4: 45442 | C4: South | D4: Arjun | E4: Customer_24 | F4: Office Supplies | G4: Desk | H4: 20 | I4: 13233 | J4: 20 | K4: 211728 | L4: 178596.79 | M4: 33131.21 | N4: UPI | O4: 10 | P4: 3.2 | Q4: =RANK(M4,$M$2:$M$1000) -> 127 | R4: =_xlfn.XLOOKUP(A4,A:A,G:G,"") -> Desk | S4: =INDEX(D:D,MATCH($T$1,A:A,0)) -> #N/A | T4: 45677 | U4: South | V4: Neha | W4: Customer_6 | X4: Electronics | Y4: Phone | Z4: 14 | AA4: 44162 | AB4: 15 | AC4: 525527.8 | AD4: 431802.75 | AE4: 93725.05 | AF4: UPI | AG4: 3 | AH4: 5 | AI4: 63 | AJ4: Phone | AK4: 1079 | AL4: 45526 | AM4: North | AN4: Arjun | AO4: Customer_7 | AP4: Furniture | AQ4: Printer | AR4: 20 | AS4: 49976 | AT4: 0 | AU4: 999520 | AV4: 718924.05 | AW4: 280595.95 | AX4: UPI | AY4: 1 | AZ4: 3.1 | BA4: 2 | BB4: Printer | BC4: =ROUND(MONTH(B4)/3,0) -> 2 | BD4: =IF(M4>100000,"Bonus!","") | BE4: =_xlfn.LET(_xlpm.profit,M4,_xlpm.sales,K4,_xlpm.profit/_xlpm.sales) -> 0.15648006 | BF4: Customer_10 | BG4: =_xlfn.TEXTJOIN("-",TRUE,C4,G4) -> South-Desk | BH4: =YEAR(B4) -> 2024 | BI4: =TEXT(B4,"mmmm") -> May | BJ4: =NETWORKDAYS(B4,TODAY()) -> 545 | BK4: =M4/K4 -> 0.15648006 | BL4: =_xlfn.XLOOKUP(G4,G:G,I:I,"",0) -> 13233 | BM4: =_xlfn.XMATCH(E4,E:E,0) -> 4 | BN4: 1003 | BO4: 45298 | BP4: South | BQ4: Karan | BR4: Customer_49 | BS4: Office Supplies | BT4: Keyboard | BU4: 11 | BV4: 23829 | BW4: 5 | BX4: 249013.05 | BY4: 170899.83 | BZ4: 78113.22 | CA4: UPI | CB4: 3 | CC4: 4.7 | CD4: =COUNTIF(Sales_Data!E:E,Sales_Data!E4)>1 -> FALSE | CE4: =SUM(Sales_Data!$K$2:'Sales_Data'!K4) -> 940189.05 | CF4: =K4*1.15 -> 243487.2 | CG4: =CHOOSE(MATCH(C4,{"North","West","South","East"},0),"Zone 1","Zone 2","Zone 3","Zone 4") -> Zone 3 | CH4: {=_xlfn.SWITCH(N4,"Card","Card Payment","UPI", "UPI Payment","Cash","Cash Payment","NetBanking", "NetBanking Payment", "Unknown")} -> UPI Payment | CI4: {=_xlfn.IFS(Sales_Data!J4<=5,"Low",Sales_Data!J4<=10,"Medium",Sales_Data!J4>10,"High")} -> High
A5: 1005 | B5: 45677 | C5: South | D5: Neha | E5: Customer_6 | F5: Electronics | G5: Phone | H5: 14 | I5: 44162 | J5: 15 | K5: 525527.8 | L5: 431802.75 | M5: 93725.05 | N5: UPI | O5: 3 | P5: 5 | Q5: =RANK(M5,$M$2:$M$1000) -> 63 | R5: =_xlfn.XLOOKUP(A5,A:A,G:G,"") -> Phone | S5: =INDEX(D:D,MATCH($T$1,A:A,0)) -> #N/A | T5: 45384 | U5: East | V5: Rohan | W5: Customer_36 | X5: Furniture | Y5: Laptop | Z5: 9 | AA5: 30283 | AB5: 10 | AC5: 245292.3 | AD5: 149179.91 | AE5: 96112.39 | AF5: Cash | AG5: 10 | AH5: 2.8 | AI5: 61 | AJ5: Laptop | AK5: 1078 | AL5: 45547 | AM5: North | AN5: Arjun | AO5: Customer_21 | AP5: Furniture | AQ5: Keyboard | AR5: 17 | AS5: 47832 | AT5: 15 | AU5: 691172.4 | AV5: 411242.55 | AW5: 279929.85 | AX5: Card | AY5: 2 | AZ5: 3.2 | BA5: 3 | BB5: Keyboard | BC5: =ROUND(MONTH(B5)/3,0) -> 0 | BD5: =IF(M5>100000,"Bonus!","") | BE5: =_xlfn.LET(_xlpm.profit,M5,_xlpm.sales,K5,_xlpm.profit/_xlpm.sales) -> 0.17834461 | BF5: Customer_10 | BG5: =_xlfn.TEXTJOIN("-",TRUE,C5,G5) -> South-Phone | BH5: =YEAR(B5) -> 2025 | BI5: =TEXT(B5,"mmmm") -> January | BJ5: =NETWORKDAYS(B5,TODAY()) -> 378 | BK5: =M5/K5 -> 0.17834461 | BL5: =_xlfn.XLOOKUP(G5,G:G,I:I,"",0) -> 33295 | BM5: =_xlfn.XMATCH(E5,E:E,0) -> 5 | BN5: 1004 | BO5: 45442 | BP5: South | BQ5: Arjun | BR5: Customer_24 | BS5: Office Supplies | BT5: Desk | BU5: 20 | BV5: 13233 | BW5: 20 | BX5: 211728 | BY5: 178596.79 | BZ5: 33131.21 | CA5: UPI | CB5: 10 | CC5: 3.2 | CD5: =COUNTIF(Sales_Data!E:E,Sales_Data!E5)>1 -> TRUE | CE5: =SUM(Sales_Data!$K$2:'Sales_Data'!K5) -> 1465716.9 | CF5: =K5*1.15 -> 604356.97 | CG5: =CHOOSE(MATCH(C5,{"North","West","South","East"},0),"Zone 1","Zone 2","Zone 3","Zone 4") -> Zone 3 | CH5: {=_xlfn.SWITCH(N5,"Card","Card Payment","UPI", "UPI Payment","Cash","Cash Payment","NetBanking", "NetBanking Payment", "Unknown")} -> UPI Payment | CI5: {=_xlfn.IFS(Sales_Data!J5<=5,"Low",Sales_Data!J5<=10,"Medium",Sales_Data!J5>10,"High")} -> High
A6: 1006 | B6: 45384 | C6: East | D6: Rohan | E6: Customer_36 | F6: Furniture | G6: Laptop | H6: 9 | I6: 30283 | J6: 10 | K6: 245292.3 | L6: 149179.91 | M6: 96112.39 | N6: Cash | O6: 10 | P6: 2.8 | Q6: =RANK(M6,$M$2:$M$1000) -> 61 | R6: =_xlfn.XLOOKUP(A6,A:A,G:G,"") -> Laptop | S6: =INDEX(D:D,MATCH($T$1,A:A,0)) -> #N/A | T6: 45496 | U6: East | V6: Karan | W6: Customer_46 | X6: Electronics | Y6: Keyboard | Z6: 18 | AA6: 22848 | AB6: 5 | AC6: 390700.8 | AD6: 234134.57 | AE6: 156566.23 | AF6: UPI | AG6: 4 | AH6: 3.9 | AI6: 23 | AJ6: Keyboard | AK6: 1157 | AL6: 45336 | AM6: North | AN6: Neha | AO6: Customer_47 | AP6: Furniture | AQ6: Monitor | AR6: 20 | AS6: 43635 | AT6: 5 | AU6: 829065 | AV6: 563160.05 | AW6: 265904.95 | AX6: UPI | AY6: 1 | AZ6: 4.8 | BA6: 4 | BB6: Monitor | BC6: =ROUND(MONTH(B6)/3,0) -> 1 | BD6: =IF(M6>100000,"Bonus!","") | BE6: =_xlfn.LET(_xlpm.profit,M6,_xlpm.sales,K6,_xlpm.profit/_xlpm.sales) -> 0.39182799 | BF6: Customer_10 | BG6: =_xlfn.TEXTJOIN("-",TRUE,C6,G6) -> East-Laptop | BH6: =YEAR(B6) -> 2024 | BI6: =TEXT(B6,"mmmm") -> April | BJ6: =NETWORKDAYS(B6,TODAY()) -> 587 | BK6: =M6/K6 -> 0.39182799 | BL6: =_xlfn.XLOOKUP(G6,G:G,I:I,"",0) -> 30283 | BM6: =_xlfn.XMATCH(E6,E:E,0) -> 6 | BN6: 1005 | BO6: 45677 | BP6: South | BQ6: Neha | BR6: Customer_6 | BS6: Electronics | BT6: Phone | BU6: 14 | BV6: 44162 | BW6: 15 | BX6: 525527.8 | BY6: 431802.75 | BZ6: 93725.05 | CA6: UPI | CB6: 3 | CC6: 5 | CD6: =COUNTIF(Sales_Data!E:E,Sales_Data!E6)>1 -> TRUE | CE6: =SUM(Sales_Data!$K$2:'Sales_Data'!K6) -> 1711009.2 | CF6: =K6*1.15 -> 282086.14 | CG6: =CHOOSE(MATCH(C6,{"North","West","South","East"},0),"Zone 1","Zone 2","Zone 3","Zone 4") -> Zone 4 | CH6: {=_xlfn.SWITCH(N6,"Card","Card Payment","UPI", "UPI Payment","Cash","Cash Payment","NetBanking", "NetBanking Payment", "Unknown")} -> Cash Payment | CI6: {=_xlfn.IFS(Sales_Data!J6<=5,"Low",Sales_Data!J6<=10,"Medium",Sales_Data!J6>10,"High")} -> Medium
A7: 1007 | B7: 45551 | C7: South | D7: Neha | E7: Customer_12 | F7: Furniture | G7: Keyboard | H7: 8 | I7: 24791 | J7: 5 | K7: 188411.6 | L7: 136789.64 | M7: 51621.96 | N7: UPI | O7: 2 | P7: 2.7 | Q7: =RANK(M7,$M$2:$M$1000) -> 106 | R7: =_xlfn.XLOOKUP(A7,A:A,G:G,"") -> Keyboard | S7: =INDEX(D:D,MATCH($T$1,A:A,0)) -> #N/A | T7: 45297 | U7: East | V7: Rohan | W7: Customer_20 | X7: Office Supplies | Y7: Monitor | Z7: 18 | AA7: 26687 | AB7: 0 | AC7: 480366 | AD7: 387524.91 | AE7: 92841.09 | AF7: NetBanking | AG7: 8 | AH7: 4.8 | AI7: 64 | AJ7: Monitor | AK7: 1063 | AL7: 45597 | AM7: East | AN7: Rohan | AO7: Customer_37 | AP7: Office Supplies | AQ7: Phone | AR7: 14 | AS7: 43915 | AT7: 10 | AU7: 553329 | AV7: 308406.04 | AW7: 244922.96 | AX7: Cash | AY7: 10 | AZ7: 3 | BA7: 5 | BB7: Phone | BC7: =ROUND(MONTH(B7)/3,0) -> 3 | BD7: =IF(M7>100000,"Bonus!","") | BE7: =_xlfn.LET(_xlpm.profit,M7,_xlpm.sales,K7,_xlpm.profit/_xlpm.sales) -> 0.27398504 | BF7: Customer_10 | BG7: =_xlfn.TEXTJOIN("-",TRUE,C7,G7) -> South-Keyboard | BH7: =YEAR(B7) -> 2024 | BI7: =TEXT(B7,"mmmm") -> September | BJ7: =NETWORKDAYS(B7,TODAY()) -> 468 | BK7: =M7/K7 -> 0.27398504 | BL7: =_xlfn.XLOOKUP(G7,G:G,I:I,"",0) -> 23829 | BM7: =_xlfn.XMATCH(E7,E:E,0) -> 7 | BN7: 1006 | BO7: 45384 | BP7: East | BQ7: Rohan | BR7: Customer_36 | BS7: Furniture | BT7: Laptop | BU7: 9 | BV7: 30283 | BW7: 10 | BX7: 245292.3 | BY7: 149179.91 | BZ7: 96112.39 | CA7: Cash | CB7: 10 | CC7: 2.8 | CD7: =COUNTIF(Sales_Data!E:E,Sales_Data!E7)>1 -> TRUE | CE7: =SUM(Sales_Data!$K$2:'Sales_Data'!K7) -> 1899420.8 | CF7: =K7*1.15 -> 216673.34 | CG7: =CHOOSE(MATCH(C7,{"North","West","South","East"},0),"Zone 1","Zone 2","Zone 3","Zone 4") -> Zone 3 | CH7: {=_xlfn.SWITCH(N7,"Card","Card Payment","UPI", "UPI Payment","Cash","Cash Payment","NetBanking", "NetBanking Payment", "Unknown")} -> UPI Payment | CI7: {=_xlfn.IFS(Sales_Data!J7<=5,"Low",Sales_Data!J7<=10,"Medium",Sales_Data!J7>10,"High")} -> Low
A8: 1008 | B8: 45643 | C8: South | D8: Sneha | E8: Customer_30 | F8: Furniture | G8: Chair | H8: 16 | I8: 4972 | J8: 15 | K8: 67619.2 | L8: 50347.29 | M8: 17271.91 | N8: Cash | O8: 10 | P8: 2.5 | Q8: =RANK(M8,$M$2:$M$1000) -> 153 | R8: =_xlfn.XLOOKUP(A8,A:A,G:G,"") -> Chair | S8: =INDEX(D:D,MATCH($T$1,A:A,0)) -> #N/A | T8: 45452 | U8: South | V8: Sneha | W8: Customer_44 | X8: Electronics | Y8: Monitor | Z8: 16 | AA8: 28272 | AB8: 10 | AC8: 407116.8 | AD8: 247249.79 | AE8: 159867.01 | AF8: UPI | AG8: 2 | AH8: 4.4 | AI8: 21 | AJ8: Monitor | AK8: 1148 | AL8: 45569 | AM8: West | AN8: Arjun | AO8: Customer_3 | AP8: Electronics | AQ8: Chair | AR8: 19 | AS8: 37146 | AT8: 10 | AU8: 635196.6 | AV8: 393954.8 | AW8: 241241.8 | AX8: NetBanking | AY8: 10 | AZ8: 3.5 | BA8: 6 | BB8: Chair | BC8: =ROUND(MONTH(B8)/3,0) -> 4 | BD8: =IF(M8>100000,"Bonus!","") | BE8: =_xlfn.LET(_xlpm.profit,M8,_xlpm.sales,K8,_xlpm.profit/_xlpm.sales) -> 0.25542908 | BF8: Customer_10 | BG8: =_xlfn.TEXTJOIN("-",TRUE,C8,G8) -> South-Chair | BH8: =YEAR(B8) -> 2024 | BI8: =TEXT(B8,"mmmm") -> December | BJ8: =NETWORKDAYS(B8,TODAY()) -> 402 | BK8: =M8/K8 -> 0.25542908 | BL8: =_xlfn.XLOOKUP(G8,G:G,I:I,"",0) -> 4972 | BM8: =_xlfn.XMATCH(E8,E:E,0) -> 8 | BN8: 1007 | BO8: 45551 | BP8: South | BQ8: Neha | BR8: Customer_12 | BS8: Furniture | BT8: Keyboard | BU8: 8 | BV8: 24791 | BW8: 5 | BX8: 188411.6 | BY8: 136789.64 | BZ8: 51621.96 | CA8: UPI | CB8: 2 | CC8: 2.7 | CD8: =COUNTIF(Sales_Data!E:E,Sales_Data!E8)>1 -> TRUE | CE8: =SUM(Sales_Data!$K$2:'Sales_Data'!K8) -> 1967040 | CF8: =K8*1.15 -> 77762.08 | CG8: =CHOOSE(MATCH(C8,{"North","West","South","East"},0),"Zone 1","Zone 2","Zone 3","Zone 4") -> Zone 3 | CH8: {=_xlfn.SWITCH(N8,"Card","Card Payment","UPI", "UPI Payment","Cash","Cash Payment","NetBanking", "NetBanking Payment", "Unknown")} -> Cash Payment | CI8: {=_xlfn.IFS(Sales_Data!J8<=5,"Low",Sales_Data!J8<=10,"Medium",Sales_Data!J8>10,"High")} -> High
A9: 1009 | B9: 45454 | C9: East | D9: Priya | E9: Customer_9 | F9: Office Supplies | G9: Printer | H9: 11 | I9: 1561 | J9: 0 | K9: 17171 | L9: 10429.29 | M9: 6741.71 | N9: Card | O9: 10 | P9: 4.6 | Q9: =RANK(M9,$M$2:$M$1000) -> 180 | R9: =_xlfn.XLOOKUP(A9,A:A,G:G,"") -> Printer | S9: =INDEX(D:D,MATCH($T$1,A:A,0)) -> #N/A | T9: 45437 | U9: South | V9: Megha | W9: Customer_42 | X9: Office Supplies | Y9: Laptop | Z9: 20 | AA9: 35904 | AB9: 0 | AC9: 718080 | AD9: 608494.75 | AE9: 109585.25 | AF9: Card | AG9: 8 | AH9: 3 | AI9: 50 | AJ9: Laptop | AK9: 1116 | AL9: 45729 | AM9: North | AN9: Aman | AO9: Customer_18 | AP9: Furniture | AQ9: Phone | AR9: 15 | AS9: 46801 | AT9: 10 | AU9: 631813.5 | AV9: 395768.98 | AW9: 236044.52 | AX9: NetBanking | AY9: 10 | AZ9: 4.6 | BA9: 7 | BB9: Phone | BC9: =ROUND(MONTH(B9)/3,0) -> 2 | BD9: =IF(M9>100000,"Bonus!","") | BE9: =_xlfn.LET(_xlpm.profit,M9,_xlpm.sales,K9,_xlpm.profit/_xlpm.sales) -> 0.39262186 | BF9: Customer_10 | BG9: =_xlfn.TEXTJOIN("-",TRUE,C9,G9) -> East-Printer | BH9: =YEAR(B9) -> 2024 | BI9: =TEXT(B9,"mmmm") -> June | BJ9: =NETWORKDAYS(B9,TODAY()) -> 537 | BK9: =M9/K9 -> 0.39262186 | BL9: =_xlfn.XLOOKUP(G9,G:G,I:I,"",0) -> 1561 | BM9: =_xlfn.XMATCH(E9,E:E,0) -> 9 | BN9: 1008 | BO9: 45643 | BP9: South | BQ9: Sneha | BR9: Customer_30 | BS9: Furniture | BT9: Chair | BU9: 16 | BV9: 4972 | BW9: 15 | BX9: 67619.2 | BY9: 50347.29 | BZ9: 17271.91 | CA9: Cash | CB9: 10 | CC9: 2.5 | CD9: =COUNTIF(Sales_Data!E:E,Sales_Data!E9)>1 -> TRUE | CE9: =SUM(Sales_Data!$K$2:'Sales_Data'!K9) -> 1984211 | CF9: =K9*1.15 -> 19746.65 | CG9: =CHOOSE(MATCH(C9,{"North","West","South","East"},0),"Zone 1","Zone 2","Zone 3","Zone 4") -> Zone 4 | CH9: {=_xlfn.SWITCH(N9,"Card","Card Payment","UPI", "UPI Payment","Cash","Cash Payment","NetBanking", "NetBanking Payment", "Unknown")} -> Card Payment | CI9: {=_xlfn.IFS(Sales_Data!J9<=5,"Low",Sales_Data!J9<=10,"Medium",Sales_Data!J9>10,"High")} -> Low
A10: 1010 | B10: 45678 | C10: West | D10: Sneha | E10: Customer_47 | F10: Electronics | G10: Keyboard | H10: 3 | I10: 41396 | J10: 0 | K10: 124188 | L10: 101799.16 | M10: 22388.84 | N10: UPI | O10: 10 | P10: 3.2 | Q10: =RANK(M10,$M$2:$M$1000) -> 143 | R10: =_xlfn.XLOOKUP(A10,A:A,G:G,"") -> Keyboard | S10: =INDEX(D:D,MATCH($T$1,A:A,0)) -> #N/A | T10: 45641 | U10: East | V10: Neha | W10: Customer_2 | X10: Office Supplies | Y10: Desk | Z10: 19 | AA10: 32255 | AB10: 15 | AC10: 520918.25 | AD10: 301104 | AE10: 219814.25 | AF10: Card | AG10: 2 | AH10: 3.6 | AI10: 9 | AJ10: Desk | AK10: 1158 | AL10: 45628 | AM10: West | AN10: Neha | AO10: Customer_48 | AP10: Office Supplies | AQ10: Keyboard | AR10: 16 | AS10: 48750 | AT10: 15 | AU10: 663000 | AV10: 433762.21 | AW10: 229237.79 | AX10: UPI | AY10: 9 | AZ10: 2.9 | BA10: 8 | BB10: Keyboard | BC10: =ROUND(MONTH(B10)/3,0) -> 0 | BD10: =IF(M10>100000,"Bonus!","") | BE10: =_xlfn.LET(_xlpm.profit,M10,_xlpm.sales,K10,_xlpm.profit/_xlpm.sales) -> 0.18028183 | BF10: Customer_11 | BG10: =_xlfn.TEXTJOIN("-",TRUE,C10,G10) -> West-Keyboard | BH10: =YEAR(B10) -> 2025 | BI10: =TEXT(B10,"mmmm") -> January | BJ10: =NETWORKDAYS(B10,TODAY()) -> 377 | BK10: =M10/K10 -> 0.18028183 | BL10: =_xlfn.XLOOKUP(G10,G:G,I:I,"",0) -> 23829 | BM10: =_xlfn.XMATCH(E10,E:E,0) -> 10 | BN10: 1009 | BO10: 45454 | BP10: East | BQ10: Priya | BR10: Customer_9 | BS10: Office Supplies | BT10: Printer | BU10: 11 | BV10: 1561 | BW10: 0 | BX10: 17171 | BY10: 10429.29 | BZ10: 6741.71 | CA10: Card | CB10: 10 | CC10: 4.6 | CD10: =COUNTIF(Sales_Data!E:E,Sales_Data!E10)>1 -> TRUE | CE10: =SUM(Sales_Data!$K$2:'Sales_Data'!K10) -> 2108399 | CF10: =K10*1.15 -> 142816.2 | CG10: =CHOOSE(MATCH(C10,{"North","West","South","East"},0),"Zone 1","Zone 2","Zone 3","Zone 4") -> Zone 2 | CH10: {=_xlfn.SWITCH(N10,"Card","Card Payment","UPI", "UPI Payment","Cash","Cash Payment","NetBanking", "NetBanking Payment", "Unknown")} -> UPI Payment | CI10: {=_xlfn.IFS(Sales_Data!J10<=5,"Low",Sales_Data!J10<=10,"Medium",Sales_Data!J10>10,"High")} -> Low
A11: 1011 | B11: 45496 | C11: East | D11: Karan | E11: Customer_46 | F11: Electronics | G11: Keyboard | H11: 18 | I11: 22848 | J11: 5 | K11: 390700.8 | L11: 234134.57 | M11: 156566.23 | N11: UPI | O11: 4 | P11: 3.9 | Q11: =RANK(M11,$M$2:$M$1000) -> 23 | R11: =_xlfn.XLOOKUP(A11,A:A,G:G,"") -> Keyboard | S11: =INDEX(D:D,MATCH($T$1,A:A,0)) -> #N/A | T11: 45673 | U11: North | V11: Karan | W11: Customer_9 | X11: Office Supplies | Y11: Laptop | Z11: 12 | AA11: 26572 | AB11: 10 | AC11: 286977.6 | AD11: 173032.5 | AE11: 113945.1 | AF11: UPI | AG11: 2 | AH11: 3.3 | AI11: 44 | AJ11: Laptop | AK11: 1021 | AL11: 45641 | AM11: East | AN11: Neha | AO11: Customer_2 | AP11: Office Supplies | AQ11: Desk | AR11: 19 | AS11: 32255 | AT11: 15 | AU11: 520918.25 | AV11: 301104 | AW11: 219814.25 | AX11: Card | AY11: 2 | AZ11: 3.6 | BA11: 9 | BB11: Desk | BC11: =ROUND(MONTH(B11)/3,0) -> 2 | BD11: =IF(M11>100000,"Bonus!","") -> Bonus! | BE11: =_xlfn.LET(_xlpm.profit,M11,_xlpm.sales,K11,_xlpm.profit/_xlpm.sales) -> 0.40073179 | BF11: Customer_11 | BG11: =_xlfn.TEXTJOIN("-",TRUE,C11,G11) -> East-Keyboard | BH11: =YEAR(B11) -> 2024 | BI11: =TEXT(B11,"mmmm") -> July | BJ11: =NETWORKDAYS(B11,TODAY()) -> 507 | BK11: =M11/K11 -> 0.40073179 | BL11: =_xlfn.XLOOKUP(G11,G:G,I:I,"",0) -> 23829 | BM11: =_xlfn.XMATCH(E11,E:E,0) -> 2 | BN11: 1010 | BO11: 45678 | BP11: West | BQ11: Sneha | BR11: Customer_47 | BS11: Electronics | BT11: Keyboard | BU11: 3 | BV11: 41396 | BW11: 0 | BX11: 124188 | BY11: 101799.16 | BZ11: 22388.84 | CA11: UPI | CB11: 10 | CC11: 3.2 | CD11: =COUNTIF(Sales_Data!E:E,Sales_Data!E11)>1 -> TRUE | CE11: =SUM(Sales_Data!$K$2:'Sales_Data'!K11) -> 2499099.8 | CF11: =K11*1.15 -> 449305.92 | CG11: =CHOOSE(MATCH(C11,{"North","West","South","East"},0),"Zone 1","Zone 2","Zone 3","Zone 4") -> Zone 4 | CH11: {=_xlfn.SWITCH(N11,"Card","Card Payment","UPI", "UPI Payment","Cash","Cash Payment","NetBanking", "NetBanking Payment", "Unknown")} -> UPI Payment | CI11: {=_xlfn.IFS(Sales_Data!J11<=5,"Low",Sales_Data!J11<=10,"Medium",Sales_Data!J11>10,"High")} -> Low
A12: 1012 | B12: 45297 | C12: East | D12: Rohan | E12: Customer_20 | F12: Office Supplies | G12: Monitor | H12: 18 | I12: 26687 | J12: 0 | K12: 480366 | L12: 387524.91 | M12: 92841.09 | N12: NetBanking | O12: 8 | P12: 4.8 | Q12: =RANK(M12,$M$2:$M$1000) -> 64 | R12: =_xlfn.XLOOKUP(A12,A:A,G:G,"") -> Monitor | S12: =INDEX(D:D,MATCH($T$1,A:A,0)) -> #N/A | T12: 45659 | U12: East | V12: Megha | W12: Customer_46 | X12: Electronics | Y12: Monitor | Z12: 19 | AA12: 15090 | AB12: 15 | AC12: 243703.5 | AD12: 165570.76 | AE12: 78132.74 | AF12: Cash | AG12: 6 | AH12: 3.8 | AI12: 77 | AJ12: Monitor | AK12: 1196 | AL12: 45609 | AM12: North | AN12: Sneha | AO12: Customer_29 | AP12: Office Supplies | AQ12: Printer | AR12: 19 | AS12: 28176 | AT12: 10 | AU12: 481809.6 | AV12: 270221.41 | AW12: 211588.19 | AX12: Card | AY12: 1 | AZ12: 3.4 | BA12: 10 | BB12: Printer | BC12: =ROUND(MONTH(B12)/3,0) -> 0 | BD12: =IF(M12>100000,"Bonus!","") | BE12: =_xlfn.LET(_xlpm.profit,M12,_xlpm.sales,K12,_xlpm.profit/_xlpm.sales) -> 0.19327157 | BF12: Customer_11 | BG12: =_xlfn.TEXTJOIN("-",TRUE,C12,G12) -> East-Monitor | BH12: =YEAR(B12) -> 2024 | BI12: =TEXT(B12,"mmmm") -> January | BJ12: =NETWORKDAYS(B12,TODAY()) -> 648 | BK12: =M12/K12 -> 0.19327157 | BL12: =_xlfn.XLOOKUP(G12,G:G,I:I,"",0) -> 26687 | BM12: =_xlfn.XMATCH(E12,E:E,0) -> 12 | BN12: 1011 | BO12: 45496 | BP12: East | BQ12: Karan | BR12: Customer_46 | BS12: Electronics | BT12: Keyboard | BU12: 18 | BV12: 22848 | BW12: 5 | BX12: 390700.8 | BY12: 234134.57 | BZ12: 156566.23 | CA12: UPI | CB12: 4 | CC12: 3.9 | CD12: =COUNTIF(Sales_Data!E:E,Sales_Data!E12)>1 -> TRUE | CE12: =SUM(Sales_Data!$K$2:'Sales_Data'!K12) -> 2979465.8 | CF12: =K12*1.15 -> 552420.9 | CG12: =CHOOSE(MATCH(C12,{"North","West","South","East"},0),"Zone 1","Zone 2","Zone 3","Zone 4") -> Zone 4 | CH12: {=_xlfn.SWITCH(N12,"Card","Card Payment","UPI", "UPI Payment","Cash","Cash Payment","NetBanking", "NetBanking Payment", "Unknown")} -> NetBanking Payment | CI12: {=_xlfn.IFS(Sales_Data!J12<=5,"Low",Sales_Data!J12<=10,"Medium",Sales_Data!J12>10,"High")} -> Low
A13: 1013 | B13: 45452 | C13: South | D13: Sneha | E13: Customer_44 | F13: Electronics | G13: Monitor | H13: 16 | I13: 28272 | J13: 10 | K13: 407116.8 | L13: 247249.79 | M13: 159867.01 | N13: UPI | O13: 2 | P13: 4.4 | Q13: =RANK(M13,$M$2:$M$1000) -> 21 | R13: =_xlfn.XLOOKUP(A13,A:A,G:G,"") -> Monitor | S13: =INDEX(D:D,MATCH($T$1,A:A,0)) -> #N/A | T13: 45472 | U13: East | V13: Megha | W13: Customer_43 | X13: Office Supplies | Y13: Printer | Z13: 7 | AA13: 42639 | AB13: 15 | AC13: 253702.05 | AD13: 153492.84 | AE13: 100209.21 | AF13: UPI | AG13: 1 | AH13: 2.8 | AI13: 58 | AJ13: Printer | AK13: 1051 | AL13: 45336 | AM13: West | AN13: Arjun | AO13: Customer_49 | AP13: Furniture | AQ13: Desk | AR13: 14 | AS13: 42463 | AT13: 0 | AU13: 594482 | AV13: 387207.02 | AW13: 207274.98 | AX13: Card | AY13: 10 | AZ13: 4.2 | BA13: 11 | BB13: Desk | BC13: =ROUND(MONTH(B13)/3,0) -> 2 | BD13: =IF(M13>100000,"Bonus!","") -> Bonus! | BE13: =_xlfn.LET(_xlpm.profit,M13,_xlpm.sales,K13,_xlpm.profit/_xlpm.sales) -> 0.39268095 | BF13: Customer_11 | BG13: =_xlfn.TEXTJOIN("-",TRUE,C13,G13) -> South-Monitor | BH13: =YEAR(B13) -> 2024 | BI13: =TEXT(B13,"mmmm") -> June | BJ13: =NETWORKDAYS(B13,TODAY()) -> 538 | BK13: =M13/K13 -> 0.39268095 | BL13: =_xlfn.XLOOKUP(G13,G:G,I:I,"",0) -> 26687 | BM13: =_xlfn.XMATCH(E13,E:E,0) -> 13 | BN13: 1012 | BO13: 45297 | BP13: East | BQ13: Rohan | BR13: Customer_20 | BS13: Office Supplies | BT13: Monitor | BU13: 18 | BV13: 26687 | BW13: 0 | BX13: 480366 | BY13: 387524.91 | BZ13: 92841.09 | CA13: NetBanking | CB13: 8 | CC13: 4.8 | CD13: =COUNTIF(Sales_Data!E:E,Sales_Data!E13)>1 -> TRUE | CE13: =SUM(Sales_Data!$K$2:'Sales_Data'!K13) -> 3386582.5 | CF13: =K13*1.15 -> 468184.32 | CG13: =CHOOSE(MATCH(C13,{"North","West","South","East"},0),"Zone 1","Zone 2","Zone 3","Zone 4") -> Zone 3 | CH13: {=_xlfn.SWITCH(N13,"Card","Card Payment","UPI", "UPI Payment","Cash","Cash Payment","NetBanking", "NetBanking Payment", "Unknown")} -> UPI Payment | CI13: {=_xlfn.IFS(Sales_Data!J13<=5,"Low",Sales_Data!J13<=10,"Medium",Sales_Data!J13>10,"High")} -> Medium
A14: 1014 | B14: 45596 | C14: North | D14: Aman | E14: Customer_28 | F14: Electronics | G14: Chair | H14: 14 | I14: 4749 | J14: 0 | K14: 66486 | L14: 48246.49 | M14: 18239.51 | N14: NetBanking | O14: 9 | P14: 3.9 | Q14: =RANK(M14,$M$2:$M$1000) -> 152 | R14: =_xlfn.XLOOKUP(A14,A:A,G:G,"") -> Chair | S14: =INDEX(D:D,MATCH($T$1,A:A,0)) -> #N/A | T14: 45632 | U14: South | V14: Priya | W14: Customer_29 | X14: Electronics | Y14: Mouse | Z14: 17 | AA14: 41775 | AB14: 20 | AC14: 568140 | AD14: 366802.83 | AE14: 201337.17 | AF14: NetBanking | AG14: 10 | AH14: 2.9 | AI14: 12 | AJ14: Mouse | AK14: 1029 | AL14: 45632 | AM14: South | AN14: Priya | AO14: Customer_29 | AP14: Electronics | AQ14: Mouse | AR14: 17 | AS14: 41775 | AT14: 20 | AU14: 568140 | AV14: 366802.83 | AW14: 201337.17 | AX14: NetBanking | AY14: 10 | AZ14: 2.9 | BA14: 12 | BB14: Mouse | BC14: =ROUND(MONTH(B14)/3,0) -> 3 | BD14: =IF(M14>100000,"Bonus!","") | BE14: =_xlfn.LET(_xlpm.profit,M14,_xlpm.sales,K14,_xlpm.profit/_xlpm.sales) -> 0.2743361 | BF14: Customer_11 | BG14: =_xlfn.TEXTJOIN("-",TRUE,C14,G14) -> North-Chair | BH14: =YEAR(B14) -> 2024 | BI14: =TEXT(B14,"mmmm") -> October | BJ14: =NETWORKDAYS(B14,TODAY()) -> 435 | BK14: =M14/K14 -> 0.2743361 | BL14: =_xlfn.XLOOKUP(G14,G:G,I:I,"",0) -> 4972 | BM14: =_xlfn.XMATCH(E14,E:E,0) -> 14 | BN14: 1013 | BO14: 45452 | BP14: South | BQ14: Sneha | BR14: Customer_44 | BS14: Electronics | BT14: Monitor | BU14: 16 | BV14: 28272 | BW14: 10 | BX14: 407116.8 | BY14: 247249.79 | BZ14: 159867.01 | CA14: UPI | CB14: 2 | CC14: 4.4 | CD14: =COUNTIF(Sales_Data!E:E,Sales_Data!E14)>1 -> TRUE | CE14: =SUM(Sales_Data!$K$2:'Sales_Data'!K14) -> 3453068.5 | CF14: =K14*1.15 -> 76458.9 | CG14: =CHOOSE(MATCH(C14,{"North","West","South","East"},0),"Zone 1","Zone 2","Zone 3","Zone 4") -> Zone 1 | CH14: {=_xlfn.SWITCH(N14,"Card","Card Payment","UPI", "UPI Payment","Cash","Cash Payment","NetBanking", "NetBanking Payment", "Unknown")} -> NetBanking Payment | CI14: {=_xlfn.IFS(Sales_Data!J14<=5,"Low",Sales_Data!J14<=10,"Medium",Sales_Data!J14>10,"High")} -> Low
... A89: 1089 | B89: 45455 | C89: South | D89: Sneha | E89: Customer_19 | F89: Office Supplies | G89: Desk | H89: 15 | I89: 20264 | J89: 5 | K89: 288762 | L89: 224577.69 | M89: 64184.31 | N89: UPI | O89: 7 | P89: 3.6 | Q89: =RANK(M89,$M$2:$M$1000) -> 89 | R89: =_xlfn.XLOOKUP(A89,A:A,G:G,"") -> Desk | S89: =INDEX(D:D,MATCH($T$1,A:A,0)) -> #N/A | T89: 45293 | U89: North | V89: Arjun | W89: Customer_40 | X89: Furniture | Y89: Laptop | Z89: 8 | AA89: 44578 | AB89: 5 | AC89: 338792.8 | AD89: 213119.97 | AE89: 125672.83 | AF89: Cash | AG89: 2 | AH89: 3.9 | AI89: 38 | AJ89: Laptop | AK89: 1040 | AL89: 45787 | AM89: East | AN89: Arjun | AO89: Customer_12 | AP89: Office Supplies | AQ89: Printer | AR89: 16 | AS89: 9791 | AT89: 5 | AU89: 148823.2 | AV89: 84389.31 | AW89: 64433.89 | AX89: NetBanking | AY89: 9 | AZ89: 4.1 | BA89: 87 | BB89: Printer | BC89: =ROUND(MONTH(B89)/3,0) -> 2 | BD89: =IF(M89>100000,"Bonus!","") | BE89: =_xlfn.LET(_xlpm.profit,M89,_xlpm.sales,K89,_xlpm.profit/_xlpm.sales) -> 0.22227409 | BF89: Customer_31 | BG89: =_xlfn.TEXTJOIN("-",TRUE,C89,G89) -> South-Desk | BH89: =YEAR(B89) -> 2024 | BI89: =TEXT(B89,"mmmm") -> June | BJ89: =NETWORKDAYS(B89,TODAY()) -> 536 | BK89: =M89/K89 -> 0.22227409 | BL89: =_xlfn.XLOOKUP(G89,G:G,I:I,"",0) -> 13233 | BM89: =_xlfn.XMATCH(E89,E:E,0) -> 64 | BN89: 1088 | BO89: 45305 | BP89: South | BQ89: Aman | BR89: Customer_40 | BS89: Furniture | BT89: Chair | BU89: 8 | BV89: 4175 | BW89: 10 | BX89: 30060 | BY89: 18851.76 | BZ89: 11208.24 | CA89: Card | CB89: 6 | CC89: 2.5 | CD89: =COUNTIF(Sales_Data!E:E,Sales_Data!E89)>1 -> TRUE | CE89: =SUM(Sales_Data!$K$2:'Sales_Data'!K89) -> 22998440 | CF89: =K89*1.15 -> 332076.3 | CG89: =CHOOSE(MATCH(C89,{"North","West","South","East"},0),"Zone 1","Zone 2","Zone 3","Zone 4") -> Zone 3 | CH89: {=_xlfn.SWITCH(N89,"Card","Card Payment","UPI", "UPI Payment","Cash","Cash Payment","NetBanking", "NetBanking Payment", "Unknown")} -> UPI Payment | CI89: {=_xlfn.IFS(Sales_Data!J89<=5,"Low",Sales_Data!J89<=10,"Medium",Sales_Data!J89>10,"High")} -> Low
A90: 1090 | B90: 45365 | C90: West | D90: Arjun | E90: Customer_26 | F90: Electronics | G90: Mouse | H90: 2 | I90: 38916 | J90: 15 | K90: 66157.2 | L90: 41074.91 | M90: 25082.29 | N90: UPI | O90: 3 | P90: 3.1 | Q90: =RANK(M90,$M$2:$M$1000) -> 137 | R90: =_xlfn.XLOOKUP(A90,A:A,G:G,"") -> Mouse | S90: =INDEX(D:D,MATCH($T$1,A:A,0)) -> #N/A | AK90: 1195 | AL90: 45590 | AM90: East | AN90: Megha | AO90: Customer_34 | AP90: Electronics | AQ90: Monitor | AR90: 6 | AS90: 45030 | AT90: 10 | AU90: 243162 | AV90: 178779.53 | AW90: 64382.47 | AX90: Cash | AY90: 1 | AZ90: 4.7 | BA90: 88 | BB90: Monitor | BC90: =ROUND(MONTH(B90)/3,0) -> 1 | BD90: =IF(M90>100000,"Bonus!","") | BE90: =_xlfn.LET(_xlpm.profit,M90,_xlpm.sales,K90,_xlpm.profit/_xlpm.sales) -> 0.37913167 | BF90: Customer_31 | BG90: =_xlfn.TEXTJOIN("-",TRUE,C90,G90) -> West-Mouse | BH90: =YEAR(B90) -> 2024 | BI90: =TEXT(B90,"mmmm") -> March | BJ90: =NETWORKDAYS(B90,TODAY()) -> 600 | BK90: =M90/K90 -> 0.37913167 | BL90: =_xlfn.XLOOKUP(G90,G:G,I:I,"",0) -> 41775 | BM90: =_xlfn.XMATCH(E90,E:E,0) -> 28 | BN90: 1089 | BO90: 45455 | BP90: South | BQ90: Sneha | BR90: Customer_19 | BS90: Office Supplies | BT90: Desk | BU90: 15 | BV90: 20264 | BW90: 5 | BX90: 288762 | BY90: 224577.69 | BZ90: 64184.31 | CA90: UPI | CB90: 7 | CC90: 3.6 | CD90: =COUNTIF(Sales_Data!E:E,Sales_Data!E90)>1 -> TRUE | CE90: =SUM(Sales_Data!$K$2:'Sales_Data'!K90) -> 23064597 | CF90: =K90*1.15 -> 76080.78 | CG90: =CHOOSE(MATCH(C90,{"North","West","South","East"},0),"Zone 1","Zone 2","Zone 3","Zone 4") -> Zone 2 | CH90: {=_xlfn.SWITCH(N90,"Card","Card Payment","UPI", "UPI Payment","Cash","Cash Payment","NetBanking", "NetBanking Payment", "Unknown")} -> UPI Payment | CI90: {=_xlfn.IFS(Sales_Data!J90<=5,"Low",Sales_Data!J90<=10,"Medium",Sales_Data!J90>10,"High")} -> High
A91: 1091 | B91: 45342 | C91: West | D91: Arjun | E91: Customer_15 | F91: Electronics | G91: Chair | H91: 7 | I91: 48661 | J91: 20 | K91: 272501.6 | L91: 214275.98 | M91: 58225.62 | N91: Card | O91: 3 | P91: 2.6 | Q91: =RANK(M91,$M$2:$M$1000) -> 96 | R91: =_xlfn.XLOOKUP(A91,A:A,G:G,"") -> Chair | S91: =INDEX(D:D,MATCH($T$1,A:A,0)) -> #N/A | AK91: 1089 | AL91: 45455 | AM91: South | AN91: Sneha | AO91: Customer_19 | AP91: Office Supplies | AQ91: Desk | AR91: 15 | AS91: 20264 | AT91: 5 | AU91: 288762 | AV91: 224577.69 | AW91: 64184.31 | AX91: UPI | AY91: 7 | AZ91: 3.6 | BA91: 89 | BB91: Desk | BC91: =ROUND(MONTH(B91)/3,0) -> 1 | BD91: =IF(M91>100000,"Bonus!","") | BE91: =_xlfn.LET(_xlpm.profit,M91,_xlpm.sales,K91,_xlpm.profit/_xlpm.sales) -> 0.21367075 | BF91: Customer_32 | BG91: =_xlfn.TEXTJOIN("-",TRUE,C91,G91) -> West-Chair | BH91: =YEAR(B91) -> 2024 | BI91: =TEXT(B91,"mmmm") -> February | BJ91: =NETWORKDAYS(B91,TODAY()) -> 617 | BK91: =M91/K91 -> 0.21367075 | BL91: =_xlfn.XLOOKUP(G91,G:G,I:I,"",0) -> 4972 | BM91: =_xlfn.XMATCH(E91,E:E,0) -> 33 | BN91: 1090 | BO91: 45365 | BP91: West | BQ91: Arjun | BR91: Customer_26 | BS91: Electronics | BT91: Mouse | BU91: 2 | BV91: 38916 | BW91: 15 | BX91: 66157.2 | BY91: 41074.91 | BZ91: 25082.29 | CA91: UPI | CB91: 3 | CC91: 3.1 | CD91: =COUNTIF(Sales_Data!E:E,Sales_Data!E91)>1 -> TRUE | CE91: =SUM(Sales_Data!$K$2:'Sales_Data'!K91) -> 23337099 | CF91: =K91*1.15 -> 313376.84 | CG91: =CHOOSE(MATCH(C91,{"North","West","South","East"},0),"Zone 1","Zone 2","Zone 3","Zone 4") -> Zone 2 | CH91: {=_xlfn.SWITCH(N91,"Card","Card Payment","UPI", "UPI Payment","Cash","Cash Payment","NetBanking", "NetBanking Payment", "Unknown")} -> Card Payment | CI91: {=_xlfn.IFS(Sales_Data!J91<=5,"Low",Sales_Data!J91<=10,"Medium",Sales_Data!J91>10,"High")} -> High
A92: 1092 | B92: 45593 | C92: North | D92: Neha | E92: Customer_16 | F92: Furniture | G92: Desk | H92: 3 | I92: 19438 | J92: 0 | K92: 58314 | L92: 35974.64 | M92: 22339.36 | N92: Card | O92: 3 | P92: 4.6 | Q92: =RANK(M92,$M$2:$M$1000) -> 144 | R92: =_xlfn.XLOOKUP(A92,A:A,G:G,"") -> Desk | S92: =INDEX(D:D,MATCH($T$1,A:A,0)) -> #N/A | AK92: 1075 | AL92: 45699 | AM92: North | AN92: Megha | AO92: Customer_40 | AP92: Office Supplies | AQ92: Laptop | AR92: 10 | AS92: 33386 | AT92: 20 | AU92: 267088 | AV92: 202959.66 | AW92: 64128.34 | AX92: UPI | AY92: 2 | AZ92: 2.8 | BA92: 90 | BB92: Laptop | BC92: =ROUND(MONTH(B92)/3,0) -> 3 | BD92: =IF(M92>100000,"Bonus!","") | BE92: =_xlfn.LET(_xlpm.profit,M92,_xlpm.sales,K92,_xlpm.profit/_xlpm.sales) -> 0.38308742 | BF92: Customer_32 | BG92: =_xlfn.TEXTJOIN("-",TRUE,C92,G92) -> North-Desk | BH92: =YEAR(B92) -> 2024 | BI92: =TEXT(B92,"mmmm") -> October | BJ92: =NETWORKDAYS(B92,TODAY()) -> 438 | BK92: =M92/K92 -> 0.38308742 | BL92: =_xlfn.XLOOKUP(G92,G:G,I:I,"",0) -> 13233 | BM92: =_xlfn.XMATCH(E92,E:E,0) -> 92 | BN92: 1091 | BO92: 45342 | BP92: West | BQ92: Arjun | BR92: Customer_15 | BS92: Electronics | BT92: Chair | BU92: 7 | BV92: 48661 | BW92: 20 | BX92: 272501.6 | BY92: 214275.98 | BZ92: 58225.62 | CA92: Card | CB92: 3 | CC92: 2.6 | CD92: =COUNTIF(Sales_Data!E:E,Sales_Data!E92)>1 -> TRUE | CE92: =SUM(Sales_Data!$K$2:'Sales_Data'!K92) -> 23395413 | CF92: =K92*1.15 -> 67061.1 | CG92: =CHOOSE(MATCH(C92,{"North","West","South","East"},0),"Zone 1","Zone 2","Zone 3","Zone 4") -> Zone 1 | CH92: {=_xlfn.SWITCH(N92,"Card","Card Payment","UPI", "UPI Payment","Cash","Cash Payment","NetBanking", "NetBanking Payment", "Unknown")} -> Card Payment | CI92: {=_xlfn.IFS(Sales_Data!J92<=5,"Low",Sales_Data!J92<=10,"Medium",Sales_Data!J92>10,"High")} -> Low
A93: 1093 | B93: 45480 | C93: North | D93: Aman | E93: Customer_42 | F93: Furniture | G93: Desk | H93: 19 | I93: 16452 | J93: 20 | K93: 250070.4 | L93: 209692.45 | M93: 40377.95 | N93: NetBanking | O93: 1 | P93: 3.2 | Q93: =RANK(M93,$M$2:$M$1000) -> 122 | R93: =_xlfn.XLOOKUP(A93,A:A,G:G,"") -> Desk | S93: =INDEX(D:D,MATCH($T$1,A:A,0)) -> #N/A | AK93: 1190 | AL93: 45582 | AM93: South | AN93: Sneha | AO93: Customer_11 | AP93: Office Supplies | AQ93: Phone | AR93: 6 | AS93: 38939 | AT93: 15 | AU93: 198588.9 | AV93: 135305.46 | AW93: 63283.44 | AX93: UPI | AY93: 6 | AZ93: 3.2 | BA93: 91 | BB93: Phone | BC93: =ROUND(MONTH(B93)/3,0) -> 2 | BD93: =IF(M93>100000,"Bonus!","") | BE93: =_xlfn.LET(_xlpm.profit,M93,_xlpm.sales,K93,_xlpm.profit/_xlpm.sales) -> 0.16146633 | BF93: Customer_32 | BG93: =_xlfn.TEXTJOIN("-",TRUE,C93,G93) -> North-Desk | BH93: =YEAR(B93) -> 2024 | BI93: =TEXT(B93,"mmmm") -> July | BJ93: =NETWORKDAYS(B93,TODAY()) -> 518 | BK93: =M93/K93 -> 0.16146633 | BL93: =_xlfn.XLOOKUP(G93,G:G,I:I,"",0) -> 13233 | BM93: =_xlfn.XMATCH(E93,E:E,0) -> 19 | BN93: 1092 | BO93: 45593 | BP93: North | BQ93: Neha | BR93: Customer_16 | BS93: Furniture | BT93: Desk | BU93: 3 | BV93: 19438 | BW93: 0 | BX93: 58314 | BY93: 35974.64 | BZ93: 22339.36 | CA93: Card | CB93: 3 | CC93: 4.6 | CD93: =COUNTIF(Sales_Data!E:E,Sales_Data!E93)>1 -> TRUE | CE93: =SUM(Sales_Data!$K$2:'Sales_Data'!K93) -> 23645483 | CF93: =K93*1.15 -> 287580.96 | CG93: =CHOOSE(MATCH(C93,{"North","West","South","East"},0),"Zone 1","Zone 2","Zone 3","Zone 4") -> Zone 1 | CH93: {=_xlfn.SWITCH(N93,"Card","Card Payment","UPI", "UPI Payment","Cash","Cash Payment","NetBanking", "NetBanking Payment", "Unknown")} -> NetBanking Payment | CI93: {=_xlfn.IFS(Sales_Data!J93<=5,"Low",Sales_Data!J93<=10,"Medium",Sales_Data!J93>10,"High")} -> High
A94: 1094 | B94: 45517 | C94: North | D94: Arjun | E94: Customer_17 | F94: Electronics | G94: Keyboard | H94: 13 | I94: 22612 | J94: 5 | K94: 279258.2 | L94: 168584.77 | M94: 110673.43 | N94: NetBanking | O94: 6 | P94: 2.8 | Q94: =RANK(M94,$M$2:$M$1000) -> 49 | R94: =_xlfn.XLOOKUP(A94,A:A,G:G,"") -> Keyboard | S94: =INDEX(D:D,MATCH($T$1,A:A,0)) -> #N/A | AK94: 1133 | AL94: 45431 | AM94: West | AN94: Rohan | AO94: Customer_30 | AP94: Furniture | AQ94: Mouse | AR94: 16 | AS94: 13036 | AT94: 10 | AU94: 187718.4 | AV94: 125240.8 | AW94: 62477.6 | AX94: Card | AY94: 8 | AZ94: 4.8 | BA94: 92 | BB94: Mouse | BC94: =ROUND(MONTH(B94)/3,0) -> 3 | BD94: =IF(M94>100000,"Bonus!","") -> Bonus! | BE94: =_xlfn.LET(_xlpm.profit,M94,_xlpm.sales,K94,_xlpm.profit/_xlpm.sales) -> 0.39631219 | BF94: Customer_32 | BG94: =_xlfn.TEXTJOIN("-",TRUE,C94,G94) -> North-Keyboard | BH94: =YEAR(B94) -> 2024 | BI94: =TEXT(B94,"mmmm") -> August | BJ94: =NETWORKDAYS(B94,TODAY()) -> 492 | BK94: =M94/K94 -> 0.39631219 | BL94: =_xlfn.XLOOKUP(G94,G:G,I:I,"",0) -> 23829 | BM94: =_xlfn.XMATCH(E94,E:E,0) -> 94 | BN94: 1093 | BO94: 45480 | BP94: North | BQ94: Aman | BR94: Customer_42 | BS94: Furniture | BT94: Desk | BU94: 19 | BV94: 16452 | BW94: 20 | BX94: 250070.4 | BY94: 209692.45 | BZ94: 40377.95 | CA94: NetBanking | CB94: 1 | CC94: 3.2 | CD94: =COUNTIF(Sales_Data!E:E,Sales_Data!E94)>1 -> FALSE | CE94: =SUM(Sales_Data!$K$2:'Sales_Data'!K94) -> 23924741 | CF94: =K94*1.15 -> 321146.93 | CG94: =CHOOSE(MATCH(C94,{"North","West","South","East"},0),"Zone 1","Zone 2","Zone 3","Zone 4") -> Zone 1 | CH94: {=_xlfn.SWITCH(N94,"Card","Card Payment","UPI", "UPI Payment","Cash","Cash Payment","NetBanking", "NetBanking Payment", "Unknown")} -> NetBanking Payment | CI94: {=_xlfn.IFS(Sales_Data!J94<=5,"Low",Sales_Data!J94<=10,"Medium",Sales_Data!J94>10,"High")} -> Low
A95: 1095 | B95: 45617 | C95: East | D95: Neha | E95: Customer_13 | F95: Office Supplies | G95: Keyboard | H95: 13 | I95: 33311 | J95: 20 | K95: 346434.4 | L95: 238485.76 | M95: 107948.64 | N95: UPI | O95: 1 | P95: 4.9 | Q95: =RANK(M95,$M$2:$M$1000) -> 52 | R95: =_xlfn.XLOOKUP(A95,A:A,G:G,"") -> Keyboard | S95: =INDEX(D:D,MATCH($T$1,A:A,0)) -> #N/A | AK95: 1171 | AL95: 45314 | AM95: East | AN95: Priya | AO95: Customer_29 | AP95: Electronics | AQ95: Printer | AR95: 9 | AS95: 16370 | AT95: 5 | AU95: 139963.5 | AV95: 78551.74 | AW95: 61411.76 | AX95: Card | AY95: 3 | AZ95: 3.2 | BA95: 93 | BB95: Printer | BC95: =ROUND(MONTH(B95)/3,0) -> 4 | BD95: =IF(M95>100000,"Bonus!","") -> Bonus! | BE95: =_xlfn.LET(_xlpm.profit,M95,_xlpm.sales,K95,_xlpm.profit/_xlpm.sales) -> 0.31159908 | BF95: Customer_32 | BG95: =_xlfn.TEXTJOIN("-",TRUE,C95,G95) -> East-Keyboard | BH95: =YEAR(B95) -> 2024 | BI95: =TEXT(B95,"mmmm") -> November | BJ95: =NETWORKDAYS(B95,TODAY()) -> 420 | BK95: =M95/K95 -> 0.31159908 | BL95: =_xlfn.XLOOKUP(G95,G:G,I:I,"",0) -> 23829 | BM95: =_xlfn.XMATCH(E95,E:E,0) -> 27 | BN95: 1094 | BO95: 45517 | BP95: North | BQ95: Arjun | BR95: Customer_17 | BS95: Electronics | BT95: Keyboard | BU95: 13 | BV95: 22612 | BW95: 5 | BX95: 279258.2 | BY95: 168584.77 | BZ95: 110673.43 | CA95: NetBanking | CB95: 6 | CC95: 2.8 | CD95: =COUNTIF(Sales_Data!E:E,Sales_Data!E95)>1 -> TRUE | CE95: =SUM(Sales_Data!$K$2:'Sales_Data'!K95) -> 24271176 | CF95: =K95*1.15 -> 398399.56 | CG95: =CHOOSE(MATCH(C95,{"North","West","South","East"},0),"Zone 1","Zone 2","Zone 3","Zone 4") -> Zone 4 | CH95: {=_xlfn.SWITCH(N95,"Card","Card Payment","UPI", "UPI Payment","Cash","Cash Payment","NetBanking", "NetBanking Payment", "Unknown")} -> UPI Payment | CI95: {=_xlfn.IFS(Sales_Data!J95<=5,"Low",Sales_Data!J95<=10,"Medium",Sales_Data!J95>10,"High")} -> High
A96: 1096 | B96: 45400 | C96: West | D96: Karan | E96: Customer_48 | F96: Furniture | G96: Printer | H96: 3 | I96: 26245 | J96: 10 | K96: 70861.5 | L96: 57066.53 | M96: 13794.97 | N96: Card | O96: 7 | P96: 4.1 | Q96: =RANK(M96,$M$2:$M$1000) -> 162 | R96: =_xlfn.XLOOKUP(A96,A:A,G:G,"") -> Printer | S96: =INDEX(D:D,MATCH($T$1,A:A,0)) -> #N/A | AK96: 1104 | AL96: 45500 | AM96: South | AN96: Aman | AO96: Customer_49 | AP96: Electronics | AQ96: Desk | AR96: 11 | AS96: 27318 | AT96: 20 | AU96: 240398.4 | AV96: 180570.62 | AW96: 59827.78 | AX96: Cash | AY96: 10 | AZ96: 2.9 | BA96: 94 | BB96: Desk | BC96: =ROUND(MONTH(B96)/3,0) -> 1 | BD96: =IF(M96>100000,"Bonus!","") | BE96: =_xlfn.LET(_xlpm.profit,M96,_xlpm.sales,K96,_xlpm.profit/_xlpm.sales) -> 0.19467511 | BF96: Customer_32 | BG96: =_xlfn.TEXTJOIN("-",TRUE,C96,G96) -> West-Printer | BH96: =YEAR(B96) -> 2024 | BI96: =TEXT(B96,"mmmm") -> April | BJ96: =NETWORKDAYS(B96,TODAY()) -> 575 | BK96: =M96/K96 -> 0.19467511 | BL96: =_xlfn.XLOOKUP(G96,G:G,I:I,"",0) -> 1561 | BM96: =_xlfn.XMATCH(E96,E:E,0) -> 96 | BN96: 1095 | BO96: 45617 | BP96: East | BQ96: Neha | BR96: Customer_13 | BS96: Office Supplies | BT96: Keyboard | BU96: 13 | BV96: 33311 | BW96: 20 | BX96: 346434.4 | BY96: 238485.76 | BZ96: 107948.64 | CA96: UPI | CB96: 1 | CC96: 4.9 | CD96: =COUNTIF(Sales_Data!E:E,Sales_Data!E96)>1 -> TRUE | CE96: =SUM(Sales_Data!$K$2:'Sales_Data'!K96) -> 24342037 | CF96: =K96*1.15 -> 81490.725 | CG96: =CHOOSE(MATCH(C96,{"North","West","South","East"},0),"Zone 1","Zone 2","Zone 3","Zone 4") -> Zone 2 | CH96: {=_xlfn.SWITCH(N96,"Card","Card Payment","UPI", "UPI Payment","Cash","Cash Payment","NetBanking", "NetBanking Payment", "Unknown")} -> Card Payment | CI96: {=_xlfn.IFS(Sales_Data!J96<=5,"Low",Sales_Data!J96<=10,"Medium",Sales_Data!J96>10,"High")} -> Medium
A97: 1097 | B97: 45581 | C97: West | D97: Aman | E97: Customer_30 | F97: Electronics | G97: Phone | H97: 9 | I97: 46174 | J97: 15 | K97: 353231.1 | L97: 286805.19 | M97: 66425.91 | N97: Cash | O97: 9 | P97: 4.9 | Q97: =RANK(M97,$M$2:$M$1000) -> 86 | R97: =_xlfn.XLOOKUP(A97,A:A,G:G,"") -> Phone | S97: =INDEX(D:D,MATCH($T$1,A:A,0)) -> #N/A | AK97: 1159 | AL97: 45435 | AM97: East | AN97: Neha | AO97: Customer_30 | AP97: Office Supplies | AQ97: Monitor | AR97: 9 | AS97: 34301 | AT97: 0 | AU97: 308709 | AV97: 249532.93 | AW97: 59176.07 | AX97: Card | AY97: 5 | AZ97: 4.6 | BA97: 95 | BB97: Monitor | BC97: =ROUND(MONTH(B97)/3,0) -> 3 | BD97: =IF(M97>100000,"Bonus!","") | BE97: =_xlfn.LET(_xlpm.profit,M97,_xlpm.sales,K97,_xlpm.profit/_xlpm.sales) -> 0.18805227 | BF97: Customer_33 | BG97: =_xlfn.TEXTJOIN("-",TRUE,C97,G97) -> West-Phone | BH97: =YEAR(B97) -> 2024 | BI97: =TEXT(B97,"mmmm") -> October | BJ97: =NETWORKDAYS(B97,TODAY()) -> 446 | BK97: =M97/K97 -> 0.18805227 | BL97: =_xlfn.XLOOKUP(G97,G:G,I:I,"",0) -> 33295 | BM97: =_xlfn.XMATCH(E97,E:E,0) -> 8 | BN97: 1096 | BO97: 45400 | BP97: West | BQ97: Karan | BR97: Customer_48 | BS97: Furniture | BT97: Printer | BU97: 3 | BV97: 26245 | BW97: 10 | BX97: 70861.5 | BY97: 57066.53 | BZ97: 13794.97 | CA97: Card | CB97: 7 | CC97: 4.1 | CD97: =COUNTIF(Sales_Data!E:E,Sales_Data!E97)>1 -> TRUE | CE97: =SUM(Sales_Data!$K$2:'Sales_Data'!K97) -> 24695268 | CF97: =K97*1.15 -> 406215.76 | CG97: =CHOOSE(MATCH(C97,{"North","West","South","East"},0),"Zone 1","Zone 2","Zone 3","Zone 4") -> Zone 2 | CH97: {=_xlfn.SWITCH(N97,"Card","Card Payment","UPI", "UPI Payment","Cash","Cash Payment","NetBanking", "NetBanking Payment", "Unknown")} -> Cash Payment | CI97: {=_xlfn.IFS(Sales_Data!J97<=5,"Low",Sales_Data!J97<=10,"Medium",Sales_Data!J97>10,"High")} -> High
A98: 1098 | B98: 45727 | C98: South | D98: Sneha | E98: Customer_22 | F98: Electronics | G98: Chair | H98: 6 | I98: 15937 | J98: 20 | K98: 76497.6 | L98: 44848.76 | M98: 31648.84 | N98: NetBanking | O98: 3 | P98: 3.4 | Q98: =RANK(M98,$M$2:$M$1000) -> 129 | R98: =_xlfn.XLOOKUP(A98,A:A,G:G,"") -> Chair | S98: =INDEX(D:D,MATCH($T$1,A:A,0)) -> #N/A | AK98: 1091 | AL98: 45342 | AM98: West | AN98: Arjun | AO98: Customer_15 | AP98: Electronics | AQ98: Chair | AR98: 7 | AS98: 48661 | AT98: 20 | AU98: 272501.6 | AV98: 214275.98 | AW98: 58225.62 | AX98: Card | AY98: 3 | AZ98: 2.6 | BA98: 96 | BB98: Chair | BC98: =ROUND(MONTH(B98)/3,0) -> 1 | BD98: =IF(M98>100000,"Bonus!","") | BE98: =_xlfn.LET(_xlpm.profit,M98,_xlpm.sales,K98,_xlpm.profit/_xlpm.sales) -> 0.41372331 | BF98: Customer_33 | BG98: =_xlfn.TEXTJOIN("-",TRUE,C98,G98) -> South-Chair | BH98: =YEAR(B98) -> 2025 | BI98: =TEXT(B98,"mmmm") -> March | BJ98: =NETWORKDAYS(B98,TODAY()) -> 342 | BK98: =M98/K98 -> 0.41372331 | BL98: =_xlfn.XLOOKUP(G98,G:G,I:I,"",0) -> 4972 | BM98: =_xlfn.XMATCH(E98,E:E,0) -> 43 | BN98: 1097 | BO98: 45581 | BP98: West | BQ98: Aman | BR98: Customer_30 | BS98: Electronics | BT98: Phone | BU98: 9 | BV98: 46174 | BW98: 15 | BX98: 353231.1 | BY98: 286805.19 | BZ98: 66425.91 | CA98: Cash | CB98: 9 | CC98: 4.9 | CD98: =COUNTIF(Sales_Data!E:E,Sales_Data!E98)>1 -> TRUE | CE98: =SUM(Sales_Data!$K$2:'Sales_Data'!K98) -> 24771766 | CF98: =K98*1.15 -> 87972.24 | CG98: =CHOOSE(MATCH(C98,{"North","West","South","East"},0),"Zone 1","Zone 2","Zone 3","Zone 4") -> Zone 3 | CH98: {=_xlfn.SWITCH(N98,"Card","Card Payment","UPI", "UPI Payment","Cash","Cash Payment","NetBanking", "NetBanking Payment", "Unknown")} -> NetBanking Payment | CI98: {=_xlfn.IFS(Sales_Data!J98<=5,"Low",Sales_Data!J98<=10,"Medium",Sales_Data!J98>10,"High")} -> High
A99: 1099 | B99: 45723 | C99: East | D99: Rohan | E99: Customer_15 | F99: Office Supplies | G99: Printer | H99: 5 | I99: 5506 | J99: 0 | K99: 27530 | L99: 18475.3 | M99: 9054.7 | N99: Cash | O99: 9 | P99: 2.9 | Q99: =RANK(M99,$M$2:$M$1000) -> 177 | R99: =_xlfn.XLOOKUP(A99,A:A,G:G,"") -> Printer | S99: =INDEX(D:D,MATCH($T$1,A:A,0)) -> #N/A | AK99: 1107 | AL99: 45763 | AM99: North | AN99: Megha | AO99: Customer_50 | AP99: Office Supplies | AQ99: Laptop | AR99: 9 | AS99: 20779 | AT99: 0 | AU99: 187011 | AV99: 128903.27 | AW99: 58107.73 | AX99: NetBanking | AY99: 2 | AZ99: 3.4 | BA99: 97 | BB99: Laptop | BC99: =ROUND(MONTH(B99)/3,0) -> 1 | BD99: =IF(M99>100000,"Bonus!","") | BE99: =_xlfn.LET(_xlpm.profit,M99,_xlpm.sales,K99,_xlpm.profit/_xlpm.sales) -> 0.32890301 | BF99: Customer_34 | BG99: =_xlfn.TEXTJOIN("-",TRUE,C99,G99) -> East-Printer | BH99: =YEAR(B99) -> 2025 | BI99: =TEXT(B99,"mmmm") -> March | BJ99: =NETWORKDAYS(B99,TODAY()) -> 344 | BK99: =M99/K99 -> 0.32890301 | BL99: =_xlfn.XLOOKUP(G99,G:G,I:I,"",0) -> 1561 | BM99: =_xlfn.XMATCH(E99,E:E,0) -> 33 | BN99: 1098 | BO99: 45727 | BP99: South | BQ99: Sneha | BR99: Customer_22 | BS99: Electronics | BT99: Chair | BU99: 6 | BV99: 15937 | BW99: 20 | BX99: 76497.6 | BY99: 44848.76 | BZ99: 31648.84 | CA99: NetBanking | CB99: 3 | CC99: 3.4 | CD99: =COUNTIF(Sales_Data!E:E,Sales_Data!E99)>1 -> TRUE | CE99: =SUM(Sales_Data!$K$2:'Sales_Data'!K99) -> 24799296 | CF99: =K99*1.15 -> 31659.5 | CG99: =CHOOSE(MATCH(C99,{"North","West","South","East"},0),"Zone 1","Zone 2","Zone 3","Zone 4") -> Zone 4 | CH99: {=_xlfn.SWITCH(N99,"Card","Card Payment","UPI", "UPI Payment","Cash","Cash Payment","NetBanking", "NetBanking Payment", "Unknown")} -> Cash Payment | CI99: {=_xlfn.IFS(Sales_Data!J99<=5,"Low",Sales_Data!J99<=10,"Medium",Sales_Data!J99>10,"High")} -> Low
A100: 1100 | B100: 45425 | C100: North | D100: Arjun | E100: Customer_37 | F100: Electronics | G100: Monitor | H100: 15 | I100: 20968 | J100: 20 | K100: 251616 | L100: 208981.6 | M100: 42634.4 | N100: NetBanking | O100: 8 | P100: 2.8 | Q100: =RANK(M100,$M$2:$M$1000) -> 117 | R100: =_xlfn.XLOOKUP(A100,A:A,G:G,"") -> Monitor | S100: =INDEX(D:D,MATCH($T$1,A:A,0)) -> #N/A | AK100: 1112 | AL100: 45735 | AM100: East | AN100: Priya | AO100: Customer_50 | AP100: Office Supplies | AQ100: Laptop | AR100: 7 | AS100: 29354 | AT100: 10 | AU100: 184930.2 | AV100: 127141.61 | AW100: 57788.59 | AX100: NetBanking | AY100: 1 | AZ100: 3.5 | BA100: 98 | BB100: Laptop | BC100: =ROUND(MONTH(B100)/3,0) -> 2 | BD100: =IF(M100>100000,"Bonus!","") | BE100: =_xlfn.LET(_xlpm.profit,M100,_xlpm.sales,K100,_xlpm.profit/_xlpm.sales) -> 0.16944232 | BF100: Customer_34 | BG100: =_xlfn.TEXTJOIN("-",TRUE,C100,G100) -> North-Monitor | BH100: =YEAR(B100) -> 2024 | BI100: =TEXT(B100,"mmmm") -> May | BJ100: =NETWORKDAYS(B100,TODAY()) -> 558 | BK100: =M100/K100 -> 0.16944232 | BL100: =_xlfn.XLOOKUP(G100,G:G,I:I,"",0) -> 26687 | BM100: =_xlfn.XMATCH(E100,E:E,0) -> 63 | BN100: 1099 | BO100: 45723 | BP100: East | BQ100: Rohan | BR100: Customer_15 | BS100: Office Supplies | BT100: Printer | BU100: 5 | BV100: 5506 | BW100: 0 | BX100: 27530 | BY100: 18475.3 | BZ100: 9054.7 | CA100: Cash | CB100: 9 | CC100: 2.9 | CD100: =COUNTIF(Sales_Data!E:E,Sales_Data!E100)>1 -> TRUE | CE100: =SUM(Sales_Data!$K$2:'Sales_Data'!K100) -> 25050912 | CF100: =K100*1.15 -> 289358.4 | CG100: =CHOOSE(MATCH(C100,{"North","West","South","East"},0),"Zone 1","Zone 2","Zone 3","Zone 4") -> Zone 1 | CH100: {=_xlfn.SWITCH(N100,"Card","Card Payment","UPI", "UPI Payment","Cash","Cash Payment","NetBanking", "NetBanking Payment", "Unknown")} -> NetBanking Payment | CI100: {=_xlfn.IFS(Sales_Data!J100<=5,"Low",Sales_Data!J100<=10,"Medium",Sales_Data!J100>10,"High")} -> High
A101: 1101 | B101: 45683 | C101: South | D101: Arjun | E101: Customer_21 | F101: Electronics | G101: Desk | H101: 8 | I101: 48000 | J101: 15 | K101: 326400 | L101: 206323.06 | M101: 120076.94 | N101: Card | O101: 6 | P101: 4.3 | Q101: =RANK(M101,$M$2:$M$1000) -> 41 | R101: =_xlfn.XLOOKUP(A101,A:A,G:G,"") -> Desk | S101: =INDEX(D:D,MATCH($T$1,A:A,0)) -> #N/A | AK101: 1041 | AL101: 45630 | AM101: South | AN101: Arjun | AO101: Customer_11 | AP101: Electronics | AQ101: Phone | AR101: 13 | AS101: 23817 | AT101: 20 | AU101: 247696.8 | AV101: 192131.28 | AW101: 55565.52 | AX101: Card | AY101: 7 | AZ101: 4.4 | BA101: 99 | BB101: Phone | BC101: =ROUND(MONTH(B101)/3,0) -> 0 | BD101: =IF(M101>100000,"Bonus!","") -> Bonus! | BE101: =_xlfn.LET(_xlpm.profit,M101,_xlpm.sales,K101,_xlpm.profit/_xlpm.sales) -> 0.36788278 | BF101: Customer_34 | BG101: =_xlfn.TEXTJOIN("-",TRUE,C101,G101) -> South-Desk | BH101: =YEAR(B101) -> 2025 | BI101: =TEXT(B101,"mmmm") -> January | BJ101: =NETWORKDAYS(B101,TODAY()) -> 373 | BK101: =M101/K101 -> 0.36788278 | BL101: =_xlfn.XLOOKUP(G101,G:G,I:I,"",0) -> 13233 | BM101: =_xlfn.XMATCH(E101,E:E,0) -> 78 | BN101: 1100 | BO101: 45425 | BP101: North | BQ101: Arjun | BR101: Customer_37 | BS101: Electronics | BT101: Monitor | BU101: 15 | BV101: 20968 | BW101: 20 | BX101: 251616 | BY101: 208981.6 | BZ101: 42634.4 | CA101: NetBanking | CB101: 8 | CC101: 2.8 | CD101: =COUNTIF(Sales_Data!E:E,Sales_Data!E101)>1 -> TRUE | CE101: =SUM(Sales_Data!$K$2:'Sales_Data'!K101) -> 25377312 | CF101: =K101*1.15 -> 375360 | CG101: =CHOOSE(MATCH(C101,{"North","West","South","East"},0),"Zone 1","Zone 2","Zone 3","Zone 4") -> Zone 3 | CH101: {=_xlfn.SWITCH(N101,"Card","Card Payment","UPI", "UPI Payment","Cash","Cash Payment","NetBanking", "NetBanking Payment", "Unknown")} -> Card Payment | CI101: {=_xlfn.IFS(Sales_Data!J101<=5,"Low",Sales_Data!J101<=10,"Medium",Sales_Data!J101>10,"High")} -> High
... A201: 1201 | B201: 45293 | C201: North | D201: Arjun | E201: Customer_40 | F201: Furniture | G201: Laptop | H201: 8 | I201: 44578 | J201: 5 | K201: 338792.8 | L201: 213119.97 | M201: 125672.83 | N201: Cash | O201: 2 | P201: 3.9 | Q201: =RANK(M201,$M$2:$M$1000) -> 38 | R201: =_xlfn.XLOOKUP(A201,A:A,G:G,"") -> Laptop | S201: =INDEX(D:D,MATCH($T$1,A:A,0)) -> #N/A | AK201: 1167 | AL201: 45601 | AM201: North | AN201: Arjun | AO201: Customer_49 | AP201: Electronics | AQ201: Mouse | AR201: 1 | AS201: 3593 | AT201: 15 | AU201: 3054.05 | AV201: 2367.8 | AW201: 686.25 | AX201: Card | AY201: 5 | AZ201: 3.9 | BA201: 199 | BB201: Mouse | BC201: =ROUND(MONTH(B201)/3,0) -> 0 | BD201: =IF(M201>100000,"Bonus!","") -> Bonus! | BE201: =_xlfn.LET(_xlpm.profit,M201,_xlpm.sales,K201,_xlpm.profit/_xlpm.sales) -> 0.37094304 | BF201: Customer_9 | BG201: =_xlfn.TEXTJOIN("-",TRUE,C201,G201) -> North-Laptop | BH201: =YEAR(B201) -> 2024 | BI201: =TEXT(B201,"mmmm") -> January | BJ201: =NETWORKDAYS(B201,TODAY()) -> 652 | BK201: =M201/K201 -> 0.37094304 | BL201: =_xlfn.XLOOKUP(G201,G:G,I:I,"",0) -> 30283 | BM201: =_xlfn.XMATCH(E201,E:E,0) -> 17 | BN201: 1200 | BO201: 45577 | BP201: South | BQ201: Megha | BR201: Customer_27 | BS201: Office Supplies | BT201: Mouse | BU201: 12 | BV201: 47005 | BW201: 20 | BX201: 451248 | BY201: 315069.61 | BZ201: 136178.39 | CA201: Card | CB201: 6 | CC201: 3.9 | CD201: =COUNTIF(Sales_Data!E:E,Sales_Data!E201)>1 -> TRUE | CE201: =SUM(Sales_Data!$K$2:'Sales_Data'!K201) -> 47684698 | CF201: =K201*1.15 -> 389611.72 | CG201: =CHOOSE(MATCH(C201,{"North","West","South","East"},0),"Zone 1","Zone 2","Zone 3","Zone 4") -> Zone 1 | CH201: {=_xlfn.SWITCH(N201,"Card","Card Payment","UPI", "UPI Payment","Cash","Cash Payment","NetBanking", "NetBanking Payment", "Unknown")} -> Cash Payment | CI201: {=_xlfn.IFS(Sales_Data!J201<=5,"Low",Sales_Data!J201<=10,"Medium",Sales_Data!J201>10,"High")} -> Low
AK202: 1069 | AL202: 45549 | AM202: West | AN202: Priya | AO202: Customer_33 | AP202: Furniture | AQ202: Mouse | AR202: 1 | AS202: 672 | AT202: 20 | AU202: 537.6 | AV202: 316.74 | AW202: 220.86 | AX202: NetBanking | AY202: 6 | AZ202: 4.4 | BA202: 200 | BB202: Mouse | BC202: =ROUND(MONTH(B202)/3,0) -> 0 | BD202: =IF(M202>100000,"Bonus!","") | BE202: =_xlfn.LET(_xlpm.profit,M202,_xlpm.sales,K202,_xlpm.profit/_xlpm.sales) -> #DIV/0! | BG202: =_xlfn.TEXTJOIN("-",TRUE,C202,G202) | BH202: =YEAR(B202) -> 1900 | BI202: =TEXT(B202,"mmmm") -> January | BJ202: =NETWORKDAYS(B202,TODAY()) -> 33003 | BK202: =M202/K202 -> #DIV/0! | BL202: =_xlfn.XLOOKUP(G202,G:G,I:I,"",0) -> 0 | BM202: =_xlfn.XMATCH(E202,E:E,0) -> 202 | BN202: 1201 | BO202: 45293 | BP202: North | BQ202: Arjun | BR202: Customer_40 | BS202: Furniture | BT202: Laptop | BU202: 8 | BV202: 44578 | BW202: 5 | BX202: 338792.8 | BY202: 213119.97 | BZ202: 125672.83 | CA202: Cash | CB202: 2 | CC202: 3.9 | CD202: =COUNTIF(Sales_Data!E:E,Sales_Data!E202)>1 -> FALSE | CE202: =SUM(Sales_Data!$K$2:'Sales_Data'!K202) -> 47684698 | CF202: =K202*1.15 -> 0 | CG202: =CHOOSE(MATCH(C202,{"North","West","South","East"},0),"Zone 1","Zone 2","Zone 3","Zone 4") -> #N/A | CH202: {=_xlfn.SWITCH(N202,"Card","Card Payment","UPI", "UPI Payment","Cash","Cash Payment","NetBanking", "NetBanking Payment", "Unknown")} -> Unknown | CI202: {=_xlfn.IFS(Sales_Data!J202<=5,"Low",Sales_Data!J202<=10,"Medium",Sales_Data!J202>10,"High")} -> Low

Sheet Advanced_Formula_Questions
A1: 50 Business Scenario Questions | J1: ans 1
A2: 1. Calculate total sales for each Region using SUMIFS. | J2: {=_xlfn.UNIQUE(Sales_Data!C:C)} -> Region
A3: 2. Calculate total profit for each Category. | J3: West | K3: =SUMIFS(Sales_Data!K:K,Sales_Data!C:C,J3) -> 10267687
A4: 3. Find average Sales for Electronics using AVERAGEIFS. | G4: =AVERAGEIFS(Sales_Data!K:K,Sales_Data!F:F,Sales_Data!F2) -> 235998.63 | J4: South | K4: =SUMIFS(Sales_Data!K:K,Sales_Data!C:C,J4) -> 11033934
A5: 4. Count orders with Discount >=10% using COUNTIFS. | G5: =COUNTIFS(Sales_Data!J:J,">=10") -> 112 | J5: East | K5: =SUMIFS(Sales_Data!K:K,Sales_Data!C:C,J5) -> 12180284
A6: 5. Find highest Profit using MAX. | G6: =MAX(Sales_Data!M:M) -> 294520.01 | J6: North | K6: =SUMIFS(Sales_Data!K:K,Sales_Data!C:C,J6) -> 14202793
A7: 6. Find lowest Delivery Days using MIN. | G7: =MIN(Sales_Data!O:O) -> 1 | J7: 0
A8: 7. Rank all sales by Profit using RANK. | J8: ans2
A9: 8. Return Product for a given Order_ID using XLOOKUP. | J9: {=_xlfn.UNIQUE(Sales_Data!F:F)} -> Category
A10: 9. Return Salesperson using INDEX-MATCH. | G10: doubt | J10: Electronics | K10: =SUMIF(Sales_Data!F:F,J10,Sales_Data!M:M) -> 4955324.7
A11: 10. Find orders with Sales above overall average using FILTER. | J11: Office Supplies | K11: =SUMIF(Sales_Data!F:F,J11,Sales_Data!M:M) -> 4952943.1
A12: 11. List unique Categories using UNIQUE. | J12: Furniture | K12: =SUMIF(Sales_Data!F:F,J12,Sales_Data!M:M) -> 4586500.1
A13: 12. Sort products by Profit descending using SORT. | J13: 0
A14: 13. Calculate monthly sales using EOMONTH and SUMIFS. | G14: doubt | J14: ans11
A15: 14. Calculate quarter from Order_Date. | J15: {=_xlfn.UNIQUE(Sales_Data!F:F)} -> Category
A16: 15. Find top 5 Profits using LARGE. | J16: Electronics
A17: 16. Find 3rd highest Sales. | G17: =LARGE(Sales_Data!K:K,3) -> 718080 | J17: Office Supplies
A18: 17. Calculate median Sales. | G18: =MEDIAN(Sales_Data!K:K) -> 204176.6 | J18: Furniture
A19: 18. Calculate standard deviation of Profit. | G19: =_xlfn.STDEV.S(Sales_Data!M:M) -> 65036.937 | J19: 0
A20: 19. Create bonus IF Profit>100000. | J20: ans15 | L20: ans22
A21: 20. Nested IF for performance bands. | G21: doubt | J21: {=LARGE(Sales_Data!M:M,{1;2;3;4;5})} -> 294520.01 | L21: {=_xlfn.UNIQUE(Sales_Data!D:D)} -> Salesperson
A22: 21. Use LET to simplify profit margin calculation. | J22: 280595.95 | L22: Rohan
A23: 22. Find unique Salespersons. | J23: 279929.85 | L23: Karan
A24: 23. Sort customers alphabetically. | J24: 265904.95 | L24: Arjun
A25: 24. Textjoin Region & Product. | J25: 244922.96 | L25: Neha
A26: 25. Extract year from Order_Date. | L26: Sneha
A27: 26. Extract month name. | L27: Priya
A28: 27. Working days from Order_Date to today. | L28: Aman
A29: 28. Calculate profit margin %. | L29: Megha
A30: 29. Count Card payments. | G30: =COUNTIF(Sales_Data!N:N,"Card") -> 56 | J30: ans35 | L30: 0
A31: 30. Sum Cash sales. | G31: =SUMIF(Sales_Data!N:N,"Cash",Sales_Data!K:K) -> 8836507.9 | J31: {=_xlfn.UNIQUE(Sales_Data!C:C)} -> Region
A32: 31. Lookup Unit Price from Product table (assume lookup). | J32: West | K32: =AVERAGEIF(Sales_Data!C:C,Advanced_Formula_Questions!J32,Sales_Data!O:O) -> 6.173913
A33: 32. Use XMATCH to locate Customer. | J33: South | K33: =AVERAGEIF(Sales_Data!C:C,Advanced_Formula_Questions!J33,Sales_Data!O:O) -> 5.5217391
A34: 33. Return entire matching row with FILTER. | J34: East | K34: =AVERAGEIF(Sales_Data!C:C,Advanced_Formula_Questions!J34,Sales_Data!O:O) -> 5.0612245
A35: 34. Count high-rated customers (>4.5). | G35: =COUNTIF(Sales_Data!P:P,">4.5") -> 44 | J35: North | K35: =AVERAGEIF(Sales_Data!C:C,Advanced_Formula_Questions!J35,Sales_Data!O:O) -> 5.3220339
A36: 35. Average delivery by Region. | J36: 0
A37: 36. Highest sales by Salesperson. | J37: ans36
A38: 37. Lowest cost product. | G38: =INDEX(Sales_Data!G:G,MATCH(MIN(Sales_Data!L:L),Sales_Data!L:L,0)) -> Mouse | J38: {=_xlfn.UNIQUE(Sales_Data!D:D)} -> Salesperson
A39: 38. Use AGGREGATE to ignore errors. | G39: =_xlfn.AGGREGATE(2,6,Sales_Data!A1:P201) -> 2000 | J39: Rohan | K39: =_xlfn.MAXIFS(Sales_Data!K:K,Sales_Data!D:D,Advanced_Formula_Questions!J39) -> 674676
A40: 39. Use SUBTOTAL after filtering. | G40: =SUBTOTAL(9,Sales_Data!K:K) -> 47684698 | J40: Karan | K40: =_xlfn.MAXIFS(Sales_Data!K:K,Sales_Data!D:D,Advanced_Formula_Questions!J40) -> 673930
...
