Workbook

Sheet SalesData
A1: OrderID | B1: Date | C1: Customer | D1: Region | E1: Salesperson | F1: Product | G1: Quantity | H1: UnitPrice | I1: Revenue | J1: Order_Type | K1: Quantity_Type | L1: Performance | M1: Month | N1: Day | O1: First_three | P1: Length | Q1: Upper | R1: Lower | S1: AverageRevenue
A2: 1001 | B2: 2026-03-01 | C2: Amit | D2: North | E2: Rahul | F2: Laptop | G2: 2 | H2: 50000 | I2: =G2*H2 -> 100000 | J2: =IF(I2>20000,"High Value", "Low Value") -> High Value | K2: =IF(G2>=5,"Bulk","Regular") -> Regular | L2: =IF(SalesData!I2>=50000,"Excellent","Average") -> Excellent | M2: =MONTH(B2) -> 3 | N2: =DAY(B2) -> 1 | O2: =LEFT(C2,3) -> Ami | P2: =LEN(F2) -> 6 | Q2: =UPPER(F2) -> LAPTOP | R2: =LOWER(C2) -> amit | S2: =AVERAGEIF(E:E,E2,I:I) -> 44625
A3: 1002 | B3: 2026-03-02 | C3: Priya | D3: South | E3: Neha | F3: Mouse | G3: 5 | H3: 500 | I3: =G3*H3 -> 2500 | J3: =IF(I3>20000,"High Value", "Low Value") -> Low Value | K3: =IF(G3>=5,"Bulk","Regular") -> Bulk | L3: =IF(SalesData!I3>=50000,"Excellent","Average") -> Average | M3: =MONTH(B3) -> 3 | N3: =DAY(B3) -> 2 | O3: =LEFT(C3,3) -> Pri | P3: =LEN(F3) -> 5 | Q3: =UPPER(F3) -> MOUSE | R3: =LOWER(C3) -> priya | S3: =AVERAGEIF(E:E,E3,I:I) -> 5500
A4: 1003 | B4: 2026-03-03 | C4: Rohit | D4: East | E4: Rahul | F4: Keyboard | G4: 3 | H4: 1500 | I4: =G4*H4 -> 4500 | J4: =IF(I4>20000,"High Value", "Low Value") -> Low Value | K4: =IF(G4>=5,"Bulk","Regular") -> Regular | L4: =IF(SalesData!I4>=50000,"Excellent","Average") -> Average | M4: =MONTH(B4) -> 3 | N4: =DAY(B4) -> 3 | O4: =LEFT(C4,3) -> Roh | P4: =LEN(F4) -> 8 | Q4: =UPPER(F4) -> KEYBOARD | R4: =LOWER(C4) -> rohit | S4: =AVERAGEIF(E:E,E4,I:I) -> 44625
A5: 1004 | B5: 2026-03-05 | C5: Simran | D5: West | E5: Arjun | F5: Laptop | G5: 1 | H5: 50000 | I5: =G5*H5 -> 50000 | J5: =IF(I5>20000,"High Value", "Low Value") -> High Value | K5: =IF(G5>=5,"Bulk","Regular") -> Regular | L5: =IF(SalesData!I5>=50000,"Excellent","Average") -> Excellent | M5: =MONTH(B5) -> 3 | N5: =DAY(B5) -> 5 | O5: =LEFT(C5,3) -> Sim | P5: =LEN(F5) -> 6 | Q5: =UPPER(F5) -> LAPTOP | R5: =LOWER(C5) -> simran | S5: =AVERAGEIF(E:E,E5,I:I) -> 19333.333
A6: 1005 | B6: 2026-03-06 | C6: Amit | D6: North | E6: Neha | F6: Mouse | G6: 4 | H6: 500 | I6: =G6*H6 -> 2000 | J6: =IF(I6>20000,"High Value", "Low Value") -> Low Value | K6: =IF(G6>=5,"Bulk","Regular") -> Regular | L6: =IF(SalesData!I6>=50000,"Excellent","Average") -> Average | M6: =MONTH(B6) -> 3 | N6: =DAY(B6) -> 6 | O6: =LEFT(C6,3) -> Ami | P6: =LEN(F6) -> 5 | Q6: =UPPER(F6) -> MOUSE | R6: =LOWER(C6) -> amit | S6: =AVERAGEIF(E:E,E6,I:I) -> 5500
A7: 1006 | B7: 2026-03-07 | C7: Karan | D7: South | E7: Rahul | F7: Monitor | G7: 2 | H7: 12000 | I7: =G7*H7 -> 24000 | J7: =IF(I7>20000,"High Value", "Low Value") -> High Value | K7: =IF(G7>=5,"Bulk","Regular") -> Regular | L7: =IF(SalesData!I7>=50000,"Excellent","Average") -> Average | M7: =MONTH(B7) -> 3 | N7: =DAY(B7) -> 7 | O7: =LEFT(C7,3) -> Kar | P7: =LEN(F7) -> 7 | Q7: =UPPER(F7) -> MONITOR | R7: =LOWER(C7) -> karan | S7: =AVERAGEIF(E:E,E7,I:I) -> 44625
A8: 1007 | B8: 2026-03-10 | C8: Priya | D8: East | E8: Arjun | F8: Keyboard | G8: 2 | H8: 1500 | I8: =G8*H8 -> 3000 | J8: =IF(I8>20000,"High Value", "Low Value") -> Low Value | K8: =IF(G8>=5,"Bulk","Regular") -> Regular | L8: =IF(SalesData!I8>=50000,"Excellent","Average") -> Average | M8: =MONTH(B8) -> 3 | N8: =DAY(B8) -> 10 | O8: =LEFT(C8,3) -> Pri | P8: =LEN(F8) -> 8 | Q8: =UPPER(F8) -> KEYBOARD | R8: =LOWER(C8) -> priya | S8: =AVERAGEIF(E:E,E8,I:I) -> 19333.333
A9: 1008 | B9: 2026-03-11 | C9: Rohit | D9: West | E9: Rahul | F9: Laptop | G9: 1 | H9: 50000 | I9: =G9*H9 -> 50000 | J9: =IF(I9>20000,"High Value", "Low Value") -> High Value | K9: =IF(G9>=5,"Bulk","Regular") -> Regular | L9: =IF(SalesData!I9>=50000,"Excellent","Average") -> Excellent | M9: =MONTH(B9) -> 3 | N9: =DAY(B9) -> 11 | O9: =LEFT(C9,3) -> Roh | P9: =LEN(F9) -> 6 | Q9: =UPPER(F9) -> LAPTOP | R9: =LOWER(C9) -> rohit | S9: =AVERAGEIF(E:E,E9,I:I) -> 44625
A10: 1009 | B10: 2026-03-12 | C10: Simran | D10: North | E10: Neha | F10: Monitor | G10: 1 | H10: 12000 | I10: =G10*H10 -> 12000 | J10: =IF(I10>20000,"High Value", "Low Value") -> Low Value | K10: =IF(G10>=5,"Bulk","Regular") -> Regular | L10: =IF(SalesData!I10>=50000,"Excellent","Average") -> Average | M10: =MONTH(B10) -> 3 | N10: =DAY(B10) -> 12 | O10: =LEFT(C10,3) -> Sim | P10: =LEN(F10) -> 7 | Q10: =UPPER(F10) -> MONITOR | R10: =LOWER(C10) -> simran | S10: =AVERAGEIF(E:E,E10,I:I) -> 5500
A11: 1010 | B11: 2026-03-15 | C11: Karan | D11: South | E11: Arjun | F11: Mouse | G11: 10 | H11: 500 | I11: =G11*H11 -> 5000 | J11: =IF(I11>20000,"High Value", "Low Value") -> Low Value | K11: =IF(G11>=5,"Bulk","Regular") -> Bulk | L11: =IF(SalesData!I11>=50000,"Excellent","Average") -> Average | M11: =MONTH(B11) -> 3 | N11: =DAY(B11) -> 15 | O11: =LEFT(C11,3) -> Kar | P11: =LEN(F11) -> 5 | Q11: =UPPER(F11) -> MOUSE | R11: =LOWER(C11) -> karan | S11: =AVERAGEIF(E:E,E11,I:I) -> 19333.333
J14: Ans32 | L14: Ans34 | M14: Ans35
J15: =MAX(I:I) -> 100000 | K15: =_xlfn.XLOOKUP(J15,I:I,E:E,"",0) -> Rahul | L15: =_xlfn.XLOOKUP(J15,I:I,D:D,"") -> North | M15: =_xlfn.XLOOKUP(J15,I:I,F:F,"") -> Laptop
J17: Ans33
J18: =MAX(I:I) -> 100000 | K18: =_xlfn.XLOOKUP(J18,I:I,C:C,"") -> Amit
J20: Ans36 | L20: Ans37
J21: =MAX(G:G) -> 10 | K21: =_xlfn.XLOOKUP(J21,G:G,E:E,"",0) -> Arjun | L21: =MAX(G:G) -> 10 | M21: =_xlfn.XLOOKUP(L21,G:G,F:F,"") -> Mouse
J24: Ans38
J25: =SUMIF(F:F,"Laptop",I:I) -> 200000 | K25: =J25/J26 -> 0.79051383
J26: =SUM(I2:I11) -> 253000

Sheet questions
A1: ACCIOJOB FINAL MOCK – EXCEL PRACTICE
A3: DATASET: Use the SalesData sheet.
A5: --------------------------------------------------
A6: BASIC EXCEL
A7: --------------------------------------------------
A9: Q1. Find Total Revenue generated from all orders. | F9: =SUM(SalesData!I:I) -> 253000
A11: Q2. Find the Highest Revenue Order Value. | F11: =MAX(SalesData!I:I) -> 100000
A13: Q3. Find the Lowest Revenue Order Value. | F13: =MIN(SalesData!I:I) -> 2000
A15: Q4. Find the Total Number of Orders. | F15: =COUNTA(SalesData!A2:A11) -> 10
A17: Q5. Find the Average Revenue per Order. | F17: =AVERAGE(SalesData!I:I) -> 25300
A19: Q6. Find the Total Quantity Sold. | F19: =SUM(SalesData!G:G) -> 31
A21: --------------------------------------------------
A22: COUNTIF / SUMIF
A23: --------------------------------------------------
A25: Q7. How many orders were handled by Rahul? | G25: =COUNTIF(SalesData!E:E,"Rahul") -> 4
A27: Q8. What is the total revenue generated by Rahul? | G27: =SUMIF(SalesData!E:E,"Rahul",SalesData!I:I) -> 178500
A29: Q9. How many orders belong to the North region? | G29: =COUNTIF(SalesData!D:D,"North") -> 3
A31: Q10. What is the total revenue generated in the North region? | G31: =SUMIF(SalesData!D:D,"North",SalesData!I:I) -> 114000
A33: Q11. How many Laptop orders are there? | G33: =COUNTIF(SalesData!F:F,"Laptop") -> 3
A35: Q12. What is the total revenue generated from Laptop sales? | G35: =SUMIF(SalesData!F:F,"Laptop",SalesData!I:I) -> 200000
A37: Q13. How many orders were handled by Neha? | G37: =COUNTIF(SalesData!E:E,"Neha") -> 3
A39: Q14. What is the total revenue generated by Neha? | G39: =SUMIF(SalesData!E:E,"Neha",SalesData!I:I) -> 16500
A41: --------------------------------------------------
A42: COUNTIFS / SUMIFS
A43: --------------------------------------------------
A45: Q15. Find revenue generated by Rahul in the North region. | H45: =SUMIFS(SalesData!I:I,SalesData!E:E,"Rahul",SalesData!D:D,"North") -> 100000
A47: Q16. Count Laptop orders handled by Rahul. | H47: =COUNTIFS(SalesData!F:F,"Laptop",SalesData!E:E,"Rahul") -> 2
A49: Q17. Find revenue generated from Mouse sales in the South region. | H49: =SUMIFS(SalesData!I:I,SalesData!F:F,"Mouse",SalesData!D:D,"South") -> 7500
A51: Q18. Count orders from East region handled by Arjun. | H51: =COUNTIFS(SalesData!D:D,"East",SalesData!E:E,"Arjun") -> 1
A53: Q19. Find total revenue generated by Neha in the North region. | H53: =SUMIFS(SalesData!I:I,SalesData!E:E,"Neha",SalesData!D:D,"North") -> 14000
A55: Q20. Count orders where Product = Mouse and Quantity > 4. | H55: =COUNTIFS(SalesData!F:F,"Mouse",SalesData!G:G,">4") -> 2
A57: --------------------------------------------------
A58: IF FUNCTION
A59: --------------------------------------------------
A61: Q21. Create a column called Order_Type. | F61: Done
A63: If Revenue > 20000 → High Value
A64: Else → Low Value
A66: Q22. Create a column called Quantity_Type. | F66: Done
A68: If Quantity >= 5 → Bulk
A69: Else → Regular
...
