Workbook

Sheet Data
A1: OrderID | B1: OrderDate | C1: Customer | D1: City | E1: Restaurant | F1: Cuisine | G1: Partner | H1: OrderValue | I1: DeliveryTimeMins | J1: Rating | K1: Status | M1: quarter | N1: year | O1: day | P1: cuisine helper | Q1: city helper
A2: 20000 | B2: 45684 | C2: Sanjay Verma | D2: Delhi | E2: Curry House | F2: Italian | G2: Zomato | H2: 1868.93 | I2: 70 | J2: 1 | K2: Delivered | M2: =ROUNDUP(MONTH(B2)/3,0) -> 1 | N2: =YEAR(B2) -> 2025 | O2: =TEXT(B2,"dddd") -> Monday | P2: =IF(I2>60,F2,"") -> Italian
A3: 20001 | B3: 45945 | C3: Zara Khan | D3: Bangalore | E3: Spice Route | F3: Chinese | G3: Zomato | H3: 841.29 | I3: 36 | J3: 3 | K3: Delivered | M3: =ROUNDUP(MONTH(B3)/3,0) -> 4 | N3: =YEAR(B3) -> 2025 | O3: =TEXT(B3,"dddd") -> Wednesday | P3: =IF(I3>60,F3,"")
A4: 20002 | B4: 45881 | C4: Ishaan Rao | D4: Hyderabad | E4: Curry House | F4: North Indian | G4: Zomato | H4: 796.69 | I4: 43 | J4: 2 | K4: Cancelled | M4: =ROUNDUP(MONTH(B4)/3,0) -> 3 | N4: =YEAR(B4) -> 2025 | O4: =TEXT(B4,"dddd") -> Tuesday | P4: =IF(I4>60,F4,"")
A5: 20003 | B5: 45705 | C5: Rohan Gupta | D5: Mumbai | E5: Spice Route | F5: Italian | G5: Swiggy | H5: 1325.49 | I5: 31 | J5: 5 | K5: Delivered | M5: =ROUNDUP(MONTH(B5)/3,0) -> 1 | N5: =YEAR(B5) -> 2025 | O5: =TEXT(B5,"dddd") -> Monday | P5: =IF(I5>60,F5,"")
A6: 20004 | B6: 45814 | C6: Zara Khan | D6: Hyderabad | E6: Noodle Bar | F6: Chinese | G6: Own Fleet | H6: 1459.45 | I6: 51 | J6: 4 | K6: Delivered | M6: =ROUNDUP(MONTH(B6)/3,0) -> 2 | N6: =YEAR(B6) -> 2025 | O6: =TEXT(B6,"dddd") -> Friday | P6: =IF(I6>60,F6,"")
A7: 20005 | B7: 45988 | C7: Simran Kaur | D7: Pune | E7: Pizza Point | F7: Desserts | G7: Own Fleet | H7: 1372.83 | I7: 68 | J7: 5 | K7: Delivered | M7: =ROUNDUP(MONTH(B7)/3,0) -> 4 | N7: =YEAR(B7) -> 2025 | O7: =TEXT(B7,"dddd") -> Thursday | P7: =IF(I7>60,F7,"") -> Desserts
A8: 20006 | B8: 45872 | C8: Devansh Shah | D8: Hyderabad | E8: Spice Route | F8: Desserts | G8: Zomato | H8: 1637.95 | I8: 20 | J8: 5 | K8: Delivered | M8: =ROUNDUP(MONTH(B8)/3,0) -> 3 | N8: =YEAR(B8) -> 2025 | O8: =TEXT(B8,"dddd") -> Sunday | P8: =IF(I8>60,F8,"")
A9: 20007 | B9: 45745 | C9: Zara Khan | D9: Bangalore | E9: Pizza Point | F9: South Indian | G9: Zomato | H9: 1632.38 | I9: 39 | J9: 4 | K9: Delivered | M9: =ROUNDUP(MONTH(B9)/3,0) -> 1 | N9: =YEAR(B9) -> 2025 | O9: =TEXT(B9,"dddd") -> Saturday | P9: =IF(I9>60,F9,"")
A10: 20008 | B10: 45958 | C10: Ishaan Rao | D10: Chennai | E10: Sweet Tooth | F10: North Indian | G10: Swiggy | H10: 2194.98 | I10: 40 | J10: 5 | K10: Delivered | M10: =ROUNDUP(MONTH(B10)/3,0) -> 4 | N10: =YEAR(B10) -> 2025 | O10: =TEXT(B10,"dddd") -> Tuesday | P10: =IF(I10>60,F10,"")
A11: 20009 | B11: 45688 | C11: Nisha Reddy | D11: Pune | E11: Dosa Junction | F11: Fast Food | G11: Swiggy | H11: 2160.38 | I11: 24 | J11: 5 | K11: Delivered | M11: =ROUNDUP(MONTH(B11)/3,0) -> 1 | N11: =YEAR(B11) -> 2025 | O11: =TEXT(B11,"dddd") -> Friday | P11: =IF(I11>60,F11,"")
A12: 20010 | B12: 45894 | C12: Diya Kapoor | D12: Delhi | E12: Bella Napoli | F12: South Indian | G12: Zomato | H12: 193.07 | I12: 66 | J12: 4 | K12: Delivered | M12: =ROUNDUP(MONTH(B12)/3,0) -> 3 | N12: =YEAR(B12) -> 2025 | O12: =TEXT(B12,"dddd") -> Monday | P12: =IF(I12>60,F12,"") -> South Indian
A13: 20011 | B13: 45880 | C13: Farhan Ali | D13: Delhi | E13: Wok This Way | F13: Fast Food | G13: Zomato | H13: 1196.16 | I13: 60 | J13: 2 | K13: Delivered | M13: =ROUNDUP(MONTH(B13)/3,0) -> 3 | N13: =YEAR(B13) -> 2025 | O13: =TEXT(B13,"dddd") -> Monday | P13: =IF(I13>60,F13,"")
... A151: 20149 | B151: 46016 | C151: Ananya Bose | D151: Bangalore | E151: Sweet Tooth | F151: Fast Food | G151: Own Fleet | H151: 1595.4 | I151: 32 | J151: 5 | K151: Delivered | M151: =ROUNDUP(MONTH(B151)/3,0) -> 4 | N151: =YEAR(B151) -> 2025 | O151: =TEXT(B151,"dddd") -> Thursday | P151: =IF(I151>60,F151,"")

Sheet Formula Test
A1: Food Delivery Formula Test
A2: Use the Data sheet (rows 2-151) as your source. Write one formula per answer cell in column B. | D2: ref ans12
D3: {=_xlfn.UNIQUE(Data!F2:F151)} -> Italian | E3: =SUMIFS(Data!H2:H151,Data!J2:J151,"=5",Data!F2:F151,'Formula Test'!D3) -> 5594.24
A4: Q1. Total OrderValue for orders from 'Pizza Point' delivered by 'Swiggy'. | B4: =SUMIFS(Data!H2:H151,Data!E2:E151,"Pizza Point",Data!G2:G151,"Swiggy") -> 9624.71 | D4: Chinese | E4: =SUMIFS(Data!H3:H152,Data!J3:J152,"=5",Data!F3:F152,'Formula Test'!D4) -> 7596.29
A5: Q2. Count of orders with Status='Cancelled' and Rating less than 3. | B5: =COUNTIFS(Data!J2:J151,"<3",Data!K2:K151,"Cancelled") -> 1 | D5: North Indian | E5: =SUMIFS(Data!H4:H153,Data!J4:J153,"=5",Data!F4:F153,'Formula Test'!D5) -> 9525.15
A6: Q3. Look up the Restaurant for OrderID 20040, with a safe fallback if it isn't found. | B6: =_xlfn.XLOOKUP(20040,Data!A2:A151,Data!E2:E151,"",0) -> Noodle Bar | D6: Desserts | E6: =SUMIFS(Data!H5:H154,Data!J5:J154,"=5",Data!F5:F154,'Formula Test'!D6) -> 13633.1
A7: Q4. Average DeliveryTimeMins for orders in 'Bangalore' delivered by 'Own Fleet'. | B7: =AVERAGEIFS(Data!I2:I151,Data!D2:D151,"Bangalore",Data!G2:G151,"Own Fleet") -> 37 | D7: South Indian | E7: =SUMIFS(Data!H6:H155,Data!J6:J155,"=5",Data!F6:F155,'Formula Test'!D7) -> 6750.99
A8: Q5. Total OrderValue across the entire dataset for Status='Delivered' only, without adding a helper column. | B8: =SUMIF(Data!K2:K151,"Delivered",Data!H2:H151) -> 167128.16 | D8: Fast Food | E8: =SUMIFS(Data!H7:H156,Data!J7:J156,"=5",Data!F7:F156,'Formula Test'!D8) -> 6872.67
A9: Q6. Classify OrderID 20000's delivery speed as 'Fast' (DeliveryTimeMins<=30), 'Moderate' (31-50), or 'Slow' (50+). | B9: =IF(Data!I2<=30,"Fast",IF(Data!I2<=50,"Medium","Slow")) -> Slow
A10: Q7. Extract the month name and year (e.g. 'March 2025') from the OrderDate of OrderID 20025. | B10: =TEXT(Data!B27,"mmmm yyyy") -> April 2025
A11: Q8. Return the OrderValue where City='Chennai' and Cuisine='South Indian', using an array-style match (no helper column). | B11: {=SUMPRODUCT((Data!D2:D151="Chennai")*(Data!F2:F151="South Indian"),Data!H2:H151)} -> 8540.01 | D11: ans9 | F11: ans10
A12: Q9. Return a unique, alphabetically sorted list of all Restaurants as a spilled array. | B12: done in right | D12: {=_xlfn._xlws.SORT(_xlfn.UNIQUE(Data!E2:E151))} -> Bella Napoli | F12: {=_xlfn._xlws.FILTER(Data!A2:A151,(Data!G2:G151="Own Fleet")*(Data!J2:J151=5))} -> 20005
A13: Q10. Return all OrderIDs where Partner='Own Fleet' AND Rating=5, as a spilled array. | B13: done in right | D13: Burger Barn | F13: 20027
A14: Q11. Count how many Customer names contain 'Kaur' anywhere in the dataset. | B14: =COUNTIF(Data!C2:C151,"*Kaur*") -> 10 | D14: Curry House | F14: 20034
A15: Q12. Find the Cuisine with the highest total OrderValue among orders with Rating=5, using formulas only (no pivot table). | B15: {=_xlfn.XLOOKUP(MAX(E3:E8),E3:E8,_xlfn.ANCHORARRAY(D3),"")} -> Desserts | D15: Dosa Junction | F15: 20064
A16: Q13. Calculate the total number of unique Customers who ordered from 'Sweet Tooth'. | B16: {=COUNTA(_xlfn.UNIQUE(_xlfn._xlws.FILTER(Data!C2:C151,Data!E2:E151="Sweet Tooth","")))} -> 10 | D16: Idli Express | F16: 20101
A17: Q14. Find the second-highest DeliveryTimeMins in the entire dataset. | B17: =LARGE(Data!I2:I151,2) -> 74 | D17: Noodle Bar | F17: 20109
A18: Q15. Return the Customer name associated with the single highest OrderValue on record. | B18: =_xlfn.XLOOKUP(MAX(Data!H2:H151),Data!H2:H151,Data!C2:C151,"",0) -> Devansh Shah | D18: Pizza Point | F18: 20110
A19: Q16. Count the number of orders placed in Q1 2025 (Jan-Mar). | B19: =COUNTIFS(Data!M2:M151,1,Data!N2:N151,2025) -> 38 | D19: Spice Route | F19: 20122
A20: Q17. Calculate the percentage of orders with Status='Returned'. | B20: =COUNTIF(Data!K2:K151,"Returned")/COUNTA(Data!K2:K151) -> 0.053333333 | D20: Sweet Tooth | F20: 20126
A21: Q18. Return the most frequently ordered Cuisine overall. | B21: {=INDEX(Data!F2:F151,MATCH(MAX(COUNTIF(Data!F2:F151,Data!F2:F151)),COUNTIF(Data!F2:F151,Data!F2:F151),0))} -> Italian | D21: Wok This Way | F21: 20127
A22: Q19. Find the total OrderValue generated by each Partner, broken out into a small 3-row summary table using formulas (not a pivot table). | B22: done in right | F22: 20143
A23: Q20. Extract just the day of the week (e.g. 'Monday') for the OrderDate of OrderID 20060. | B23: =TEXT(Data!B62,"dddd") -> Sunday | F23: 20149
A24: Q21. Return the average Rating for orders with OrderValue greater than 1500. | B24: =AVERAGEIF(Data!H2:H151,">1500",Data!J2:J151) -> 3.5230769
A25: Q22. Find the Cuisine that appears most often for orders with DeliveryTimeMins greater than 60. | B25: {=INDEX(Data!P2:P151,MATCH(MAX(COUNTIF(Data!P2:P151,Data!P2:P151)*(Data!P2:P151<>"")),COUNTIF(Data!P2:P151,Data!P2:P151),0))} -> Italian | D25: ans19
A26: Q23. Return the number of distinct Cuisines available in 'Hyderabad'. | B26: {=COUNTA(_xlfn.UNIQUE(_xlfn._xlws.FILTER(Data!F2:F151,Data!D2:D151="Hyderabad","")))} -> 6 | D26: {=_xlfn.UNIQUE(Data!G2:G151)} -> Zomato | E26: =SUMIF(Data!G2:'Data'!G151,'Formula Test'!D26,Data!H2:H151) -> 70305.17
A27: Q24. Calculate the total number of days between OrderID 20010's OrderDate and today's date. | B27: =DATEDIF(Data!B12,TODAY(),"D") -> 317 | D27: Swiggy | E27: =SUMIF(Data!G3:'Data'!G152,'Formula Test'!D27,Data!H3:H152) -> 65512.23
A28: Q25. Return TRUE or FALSE for whether every order from 'Bella Napoli' has a Rating of 3 or higher. | B28: {=SUMPRODUCT((Data!E2:E151="Bella Napoli")*(Data!J2:J151<3))=0} -> FALSE | D28: Own Fleet | E28: =SUMIF(Data!G4:'Data'!G153,'Formula Test'!D28,Data!H4:H153) -> 51048.23
A29: Q26. Concatenate the Customer name and City into a single string separated by a hyphen for OrderID 20030 (e.g. 'Aarav Mehta-Delhi'). | B29: =_xlfn.TEXTJOIN("-",TRUE,Data!C32,Data!D32) -> Karan Malhotra-Hyderabad
A30: Q27. Find the earliest and latest OrderDate in the dataset, displayed as a single text string like 'Jan 2025 to Dec 2025'. | B30: =_xlfn.TEXTJOIN(" to ",TRUE,D31,D32) -> Jan 2025 to Dec 2025 | D30: ref ans27
A31: Q28. Return the overall average OrderValue, rounded to the nearest whole number. | B31: =ROUND(AVERAGE(Data!H2:H151),0) -> 1246 | D31: =TEXT(MIN(Data!B2:B151),"mmm yyyy") -> Jan 2025
A32: Q29. Find the Restaurant with the lowest average Rating (only include restaurants with at least 5 orders). | B32: =_xlfn.XLOOKUP(MIN(F35:F44),F35:F44,D35:D44,"",0) -> Noodle Bar | D32: =TEXT(MAX(Data!B3:B152),"mmm yyyy") -> Dec 2025
A33: Q30. Return the rank (1 = highest) of OrderID 20005's OrderValue among all orders, using RANK.EQ. | B33: =_xlfn.RANK.EQ(Data!H7,Data!H2:H151) -> 75
A34: Q31. Extract just the first word of the Restaurant name for OrderID 20015 (e.g. 'Pizza' from 'Pizza Point'). | B34: =LEFT(Data!E17,SEARCH(" ",Data!E17,1)-1) -> Bella | D34: ref ans29
A35: Q32. Calculate the total OrderValue for orders placed on weekends (Saturday or Sunday) using SUMPRODUCT. | B35: {=SUMPRODUCT((Data!O2:O151="Saturday")+(Data!O2:O151="Sunday"),Data!H2:H151)} -> 63958.45 | D35: {=_xlfn._xlws.SORT(_xlfn.UNIQUE(Data!E2:E151))} -> Bella Napoli | E35: =COUNTIF(Data!$E$2:$E$151,'Formula Test'!D35) -> 17 | F35: =IF(E35>=5,AVERAGEIF(Data!$E$2:$E$151,'Formula Test'!D35,Data!$J$2:$J$151)) -> 3.7058824
A36: Q33. Return the number of orders where DeliveryTimeMins is an outlier, defined as more than 1.5x the average DeliveryTimeMins. | B36: =COUNTIF(Data!I2:I151,">"&1.5*AVERAGE(Data!I2:I151)) -> 16 | D36: Burger Barn | E36: =COUNTIF(Data!$E$2:$E$151,'Formula Test'!D36) -> 10 | F36: =IF(E36>=5,AVERAGEIF(Data!$E$2:$E$151,'Formula Test'!D36,Data!$J$2:$J$151)) -> 3.8
A37: Q34. Find the City that generates the highest average OrderValue per order (minimum 10 orders), using formulas only. | B37: {=_xlfn.XLOOKUP(MAX(F47:F52),F47:F52,_xlfn.ANCHORARRAY(D47),"",0)} -> Bangalore | D37: Curry House | E37: =COUNTIF(Data!$E$2:$E$151,'Formula Test'!D37) -> 20 | F37: =IF(E37>=5,AVERAGEIF(Data!$E$2:$E$151,'Formula Test'!D37,Data!$J$2:$J$151)) -> 3.5
D38: Dosa Junction | E38: =COUNTIF(Data!$E$2:$E$151,'Formula Test'!D38) -> 14 | F38: =IF(E38>=5,AVERAGEIF(Data!$E$2:$E$151,'Formula Test'!D38,Data!$J$2:$J$151)) -> 3.7142857
D39: Idli Express | E39: =COUNTIF(Data!$E$2:$E$151,'Formula Test'!D39) -> 9 | F39: =IF(E39>=5,AVERAGEIF(Data!$E$2:$E$151,'Formula Test'!D39,Data!$J$2:$J$151)) -> 3.6666667
D40: Noodle Bar | E40: =COUNTIF(Data!$E$2:$E$151,'Formula Test'!D40) -> 16 | F40: =IF(E40>=5,AVERAGEIF(Data!$E$2:$E$151,'Formula Test'!D40,Data!$J$2:$J$151)) -> 2.8125
...
