Workbook

Sheet Data
A1: OrderID | B1: OrderDate | C1: CustomerName | D1: Region | E1: Category | F1: Product | G1: Quantity | H1: UnitPrice | I1: TotalAmount | J1: PaymentMethod | L1: quarter | M1: days | N1: len
A2: ORD6001 | B2: 45829 | C2: Krish Iyer | D2: South | E2: Stationery | F2: Sticky Notes Pack | G2: 4 | H2: 2967.95 | I2: =G2*H2 -> 11871.8 | J2: Credit Card | L2: =ROUNDUP(MONTH(B2)/3,0) -> 2 | M2: =TEXT(B2,"dddd") -> Saturday | N2: =LEN(C2) -> 10
A3: ORD6002 | B3: 45708 | C3: Tanvi Kapoor | D3: North | E3: Stationery | F3: Highlighter Pack | G3: 4 | H3: 1848.88 | I3: =G3*H3 -> 7395.52 | J3: Credit Card | L3: =ROUNDUP(MONTH(B3)/3,0) -> 1 | M3: =TEXT(B3,"dddd") -> Thursday | N3: =LEN(C3) -> 12
A4: ORD6003 | B4: 45758 | C4: Aryan Kumar | D4: South | E4: Apparel | F4: Cap | G4: 5 | H4: 2487.92 | I4: =G4*H4 -> 12439.6 | J4: Net Banking | L4: =ROUNDUP(MONTH(B4)/3,0) -> 2 | M4: =TEXT(B4,"dddd") -> Friday | N4: =LEN(C4) -> 11
A5: ORD6004 | B5: 45997 | C5: Ayaan Reddy | D5: South | E5: Electronics | F5: USB-C Cable | G5: 5 | H5: 1500.36 | I5: =G5*H5 -> 7501.8 | J5: Cash on Delivery | L5: =ROUNDUP(MONTH(B5)/3,0) -> 4 | M5: =TEXT(B5,"dddd") -> Saturday | N5: =LEN(C5) -> 11
A6: ORD6005 | B6: 45996 | C6: Rohan Joshi | D6: Central | E6: Electronics | F6: Laptop Stand | G6: 4 | H6: 4471.41 | I6: =G6*H6 -> 17885.64 | J6: Net Banking | L6: =ROUNDUP(MONTH(B6)/3,0) -> 4 | M6: =TEXT(B6,"dddd") -> Friday | N6: =LEN(C6) -> 11
A7: ORD6006 | B7: 45748 | C7: Navya Singh | D7: South | E7: Home | F7: Wall Clock | G7: 1 | H7: 2957.46 | I7: =G7*H7 -> 2957.46 | J7: Cash on Delivery | L7: =ROUNDUP(MONTH(B7)/3,0) -> 2 | M7: =TEXT(B7,"dddd") -> Tuesday | N7: =LEN(C7) -> 11
A8: ORD6007 | B8: 45851 | C8: Riya Nair | D8: North | E8: Stationery | F8: Notebook | G8: 9 | H8: 758.55 | I8: =G8*H8 -> 6826.95 | J8: Debit Card | L8: =ROUNDUP(MONTH(B8)/3,0) -> 3 | M8: =TEXT(B8,"dddd") -> Sunday | N8: =LEN(C8) -> 9
A9: ORD6008 | B9: 45983 | C9: Navya Malhotra | D9: North | E9: Grocery | F9: Almonds Pack | G9: 4 | H9: 2517.04 | I9: =G9*H9 -> 10068.16 | J9: Debit Card | L9: =ROUNDUP(MONTH(B9)/3,0) -> 4 | M9: =TEXT(B9,"dddd") -> Saturday | N9: =LEN(C9) -> 14
A10: ORD6009 | B10: 45740 | C10: Rohan Bhatt | D10: South | E10: Grocery | F10: Green Tea Pack | G10: 10 | H10: 2874.13 | I10: =G10*H10 -> 28741.3 | J10: Cash on Delivery | L10: =ROUNDUP(MONTH(B10)/3,0) -> 1 | M10: =TEXT(B10,"dddd") -> Monday | N10: =LEN(C10) -> 11
A11: ORD6010 | B11: 45981 | C11: Aryan Chopra | D11: Central | E11: Electronics | F11: Webcam | G11: 3 | H11: 2789.78 | I11: =G11*H11 -> 8369.34 | J11: UPI | L11: =ROUNDUP(MONTH(B11)/3,0) -> 4 | M11: =TEXT(B11,"dddd") -> Thursday | N11: =LEN(C11) -> 12
A12: ORD6011 | B12: 45658 | C12: Kiara Reddy | D12: East | E12: Electronics | F12: Bluetooth Speaker | G12: 1 | H12: 653.42 | I12: =G12*H12 -> 653.42 | J12: Cash on Delivery | L12: =ROUNDUP(MONTH(B12)/3,0) -> 1 | M12: =TEXT(B12,"dddd") -> Wednesday | N12: =LEN(C12) -> 11
A13: ORD6012 | B13: 46002 | C13: Navya Malhotra | D13: South | E13: Grocery | F13: Almonds Pack | G13: 4 | H13: 2385.73 | I13: =G13*H13 -> 9542.92 | J13: Net Banking | L13: =ROUNDUP(MONTH(B13)/3,0) -> 4 | M13: =TEXT(B13,"dddd") -> Thursday | N13: =LEN(C13) -> 14
... A151: ORD6150 | B151: 45808 | C151: Rohan Bhatt | D151: South | E151: Electronics | F151: Webcam | G151: 8 | H151: 3121.5 | I151: =G151*H151 -> 24972 | J151: Debit Card | L151: =ROUNDUP(MONTH(B151)/3,0) -> 2 | M151: =TEXT(B151,"dddd") -> Saturday | N151: =LEN(C151) -> 11

Sheet Formula_Practice
A1: # | B1: Question | C1: Your Formula / Answer
A2: 1 | B2: Find total revenue for orders placed in Q4 2025 (October–December). | C2: =SUMIF(Data!L2:L151,4,Data!I2:I151) -> 588731.98
A3: 2 | B3: Using MINIFS, find the earliest OrderDate specifically within the 'Electronics' category. | C3: =_xlfn.MINIFS(Data!B2:B151,Data!E2:E151,"Electronics") -> 45658
A4: 3 | B4: Using MAXIFS, find the highest single TotalAmount specifically within the 'Grocery' category. | C4: =_xlfn.MAXIFS(Data!I2:I151,Data!E2:E151,"Grocery") -> 43829.28
A5: 4 | B5: Find the date exactly 30 days after the first order's OrderDate. | C5: =Data!B2+30 -> 45859
A6: 5 | B6: Using EOMONTH, find the last day of the month in which the first order was placed. | C6: =EOMONTH(Data!B2,0) -> 45838
A7: 6 | B7: Using WORKDAY, find the date that is 10 business days after the first order's OrderDate. | C7: =WORKDAY(Data!B2,10,) -> 45842
A8: 7 | B8: Label the first order's PaymentMethod as 'Digital' (UPI, Net Banking, Credit Card, or Debit Card) or 'Offline' (Cash on Delivery), using SWITCH or nested IF. | C8: =IF(Data!J2="Cash on Delivery","Offline","Digital") -> Digital
A9: 8 | B9: Data quality check: find total revenue from orders where CustomerName does NOT contain a space (should be 0 if the data is clean). | C9: =SUMIF(Data!C2:C151,"<>* *",Data!I2:I151) -> 0
A10: 9 | B10: Data quality check: count how many CustomerNames have extra leading or trailing spaces (compare LEN of the name to LEN of TRIM of the name). | C10: {=SUMPRODUCT((LEN(Data!C2:C151)<>(LEN(TRIM(Data!C2:C151))*1)))} -> 0
A11: 10 | B11: Using SUBSTITUTE, replace the space in the first order's CustomerName with an underscore (e.g. 'Riya_Singh'). | C11: =SUBSTITUTE(Data!C2," ","_",1) -> Krish_Iyer
A12: 11 | B12: Find total revenue generated on weekdays only (Monday through Friday, excluding weekends). | C12: =SUMIFS(Data!I2:I151,Data!M2:M151,"<>Saturday",Data!M2:M151,"<>Sunday") -> 1259887
A13: 12 | B13: Find the percentile rank (0 to 1) of the first order's TotalAmount among all orders, using PERCENTRANK. | C13: =_xlfn.PERCENTRANK.EXC(Data!I:I,Data!I2,1) -> 0.5
A14: 13 | B14: Find how many orders have a TotalAmount exactly equal to the median TotalAmount. | C14: =SUM(COUNTIF(Data!I2:I151,"=D14")) -> 0 | D14: =MEDIAN(Data!I2:I151) -> 9342.36
A15: 14 | B15: Find the total number of distinct (Category, Region) combinations that appear in the dataset. | C15: {=SUM(COUNTIFS(Data!D2:D151,_xlfn.UNIQUE(Data!D2:D151),Data!E2:E151,_xlfn.UNIQUE(Data!E2:E151)))} -> 34
A16: 15 | B16: Find the total lifetime revenue of the customer with the SECOND-highest total spend (not the highest — the second). | C16: =_xlfn.XLOOKUP(G16,F16:F54,F16:F54,"") -> 35272.38 | E16: {=_xlfn.UNIQUE(Data!C2:C151)} -> Krish Iyer | F16: =SUMIF(Data!C2:C151,Formula_Practice!E16,Data!I2:I151) -> 19680.46 | G16: =LARGE(F16:F54,22) -> 35272.38
A17: 16 | B17: Calculate the average revenue earned per unit sold: total revenue divided by total quantity, across the whole dataset. | C17: =SUM(Data!I2:I151)/SUM(Data!G2:G151) -> 2362.8644 | E17: Tanvi Kapoor | F17: =SUMIF(Data!C3:C152,Formula_Practice!E17,Data!I3:I152) -> 38419.12
A18: 17 | B18: Using COUNTIFS or SUMPRODUCT, count orders that are 'Apparel' category AND placed in EITHER the 'West' or 'East' region. | C18: {=SUMPRODUCT((Data!E2:E151="Apparel")*((Data!D2:D151="West")+(Data!D2:D151="East")))} -> 14 | E18: Aryan Kumar | F18: =SUMIF(Data!C4:C153,Formula_Practice!E18,Data!I4:I153) -> 61435.88
A19: 18 | B19: Find how many orders have a CustomerName whose first letter matches the first letter of their own Region. | C19: {=SUMPRODUCT((LEFT(Data!C2:C151,1)=LEFT(Data!D2:D151))*1)} -> 3 | E19: Ayaan Reddy | F19: =SUMIF(Data!C5:C154,Formula_Practice!E19,Data!I5:I154) -> 31514.26
A20: 19 | B20: Label the first order as 'Urgent' if TotalAmount > 10000 AND PaymentMethod is 'Cash on Delivery', else 'Normal'. | C20: =IF(AND(Data!I2>10000,Data!J2="Cash on Delivery"),"Urgent","Normal") -> Normal | E20: Rohan Joshi | F20: =SUMIF(Data!C6:C155,Formula_Practice!E20,Data!I6:I155) -> 35272.38 | I20: {=_xlfn.UNIQUE(Data!M2:M151)} -> Saturday | J20: =AVERAGEIF(Data!M2:M151,Formula_Practice!I20,Data!I2:I151) -> 16621.6 | K20: =LARGE(J20:J26,1) -> 16621.6
A21: 20 | B21: Find the standard deviation of Quantity ordered across all orders (use STDEV.P). | C21: =_xlfn.STDEV.P(Data!G2:G151) -> 2.8260377 | E21: Navya Singh | F21: =SUMIF(Data!C7:C156,Formula_Practice!E21,Data!I7:I156) -> 33600.55 | I21: Thursday | J21: =AVERAGEIF(Data!M3:M152,Formula_Practice!I21,Data!I3:I152) -> 13819.934
A22: 21 | B22: Determine which day of the week (Monday–Sunday) has the HIGHEST average order value (not total — average). | C22: =_xlfn.XLOOKUP(K20,J20:J26,J20:J26,"",0,) -> 16621.6 | E22: Riya Nair | F22: =SUMIF(Data!C8:C157,Formula_Practice!E22,Data!I8:I157) -> 68059.99 | I22: Friday | J22: =AVERAGEIF(Data!M4:M153,Formula_Practice!I22,Data!I4:I153) -> 12923.772
A23: 22 | B23: Find how many customers have a total lifetime spend exceeding 50,000. | C23: =COUNTIF(F16:F54,">50000") -> 17 | E23: Navya Malhotra | F23: =SUMIF(Data!C9:C158,Formula_Practice!E23,Data!I9:I158) -> 67516.58 | I23: Tuesday | J23: =AVERAGEIF(Data!M5:M154,Formula_Practice!I23,Data!I5:I154) -> 8538.9719
A24: 23 | B24: Find how many orders were placed by customers whose CustomerName is longer than 12 characters. | C24: =COUNTIF(Data!N2:N151,">12") -> 35 | E24: Rohan Bhatt | F24: =SUMIF(Data!C10:C159,Formula_Practice!E24,Data!I10:I159) -> 134328.62 | I24: Sunday | J24: =AVERAGEIF(Data!M6:M155,Formula_Practice!I24,Data!I6:I155) -> 11715.435
A25: 24 | B25: Count how many Product names contain the word 'Pack' anywhere in them (wildcard match). | C25: =COUNTIF(Data!F2:F151,"*Pack*") -> 40 | E25: Aryan Chopra | F25: =SUMIF(Data!C11:C160,Formula_Practice!E25,Data!I11:I160) -> 17756.25 | I25: Monday | J25: =AVERAGEIF(Data!M7:M156,Formula_Practice!I25,Data!I7:I156) -> 14641.848
A26: 25 | B26: Find the total revenue for orders placed on the very same weekday as the first order (e.g. if the first order was a Tuesday, sum all Tuesday orders). | C26: =SUMIF(Data!M2:M151,Data!M2,Data!I2:I151) -> 365675.21 | E26: Kiara Reddy | F26: =SUMIF(Data!C12:C161,Formula_Practice!E26,Data!I12:I161) -> 37202.98 | I26: Wednesday | J26: =AVERAGEIF(Data!M8:M157,Formula_Practice!I26,Data!I8:I157) -> 10183.985
E27: Myra Singh | F27: =SUMIF(Data!C13:C162,Formula_Practice!E27,Data!I13:I162) -> 27639.48
B28: Note: All questions refer to the 'Data' sheet (range A2:J151). All order dates fall within 2025. | E28: Ishaan Mehta | F28: =SUMIF(Data!C14:C163,Formula_Practice!E28,Data!I14:I163) -> 51430.12
E29: Reyansh Joshi | F29: =SUMIF(Data!C15:C164,Formula_Practice!E29,Data!I15:I164) -> 61459.61
E30: Diya Reddy | F30: =SUMIF(Data!C16:C165,Formula_Practice!E30,Data!I16:I165) -> 65023.59
E31: Aryan Reddy | F31: =SUMIF(Data!C17:C166,Formula_Practice!E31,Data!I17:I166) -> 9546.39
E32: Advait Joshi | F32: =SUMIF(Data!C18:C167,Formula_Practice!E32,Data!I18:I167) -> 18647.91
E33: Vivaan Nair | F33: =SUMIF(Data!C19:C168,Formula_Practice!E33,Data!I19:I168) -> 31335.75
E34: Krish Joshi | F34: =SUMIF(Data!C20:C169,Formula_Practice!E34,Data!I20:I169) -> 61106.06
E35: Diya Joshi | F35: =SUMIF(Data!C21:C170,Formula_Practice!E35,Data!I21:I170) -> 169717.96
E36: Anika Patel | F36: =SUMIF(Data!C22:C171,Formula_Practice!E36,Data!I22:I171) -> 45515.99
E37: Reyansh Rao | F37: =SUMIF(Data!C23:C172,Formula_Practice!E37,Data!I23:I172) -> 69236.57
E38: Ananya Joshi | F38: =SUMIF(Data!C24:C173,Formula_Practice!E38,Data!I24:I173) -> 87182.16
E39: Ananya Nair | F39: =SUMIF(Data!C25:C174,Formula_Practice!E39,Data!I25:I174) -> 84101.03
E40: Advait Malhotra | F40: =SUMIF(Data!C26:C175,Formula_Practice!E40,Data!I26:I175) -> 51274.97
...
