Workbook

Sheet Data
A1: OrderID | B1: OrderDate | C1: CustomerName | D1: Region | E1: Category | F1: Product | G1: Quantity | H1: UnitPrice | I1: TotalAmount | J1: PaymentMethod | K1: month | L1: weekday | M1: quarter | N1: mod | O1: ans11
A2: ORD3001 | B2: 45668 | C2: Riya Mehta | D2: North | E2: Grocery | F2: Honey Jar | G2: 9 | H2: 1226.86 | I2: =G2*H2 -> 11041.74 | J2: Cash on Delivery | K2: =MONTH(B2) -> 1 | L2: =WEEKDAY(B2,2) -> 6 | M2: =ROUNDUP(MONTH(B2)/3,0) -> 1 | N2: =MOD(G2,2) -> 1 | O2: =SUMPRODUCT(Data!G2:G151,Data!H2:H151)/SUM(Data!G2:G151) -> 2474.6428
A3: ORD3002 | B3: 45821 | C3: Myra Mehta | D3: Central | E3: Electronics | F3: Bluetooth Speaker | G3: 3 | H3: 3188.51 | I3: =G3*H3 -> 9565.53 | K3: =MONTH(B3) -> 6 | L3: =WEEKDAY(B3,2) -> 5 | M3: =ROUNDUP(MONTH(B3)/3,0) -> 2 | N3: =MOD(G3,2) -> 1
A4: ORD3003 | B4: 45828 | C4: Myra Patel | D4: Central | E4: Home | F4: Cushion Cover | G4: 2 | H4: 968.16 | I4: =G4*H4 -> 1936.32 | K4: =MONTH(B4) -> 6 | L4: =WEEKDAY(B4,2) -> 5 | M4: =ROUNDUP(MONTH(B4)/3,0) -> 2 | N4: =MOD(G4,2) -> 0
A5: ORD3004 | B5: 45668 | C5: Anika Nair | D5: East | E5: Stationery | F5: Notebook | G5: 9 | H5: 4508.68 | I5: =G5*H5 -> 40578.12 | J5: Debit Card | K5: =MONTH(B5) -> 1 | L5: =WEEKDAY(B5,2) -> 6 | M5: =ROUNDUP(MONTH(B5)/3,0) -> 1 | N5: =MOD(G5,2) -> 1
A6: ORD3005 | B6: 45866 | C6: Aditya Kumar | D6: Central | E6: Electronics | F6: USB-C Cable | G6: 8 | H6: 2604.75 | I6: =G6*H6 -> 20838 | K6: =MONTH(B6) -> 7 | L6: =WEEKDAY(B6,2) -> 1 | M6: =ROUNDUP(MONTH(B6)/3,0) -> 3 | N6: =MOD(G6,2) -> 0
A7: ORD3006 | B7: 45784 | C7: Vivaan Malhotra | D7: South | E7: Grocery | F7: Green Tea Pack | G7: 8 | H7: 4055.62 | I7: =G7*H7 -> 32444.96 | K7: =MONTH(B7) -> 5 | L7: =WEEKDAY(B7,2) -> 3 | M7: =ROUNDUP(MONTH(B7)/3,0) -> 2 | N7: =MOD(G7,2) -> 0
A8: ORD3007 | B8: 45905 | C8: Anika Reddy | D8: East | E8: Electronics | F8: USB-C Cable | G8: 5 | H8: 318.59 | I8: =G8*H8 -> 1592.95 | J8: Debit Card | K8: =MONTH(B8) -> 9 | L8: =WEEKDAY(B8,2) -> 5 | M8: =ROUNDUP(MONTH(B8)/3,0) -> 3 | N8: =MOD(G8,2) -> 1
A9: ORD3008 | B9: 45745 | C9: Arjun Patel | D9: North | E9: Home | F9: Cushion Cover | G9: 3 | H9: 3767.36 | I9: =G9*H9 -> 11302.08 | J9: Net Banking | K9: =MONTH(B9) -> 3 | L9: =WEEKDAY(B9,2) -> 6 | M9: =ROUNDUP(MONTH(B9)/3,0) -> 1 | N9: =MOD(G9,2) -> 1
A10: ORD3009 | B10: 45683 | C10: Riya Bhatt | D10: South | E10: Grocery | F10: Oats Pack | G10: 1 | H10: 4771.22 | I10: =G10*H10 -> 4771.22 | K10: =MONTH(B10) -> 1 | L10: =WEEKDAY(B10,2) -> 7 | M10: =ROUNDUP(MONTH(B10)/3,0) -> 1 | N10: =MOD(G10,2) -> 1
A11: ORD3010 | B11: 45845 | C11: Pari Joshi | D11: East | E11: Grocery | F11: Oats Pack | G11: 8 | H11: 2968.53 | I11: =G11*H11 -> 23748.24 | K11: =MONTH(B11) -> 7 | L11: =WEEKDAY(B11,2) -> 1 | M11: =ROUNDUP(MONTH(B11)/3,0) -> 3 | N11: =MOD(G11,2) -> 0
A12: ORD3011 | B12: 45902 | C12: Aarav Kumar | D12: South | E12: Grocery | F12: Honey Jar | G12: 5 | H12: 825.66 | I12: =G12*H12 -> 4128.3 | K12: =MONTH(B12) -> 9 | L12: =WEEKDAY(B12,2) -> 2 | M12: =ROUNDUP(MONTH(B12)/3,0) -> 3 | N12: =MOD(G12,2) -> 1
A13: ORD3012 | B13: 45663 | C13: Saanvi Bhatt | D13: South | E13: Electronics | F13: USB-C Cable | G13: 10 | H13: 1731.92 | I13: =G13*H13 -> 17319.2 | J13: Debit Card | K13: =MONTH(B13) -> 1 | L13: =WEEKDAY(B13,2) -> 1 | M13: =ROUNDUP(MONTH(B13)/3,0) -> 1 | N13: =MOD(G13,2) -> 0
A14: ORD3013 | B14: 45957 | C14: Meera Verma | D14: East | E14: Apparel | F14: Denim Jacket | G14: 3 | H14: 838.54 | I14: =G14*H14 -> 2515.62 | J14: Net Banking | K14: =MONTH(B14) -> 10 | L14: =WEEKDAY(B14,2) -> 1 | M14: =ROUNDUP(MONTH(B14)/3,0) -> 4 | N14: =MOD(G14,2) -> 1
A15: ORD3014 | B15: 45706 | C15: Amara Nair | D15: North | E15: Apparel | F15: Denim Jacket | G15: 2 | H15: 4356.58 | I15: =G15*H15 -> 8713.16 | K15: =MONTH(B15) -> 2 | L15: =WEEKDAY(B15,2) -> 2 | M15: =ROUNDUP(MONTH(B15)/3,0) -> 1 | N15: =MOD(G15,2) -> 0
A16: ORD3015 | B16: 45802 | C16: Aarav Rao | D16: East | E16: Grocery | F16: Olive Oil 1L | G16: 7 | H16: 2545.25 | I16: =G16*H16 -> 17816.75 | J16: Debit Card | K16: =MONTH(B16) -> 5 | L16: =WEEKDAY(B16,2) -> 7 | M16: =ROUNDUP(MONTH(B16)/3,0) -> 2 | N16: =MOD(G16,2) -> 1
A17: ORD3016 | B17: 45976 | C17: Aditya Kumar | D17: South | E17: Stationery | F17: Highlighter Pack | G17: 4 | H17: 3593.38 | I17: =G17*H17 -> 14373.52 | J17: Cash on Delivery | K17: =MONTH(B17) -> 11 | L17: =WEEKDAY(B17,2) -> 6 | M17: =ROUNDUP(MONTH(B17)/3,0) -> 4 | N17: =MOD(G17,2) -> 0
A18: ORD3017 | B18: 45681 | C18: Aarav Gupta | D18: Central | E18: Electronics | F18: Wireless Mouse | G18: 7 | H18: 2399.82 | I18: =G18*H18 -> 16798.74 | J18: Credit Card | K18: =MONTH(B18) -> 1 | L18: =WEEKDAY(B18,2) -> 5 | M18: =ROUNDUP(MONTH(B18)/3,0) -> 1 | N18: =MOD(G18,2) -> 1
A19: ORD3018 | B19: 45861 | C19: Ananya Bhatt | D19: South | E19: Stationery | F19: Sticky Notes | G19: 10 | H19: 1671.04 | I19: =G19*H19 -> 16710.4 | J19: Credit Card | K19: =MONTH(B19) -> 7 | L19: =WEEKDAY(B19,2) -> 3 | M19: =ROUNDUP(MONTH(B19)/3,0) -> 3 | N19: =MOD(G19,2) -> 0
A20: ORD3019 | B20: 45783 | C20: Saanvi Bhatt | D20: South | E20: Home | F20: Wall Clock | G20: 9 | H20: 4044.91 | I20: =G20*H20 -> 36404.19 | J20: Net Banking | K20: =MONTH(B20) -> 5 | L20: =WEEKDAY(B20,2) -> 2 | M20: =ROUNDUP(MONTH(B20)/3,0) -> 2 | N20: =MOD(G20,2) -> 1
A21: ORD3020 | B21: 45951 | C21: Kiara Nair | D21: Central | E21: Grocery | F21: Green Tea Pack | G21: 9 | H21: 3034.61 | I21: =G21*H21 -> 27311.49 | J21: UPI | K21: =MONTH(B21) -> 10 | L21: =WEEKDAY(B21,2) -> 2 | M21: =ROUNDUP(MONTH(B21)/3,0) -> 4 | N21: =MOD(G21,2) -> 1
A22: ORD3021 | B22: 45922 | C22: Aarav Kumar | D22: East | E22: Grocery | F22: Honey Jar | G22: 9 | H22: 1069.33 | I22: =G22*H22 -> 9623.97 | J22: Cash on Delivery | K22: =MONTH(B22) -> 9 | L22: =WEEKDAY(B22,2) -> 1 | M22: =ROUNDUP(MONTH(B22)/3,0) -> 3 | N22: =MOD(G22,2) -> 1
A23: ORD3022 | B23: 45824 | C23: Ayaan Verma | D23: East | E23: Electronics | F23: USB-C Cable | G23: 7 | H23: 671.89 | I23: =G23*H23 -> 4703.23 | J23: Credit Card | K23: =MONTH(B23) -> 6 | L23: =WEEKDAY(B23,2) -> 1 | M23: =ROUNDUP(MONTH(B23)/3,0) -> 2 | N23: =MOD(G23,2) -> 1
A24: ORD3023 | B24: 45991 | C24: Amara Bhatt | D24: West | E24: Grocery | F24: Honey Jar | G24: 1 | H24: 3447.49 | I24: =G24*H24 -> 3447.49 | K24: =MONTH(B24) -> 11 | L24: =WEEKDAY(B24,2) -> 7 | M24: =ROUNDUP(MONTH(B24)/3,0) -> 4 | N24: =MOD(G24,2) -> 1
A25: ORD3024 | B25: 45884 | C25: Vihaan Bhatt | D25: Central | E25: Grocery | F25: Oats Pack | G25: 7 | H25: 491.22 | I25: =G25*H25 -> 3438.54 | J25: Credit Card | K25: =MONTH(B25) -> 8 | L25: =WEEKDAY(B25,2) -> 5 | M25: =ROUNDUP(MONTH(B25)/3,0) -> 3 | N25: =MOD(G25,2) -> 1
A26: ORD3025 | B26: 45682 | C26: Anika Nair | D26: North | E26: Stationery | F26: Sticky Notes | G26: 10 | H26: 4113.89 | I26: =G26*H26 -> 41138.9 | K26: =MONTH(B26) -> 1 | L26: =WEEKDAY(B26,2) -> 6 | M26: =ROUNDUP(MONTH(B26)/3,0) -> 1 | N26: =MOD(G26,2) -> 0
A27: ORD3026 | B27: 45876 | C27: Reyansh Gupta | D27: South | E27: Apparel | F27: Wool Socks | G27: 6 | H27: 2510.91 | I27: =G27*H27 -> 15065.46 | K27: =MONTH(B27) -> 8 | L27: =WEEKDAY(B27,2) -> 4 | M27: =ROUNDUP(MONTH(B27)/3,0) -> 3 | N27: =MOD(G27,2) -> 0
A28: ORD3027 | B28: 45993 | C28: Amara Patel | D28: North | E28: Apparel | F28: Denim Jacket | G28: 8 | H28: 1959.18 | I28: =G28*H28 -> 15673.44 | J28: Cash on Delivery | K28: =MONTH(B28) -> 12 | L28: =WEEKDAY(B28,2) -> 2 | M28: =ROUNDUP(MONTH(B28)/3,0) -> 4 | N28: =MOD(G28,2) -> 0
A29: ORD3028 | B29: 45768 | C29: Aditya Reddy | D29: Central | E29: Grocery | F29: Olive Oil 1L | G29: 4 | H29: 2483.82 | I29: =G29*H29 -> 9935.28 | J29: Net Banking | K29: =MONTH(B29) -> 4 | L29: =WEEKDAY(B29,2) -> 1 | M29: =ROUNDUP(MONTH(B29)/3,0) -> 2 | N29: =MOD(G29,2) -> 0
A30: ORD3029 | B30: 45855 | C30: Aarav Kumar | D30: Central | E30: Apparel | F30: Cap | G30: 1 | H30: 935.08 | I30: =G30*H30 -> 935.08 | J30: Debit Card | K30: =MONTH(B30) -> 7 | L30: =WEEKDAY(B30,2) -> 4 | M30: =ROUNDUP(MONTH(B30)/3,0) -> 3 | N30: =MOD(G30,2) -> 1
A31: ORD3030 | B31: 45817 | C31: Arjun Patel | D31: South | E31: Electronics | F31: Webcam | G31: 3 | H31: 535.66 | I31: =G31*H31 -> 1606.98 | J31: UPI | K31: =MONTH(B31) -> 6 | L31: =WEEKDAY(B31,2) -> 1 | M31: =ROUNDUP(MONTH(B31)/3,0) -> 2 | N31: =MOD(G31,2) -> 1
A32: ORD3031 | B32: 45975 | C32: Saanvi Bhatt | D32: West | E32: Electronics | F32: Bluetooth Speaker | G32: 7 | H32: 1148.22 | I32: =G32*H32 -> 8037.54 | J32: UPI | K32: =MONTH(B32) -> 11 | L32: =WEEKDAY(B32,2) -> 5 | M32: =ROUNDUP(MONTH(B32)/3,0) -> 4 | N32: =MOD(G32,2) -> 1
A33: ORD3032 | B33: 45848 | C33: Saanvi Iyer | D33: South | E33: Home | F33: Table Lamp | G33: 1 | H33: 1712.24 | I33: =G33*H33 -> 1712.24 | J33: UPI | K33: =MONTH(B33) -> 7 | L33: =WEEKDAY(B33,2) -> 4 | M33: =ROUNDUP(MONTH(B33)/3,0) -> 3 | N33: =MOD(G33,2) -> 1
A34: ORD3033 | B34: 45736 | C34: Reyansh Malhotra | D34: South | E34: Stationery | F34: Desk Organizer | G34: 5 | H34: 3623.52 | I34: =G34*H34 -> 18117.6 | J34: Debit Card | K34: =MONTH(B34) -> 3 | L34: =WEEKDAY(B34,2) -> 4 | M34: =ROUNDUP(MONTH(B34)/3,0) -> 1 | N34: =MOD(G34,2) -> 1
A35: ORD3034 | B35: 45859 | C35: Reyansh Gupta | D35: West | E35: Apparel | F35: Wool Socks | G35: 10 | H35: 3378.91 | I35: =G35*H35 -> 33789.1 | K35: =MONTH(B35) -> 7 | L35: =WEEKDAY(B35,2) -> 1 | M35: =ROUNDUP(MONTH(B35)/3,0) -> 3 | N35: =MOD(G35,2) -> 0
A36: ORD3035 | B36: 45747 | C36: Saanvi Bhatt | D36: Central | E36: Home | F36: Table Lamp | G36: 4 | H36: 4879.59 | I36: =G36*H36 -> 19518.36 | J36: Debit Card | K36: =MONTH(B36) -> 3 | L36: =WEEKDAY(B36,2) -> 1 | M36: =ROUNDUP(MONTH(B36)/3,0) -> 1 | N36: =MOD(G36,2) -> 0
A37: ORD3036 | B37: 45675 | C37: Myra Patel | D37: East | E37: Electronics | F37: Wireless Mouse | G37: 9 | H37: 2963.09 | I37: =G37*H37 -> 26667.81 | J37: Net Banking | K37: =MONTH(B37) -> 1 | L37: =WEEKDAY(B37,2) -> 6 | M37: =ROUNDUP(MONTH(B37)/3,0) -> 1 | N37: =MOD(G37,2) -> 1
A38: ORD3037 | B38: 45969 | C38: Aditya Reddy | D38: West | E38: Stationery | F38: Notebook | G38: 9 | H38: 867.23 | I38: =G38*H38 -> 7805.07 | J38: UPI | K38: =MONTH(B38) -> 11 | L38: =WEEKDAY(B38,2) -> 6 | M38: =ROUNDUP(MONTH(B38)/3,0) -> 4 | N38: =MOD(G38,2) -> 1
A39: ORD3038 | B39: 45755 | C39: Reyansh Gupta | D39: East | E39: Electronics | F39: USB-C Cable | G39: 3 | H39: 804.52 | I39: =G39*H39 -> 2413.56 | K39: =MONTH(B39) -> 4 | L39: =WEEKDAY(B39,2) -> 2 | M39: =ROUNDUP(MONTH(B39)/3,0) -> 2 | N39: =MOD(G39,2) -> 1
A40: ORD3039 | B40: 45879 | C40: Arjun Joshi | D40: North | E40: Home | F40: Cushion Cover | G40: 7 | H40: 2104.41 | I40: =G40*H40 -> 14730.87 | J40: Cash on Delivery | K40: =MONTH(B40) -> 8 | L40: =WEEKDAY(B40,2) -> 7 | M40: =ROUNDUP(MONTH(B40)/3,0) -> 3 | N40: =MOD(G40,2) -> 1
...

Sheet Formula_Practice
A1: # | B1: Question | C1: Your Formula / Answer
A2: 1 | B2: The CFO wants total revenue for Q1 2025 (January–March 2025) only. | C2: {=SUM(SUMIF(Data!K:K,{1,2,3},Data!I:I))} -> 557773.38
A3: 2 | B3: Marketing wants to know the month-over-month growth: what % did total revenue change from May 2025 to June 2025? | C3: =(E3-D3)/D3 -> -0.35935691 | D3: =SUMIF(Data!K:K,"=5",Data!I:I) -> 185642.79 | E3: =SUMIF(Data!K:K,"=6",Data!I1) -> 118930.77 | F3: =D3*100 -> 18564279
A4: 3 | B4: Ops flags data quality issues. Count how many orders have a missing (blank) PaymentMethod. | C4: =COUNTBLANK(Data!J2:J151) -> 51
A5: 4 | B5: Classify the first order as 'Low' if TotalAmount < 2000, 'Medium' if between 2000 and 8000, or 'High' if above 8000 (nested IF). | C5: =IF(Data!I2<2000,"Low",IF(Data!I2<=8000,"Medium","High")) -> High
A6: 5 | B6: Combine the first order's CustomerName and Region into one string separated by a hyphen, e.g. 'Riya Singh-North' (use TEXTJOIN or &). | C6: =_xlfn.TEXTJOIN("-",TRUE,Data!C2,Data!D2) -> Riya Mehta-North
A7: 6 | B7: Extract just the first name of the customer in the first order (e.g. 'Riya' from 'Riya Singh'). | C7: =LEFT(Data!C2,FIND(" ",Data!C2)-1) -> Riya
A8: 7 | B8: Find total revenue from all orders EXCLUDING the 'Grocery' category. | C8: =SUMIF(Data!E:E,"<>Grocery",Data!I:I) -> 1747969.7
A9: 8 | B9: Use IFERROR to look up OrderID 'ORD9999' (which doesn't exist) and return 'Not Found' instead of an error. | C9: =IFERROR(_xlfn.XLOOKUP("ORD9999",Data!A:A,Data!C:C),"Not Found") -> Not Found
A10: 9 | B10: Find the rank of the 10th order's (row 11) TotalAmount among all orders, where the highest TotalAmount gets rank 1. | C10: =_xlfn.RANK.EQ(Data!I11,Data!I:I) -> 29 | E10: {=_xlfn.UNIQUE(Data!E:E)} -> Category
A11: 10 | B11: Count how many orders share the exact same OrderDate as the very first order (including itself). | C11: =COUNTIF(Data!B2:B151,Data!B2) -> 2 | E11: Grocery | F11: =SUMIF(Data!E:E,Formula_Practice!E11,Data!I:I) -> 372799.22
A12: 11 | B12: Calculate the weighted average UnitPrice, weighted by Quantity, across all orders (not a simple average). | C12: =SUMPRODUCT(Data!G2:G151,Data!H2:H151)/SUM(Data!G2:G151) -> 2474.6428 | E12: Electronics | F12: =SUMIF(Data!E:E,Formula_Practice!E12,Data!I:I) -> 512817.2
A13: 12 | B13: Identify which single Category generated the highest total revenue overall (return the category name). | C13: Electronics | E13: Home | F13: =SUMIF(Data!E:E,Formula_Practice!E13,Data!I:I) -> 331087.72
A14: 13 | B14: Count how many orders were placed on a weekend (Saturday or Sunday). | C14: {=SUM(COUNTIF(Data!L:L,{6,7}))} -> 42 | E14: Stationery | F14: =SUMIF(Data!E:E,Formula_Practice!E14,Data!I:I) -> 483083.35
A15: 14 | B15: Determine which quarter (Q1, Q2, Q3, or Q4) the first order's date falls into. | C15: =_xlfn.XLOOKUP(Data!B2,Data!B:B,Data!M:M,"") -> 1 | E15: Apparel | F15: =SUMIF(Data!E:E,Formula_Practice!E15,Data!I:I) -> 420981.42
A16: 15 | B16: Count how many orders have a UnitPrice between 1000 and 3000 (inclusive). | C16: =COUNTIFS(Data!H:H,">=1000",Data!H:H,"<=3000") -> 67 | E16: 0 | F16: =SUMIF(Data!E:E,Formula_Practice!E16,Data!I:I) -> 0
A17: 16 | B17: Build a composite Order-Region ID for the first order, formatted as 'OrderID-Region' (e.g. 'ORD3001-North'). | C17: =_xlfn.TEXTJOIN("-",TRUE,Data!A2,Data!D2) -> ORD3001-North
A18: 17 | B18: Finance wants to know potential revenue at risk from very small orders. Find total revenue from orders where TotalAmount is under 500. | C18: =SUMIF(Data!I:I,"<500",Data!I:I) -> 281.38
A19: 18 | B19: Use SUMPRODUCT to find total revenue from orders where CustomerName starts with the letter 'A'. | C19: {=SUMPRODUCT((LEFT(Data!C2:C151,1)="A")*Data!I2:I151)} -> 1048743.1
A20: 19 | B20: Count how many distinct PaymentMethod values were actually used (ignore blanks). | C20: {=COUNTA(_xlfn.UNIQUE(_xlfn._xlws.FILTER(Data!J2:J151,Data!J2:J151<>"")))} -> 5
A21: 20 | B21: Compare total revenue for H1 2025 (Jan–Jun) vs H2 2025 (Jul–Dec) and state which half performed better. | C21: {=SUM(SUMIF(Data!K:K,{1,2,3,4,5,6},Data!I:I))} -> 1030980.8 | D21: {=SUM(SUMIF(Data!K:K,{7,8,9,10,11,12},Data!I:I))} -> 1089788.1 | E21: H2 performed better.
A22: 21 | B22: Find total revenue from orders where Quantity is an even number (use MOD). | C22: =SUMIF(Data!N:N,"=0",Data!I:I) -> 1157356.2
A23: 22 | B23: Data integrity check: is there any OrderID that appears more than once in the dataset? Return the count of duplicate OrderIDs (should be 0 if clean). | C23: =COUNTA(Data!A2:A151)-COUNTA(_xlfn.UNIQUE(Data!A2:A151)) -> 0
B25: Note: All questions refer to the 'Data' sheet (range A2:J151). All order dates fall within 2025.
