Workbook

Sheet Formula Test
A1: Online Learning Platform Formula Test
A2: Use the Data sheet (rows 2-161) as your source. Write one formula per answer cell in column B. | H2: ref ans12
H3: {=_xlfn.UNIQUE(Data!E2:E161)} -> Web Development | I3: =SUMIFS(Data!$I$2:$I$161,Data!$L$2:$L$161,"Completed",Data!$E$2:$E$161,'Formula Test'!H3) -> 84324.21
A4: Q1. Total Price collected from 'Completed' enrollments in the 'Data Science' category. | B4: =SUMIFS(Data!I2:I161,Data!L2:L161,"Completed",Data!E2:E161,"Data Science") -> 25235.14 | H4: Marketing | I4: =SUMIFS(Data!$I$2:$I$161,Data!$L$2:$L$161,"Completed",Data!$E$2:$E$161,'Formula Test'!H4) -> 36250.45
A5: Q2. Count of enrollments with Status='Dropped' and ProgressPct less than 20. | B5: =COUNTIFS(Data!L2:L161,"Dropped",Data!J2:J161,"<20") -> 11 | H5: Design | I5: =SUMIFS(Data!$I$2:$I$161,Data!$L$2:$L$161,"Completed",Data!$E$2:$E$161,'Formula Test'!H5) -> 37381.51
A6: Q3. Look up the Instructor for EnrollID 40055, with a safe fallback if it isn't found. | B6: =_xlfn.XLOOKUP(40055,Data!A2:A161,Data!F2:F161,"",0) -> Neel Chatterjee | H6: Finance | I6: =SUMIFS(Data!$I$2:$I$161,Data!$L$2:$L$161,"Completed",Data!$E$2:$E$161,'Formula Test'!H6) -> 19837.02
A7: Q4. Average Rating for 'Completed' enrollments in 'Excel Mastery'. | B7: =AVERAGEIFS(Data!K2:K161,Data!L2:L161,"Completed",Data!D2:D161,"Excel Mastery") -> 3.2857143 | H7: Data Science | I7: =SUMIFS(Data!$I$2:$I$161,Data!$L$2:$L$161,"Completed",Data!$E$2:$E$161,'Formula Test'!H7) -> 25235.14
A8: Q5. Total Price across the entire dataset for Status != 'Dropped', without adding a helper column. | B8: =SUMIFS(Data!I2:I161,Data!L2:L161,"<>Dropped") -> 315283.89
A9: Q6. Classify EnrollID 40000's ProgressPct as 'Low' (<=30), 'Medium' (31-70), or 'High' (70+). | B9: =IF(Data!J2<=30,"Low",IF(Data!J2<=70,"Medium","High")) -> Low | D9: ref ans22
A10: Q7. Extract the month name and year (e.g. 'March 2025') from the EnrollDate of EnrollID 40020. | B10: =TEXT(Data!B22,"mmmm yyyy") -> May 2025 | D10: {=_xlfn.UNIQUE(Data!E2:E161)} -> Web Development | E10: =COUNTIF(Data!$Q$2:$Q$161,'Formula Test'!D10) -> 14
A11: Q8. Return the Price where Course='Investment Basics' and Platform='Mobile App', using an array-style match (no helper column). | B11: {=SUMPRODUCT((Data!D2:D161="Investment Basics")*(Data!G2:G161="Mobile App"),Data!I2:I161)} -> 15097.35 | D11: Marketing | E11: =COUNTIF(Data!$Q$2:$Q$161,'Formula Test'!D11) -> 6 | H11: ans9
A12: Q9. Return a unique, alphabetically sorted list of all Instructors as a spilled array. | B12: done in right | D12: Design | E12: =COUNTIF(Data!$Q$2:$Q$161,'Formula Test'!D12) -> 10 | H12: {=_xlfn._xlws.SORT(_xlfn.UNIQUE(Data!F2:F161))} -> Alina Fernandes
A13: Q10. Return all EnrollIDs where Level='Advanced' AND Status='Completed', as a spilled array. | B13: done in right | D13: Finance | E13: =COUNTIF(Data!$Q$2:$Q$161,'Formula Test'!D13) -> 5 | H13: Neel Chatterjee
A14: Q11. Count how many Student names contain 'Nambiar' anywhere in the dataset. | B14: =COUNTIF(Data!C2:C161,"*Nambiar*") -> 6 | D14: Data Science | E14: =COUNTIF(Data!$Q$2:$Q$161,'Formula Test'!D14) -> 5 | H14: Omkar Deshmukh
A15: Q12. Find the Category with the highest total Price among 'Completed' enrollments, using formulas only (no pivot table). | B15: {=_xlfn.XLOOKUP(MAX(I3:I7),I3:I7,_xlfn.ANCHORARRAY(H3),"",0)} -> Web Development | H15: Rhea Kapoor
A16: Q13. Calculate the total number of unique Students enrolled in 'Machine Learning Intro'. | B16: {=COUNTA(_xlfn.UNIQUE(_xlfn._xlws.FILTER(Data!C2:C161,Data!D2:D161="Machine Learning Intro","")))} -> 8 | H16: Sara Thomas
A17: Q14. Find the second-highest Price in the entire dataset. | B17: =LARGE(Data!I2:I161,2) -> 4988.77 | H17: Vikram Sethi
A18: Q15. Return the Student name associated with the single highest ProgressPct on record. | B18: =INDEX(Data!C2:C161,MATCH(MAX(Data!J2:J161),Data!J2:J161,0)) -> Rohan Gupta
A19: Q16. Count the number of enrollments made in Q2 2025 (Apr-Jun). | B19: =COUNTIFS(Data!N2:N161,2,Data!O2:O161,2025) -> 31 | H19: ans10
A20: Q17. Calculate the percentage of enrollments with Status='Dropped'. | B20: =COUNTIF(Data!L2:L161,"Dropped")/COUNTA(Data!L2:L161) -> 0.16875 | D20: ans19 | H20: {=_xlfn._xlws.FILTER(Data!A2:A161,(Data!H2:H161="Advanced")*(Data!L2:L161="Completed"))} -> 40003
A21: Q18. Return the most frequently taken Course overall. | B21: {=INDEX(Data!D2:D161,MATCH(MAX(COUNTIF(Data!D2:D161,Data!D2:D161)),COUNTIF(Data!D2:D161,Data!D2:D161),0))} -> Python Basics | D21: {=_xlfn.UNIQUE(Data!G2:G161)} -> Mobile App | E21: =SUMIF(Data!$G$2:$G$161,'Formula Test'!D21,Data!$I$2:$I$161) -> 118045.03 | H21: 40016
A22: Q19. Find the total Price generated by each Platform, broken out into a small 3-row summary table using formulas (not a pivot table). | B22: done in right | D22: Desktop App | E22: =SUMIF(Data!$G$2:$G$161,'Formula Test'!D22,Data!$I$2:$I$161) -> 147533.01 | H22: 40030
A23: Q20. Extract just the day of the week (e.g. 'Monday') for the EnrollDate of EnrollID 40040. | B23: =TEXT(Data!B42,"dddd") -> Friday | D23: Web | E23: =SUMIF(Data!$G$2:$G$161,'Formula Test'!D23,Data!$I$2:$I$161) -> 120699.22 | H23: 40035
A24: Q21. Return the average ProgressPct for enrollments with Price greater than 2500. | B24: =AVERAGEIF(Data!I2:I161,">2500",Data!J2:J161) -> 68.853333 | H24: 40036
A25: Q22. Find the Category that appears most often for enrollments with Rating=5. | B25: {=_xlfn.XLOOKUP(MAX(E10:E14),E10:E14,_xlfn.ANCHORARRAY(D10),"",0)} -> Web Development | D25: ans37 | H25: 40040
A26: Q23. Return the number of distinct Courses taught by 'Rhea Kapoor'. | B26: {=COUNTA(_xlfn.UNIQUE(_xlfn._xlws.FILTER(Data!D2:D161,Data!F2:F161="Rhea Kapoor","")))} -> 3 | D26: {=_xlfn.UNIQUE(Data!F2:F161)} -> Sara Thomas | E26: =AVERAGEIFS(Data!$J$2:$J$161,Data!$F$2:$F$161,'Formula Test'!D26,Data!$L$2:$L$161,"In Progress") -> 42.285714 | H26: 40048
A27: Q24. Calculate the total number of days between EnrollID 40010's EnrollDate and today's date. | B27: =DATEDIF(Data!B12,TODAY(),"D") -> 496 | D27: Omkar Deshmukh | E27: =AVERAGEIFS(Data!$J$2:$J$161,Data!$F$2:$F$161,'Formula Test'!D27,Data!$L$2:$L$161,"In Progress") -> 44.066667 | H27: 40050
A28: Q25. Return TRUE or FALSE for whether every 'Beginner' level enrollment has a Price under 3000. | B28: {=SUMPRODUCT((Data!H2:H161="Beginner")*(Data!I2:I161>=3000))=0} -> FALSE | D28: Neel Chatterjee | E28: =AVERAGEIFS(Data!$J$2:$J$161,Data!$F$2:$F$161,'Formula Test'!D28,Data!$L$2:$L$161,"In Progress") -> 59.857143 | H28: 40058
A29: Q26. Concatenate the Student name and Course into a single string separated by a hyphen for EnrollID 40025 (e.g. 'Aarav Mehta-Excel Mastery'). | B29: =_xlfn.TEXTJOIN("-",TRUE,Data!C27,Data!D27) -> Ritika Sen-Content Strategy | D29: Alina Fernandes | E29: =AVERAGEIFS(Data!$J$2:$J$161,Data!$F$2:$F$161,'Formula Test'!D29,Data!$L$2:$L$161,"In Progress") -> 36 | H29: 40067
A30: Q27. Find the earliest and latest EnrollDate in the dataset, displayed as a single text string like 'Jan 2025 to Dec 2025'. | B30: =_xlfn.TEXTJOIN(" to ",TRUE,C31,C32) -> Jan 2025 to Dec 2025 | C30: ref ans27 | D30: Rhea Kapoor | E30: =AVERAGEIFS(Data!$J$2:$J$161,Data!$F$2:$F$161,'Formula Test'!D30,Data!$L$2:$L$161,"In Progress") -> 45.818182 | H30: 40079
A31: Q28. Return the overall average Price, rounded to the nearest whole number. | B31: =ROUND(AVERAGE(Data!I2:I161),0) -> 2414 | C31: =TEXT(MIN(Data!B2:B161),"mmm yyyy") -> Jan 2025 | D31: Vikram Sethi | E31: =AVERAGEIFS(Data!$J$2:$J$161,Data!$F$2:$F$161,'Formula Test'!D31,Data!$L$2:$L$161,"In Progress") -> 37.75 | H31: 40082
A32: Q29. Find the Instructor with the lowest average Rating (only include instructors with at least 15 enrollments). | B32: {=_xlfn.XLOOKUP(MIN(F34:F39),F34:F39,_xlfn.ANCHORARRAY(D34),"",0)} -> Sara Thomas | C32: =TEXT(MAX(Data!B2:B161),"mmm yyyy") -> Dec 2025 | H32: 40084
A33: Q30. Return the rank (1 = highest) of EnrollID 40005's Price among all enrollments, using RANK.EQ. | B33: =_xlfn.RANK.EQ(Data!I7,Data!I2:I161) -> 115 | D33: ref ans29 | H33: 40087
A34: Q31. Extract just the first word of the Course name for EnrollID 40015 (e.g. 'Excel' from 'Excel Mastery'). | B34: =LEFT(Data!D17,SEARCH(" ",Data!D17,1)-1) -> Digital | D34: {=_xlfn.UNIQUE(Data!F2:F161)} -> Sara Thomas | E34: =COUNTIF(Data!$F$2:$F$161,'Formula Test'!D34) -> 19 | F34: =IF(E34>=15,AVERAGEIF(Data!$F$2:$F$161,'Formula Test'!D34,Data!$K$2:$K$161),"") -> 1.6315789 | H34: 40088
A35: Q32. Calculate the total Price for enrollments made on weekends (Saturday or Sunday) using SUMPRODUCT. | B35: {=SUMPRODUCT((Data!P2:P161="Saturday")+(Data!P2:P161="Sunday"),Data!I2:I161)} -> 115694.65 | D35: Omkar Deshmukh | E35: =COUNTIF(Data!$F$2:$F$161,'Formula Test'!D35) -> 56 | F35: =IF(E35>=15,AVERAGEIF(Data!$F$2:$F$161,'Formula Test'!D35,Data!$K$2:$K$161),"") -> 2 | H35: 40090
A36: Q33. Return the number of enrollments where ProgressPct is an outlier, defined as more than 1.5x the average ProgressPct. | B36: =COUNTIF(Data!J2:J161,">"&1.5*'Formula Test'!D42) -> 0 | D36: Neel Chatterjee | E36: =COUNTIF(Data!$F$2:$F$161,'Formula Test'!D36) -> 19 | F36: =IF(E36>=15,AVERAGEIF(Data!$F$2:$F$161,'Formula Test'!D36,Data!$K$2:$K$161),"") -> 2.1052632 | H36: 40093
A37: Q34. Find the Category that generates the highest average Price per enrollment (minimum 15 enrollments), using formulas only. | B37: {=_xlfn.XLOOKUP(MAX(F46:F50),F46:F50,_xlfn.ANCHORARRAY(D46),"",0)} -> Design | D37: Alina Fernandes | E37: =COUNTIF(Data!$F$2:$F$161,'Formula Test'!D37) -> 14 | F37: =IF(E37>=15,AVERAGEIF(Data!$F$2:$F$161,'Formula Test'!D37,Data!$K$2:$K$161),"") | H37: 40094
A38: Q35. Calculate the completion rate (percentage of 'Completed' status) for each Level, broken out into a small 3-row summary table. | B38: done in right | D38: Rhea Kapoor | E38: =COUNTIF(Data!$F$2:$F$161,'Formula Test'!D38) -> 38 | F38: =IF(E38>=15,AVERAGEIF(Data!$F$2:$F$161,'Formula Test'!D38,Data!$K$2:$K$161),"") -> 1.7631579 | H38: 40103
A39: Q36. Return the number of working days (Mon-Fri) between EnrollID 40008's EnrollDate and today's date, using NETWORKDAYS. | B39: =NETWORKDAYS(Data!B10,TODAY()) -> 187 | D39: Vikram Sethi | E39: =COUNTIF(Data!$F$2:$F$161,'Formula Test'!D39) -> 14 | F39: =IF(E39>=15,AVERAGEIF(Data!$F$2:$F$161,'Formula Test'!D39,Data!$K$2:$K$161),"") | H39: 40106
A40: Q37. Find the Instructor whose students have the highest average ProgressPct among 'In Progress' enrollments only. | B40: {=_xlfn.XLOOKUP(MAX(E26:E31),E26:E31,_xlfn.ANCHORARRAY(D26),"",0)} -> Neel Chatterjee | H40: 40107
...

Sheet Data
A1: EnrollID | B1: EnrollDate | C1: Student | D1: Course | E1: Category | F1: Instructor | G1: Platform | H1: Level | I1: Price | J1: ProgressPct | K1: Rating | L1: Status | N1: q | O1: year | P1: days | Q1: progresspct_
A2: 40000 | B2: 45933 | C2: Kavya Nair | D2: Advanced SQL | E2: Web Development | F2: Sara Thomas | G2: Mobile App | H2: Beginner | I2: 1814.46 | J2: 10 | K2: 0 | L2: In Progress | N2: =ROUNDUP(MONTH(B2)/3,0) -> 4 | O2: =YEAR(B2) -> 2025 | P2: =TEXT(B2,"dddd") -> Friday | Q2: =IF(K2=5,E2,"")
A3: 40001 | B3: 45720 | C3: Devansh Shah | D3: Machine Learning Intro | E3: Marketing | F3: Omkar Deshmukh | G3: Desktop App | H3: Beginner | I3: 1990.7 | J3: 70 | K3: 0 | L3: In Progress | N3: =ROUNDUP(MONTH(B3)/3,0) -> 1 | O3: =YEAR(B3) -> 2025 | P3: =TEXT(B3,"dddd") -> Tuesday | Q3: =IF(K3=5,E3,"")
A4: 40002 | B4: 45956 | C4: Arjun Nambiar | D4: Python Basics | E4: Design | F4: Neel Chatterjee | G4: Desktop App | H4: Intermediate | I4: 1386.91 | J4: 51 | K4: 0 | L4: In Progress | N4: =ROUNDUP(MONTH(B4)/3,0) -> 4 | O4: =YEAR(B4) -> 2025 | P4: =TEXT(B4,"dddd") -> Sunday | Q4: =IF(K4=5,E4,"")
A5: 40003 | B5: 45864 | C5: Rohan Gupta | D5: UI/UX Principles | E5: Finance | F5: Sara Thomas | G5: Mobile App | H5: Advanced | I5: 3474.04 | J5: 100 | K5: 5 | L5: Completed | N5: =ROUNDUP(MONTH(B5)/3,0) -> 3 | O5: =YEAR(B5) -> 2025 | P5: =TEXT(B5,"dddd") -> Saturday | Q5: =IF(K5=5,E5,"") -> Finance
A6: 40004 | B6: 45684 | C6: Karan Malhotra | D6: Python Basics | E6: Design | F6: Neel Chatterjee | G6: Desktop App | H6: Intermediate | I6: 1386.91 | J6: 2 | K6: 0 | L6: Dropped | N6: =ROUNDUP(MONTH(B6)/3,0) -> 1 | O6: =YEAR(B6) -> 2025 | P6: =TEXT(B6,"dddd") -> Monday | Q6: =IF(K6=5,E6,"")
A7: 40005 | B7: 45718 | C7: Sanjay Verma | D7: Python Basics | E7: Design | F7: Neel Chatterjee | G7: Desktop App | H7: Intermediate | I7: 1386.91 | J7: 55 | K7: 0 | L7: In Progress | N7: =ROUNDUP(MONTH(B7)/3,0) -> 1 | O7: =YEAR(B7) -> 2025 | P7: =TEXT(B7,"dddd") -> Sunday | Q7: =IF(K7=5,E7,"")
A8: 40006 | B8: 45991 | C8: Karan Malhotra | D8: Content Strategy | E8: Design | F8: Omkar Deshmukh | G8: Desktop App | H8: Advanced | I8: 2612.49 | J8: 7 | K8: 0 | L8: In Progress | N8: =ROUNDUP(MONTH(B8)/3,0) -> 4 | O8: =YEAR(B8) -> 2025 | P8: =TEXT(B8,"dddd") -> Sunday | Q8: =IF(K8=5,E8,"")
A9: 40007 | B9: 45929 | C9: Ishaan Rao | D9: Figma for Beginners | E9: Web Development | F9: Alina Fernandes | G9: Web | H9: Beginner | I9: 822.47 | J9: 100 | K9: 4 | L9: Completed | N9: =ROUNDUP(MONTH(B9)/3,0) -> 3 | O9: =YEAR(B9) -> 2025 | P9: =TEXT(B9,"dddd") -> Monday | Q9: =IF(K9=5,E9,"")
A10: 40008 | B10: 45952 | C10: Aarav Mehta | D10: Machine Learning Intro | E10: Marketing | F10: Omkar Deshmukh | G10: Web | H10: Beginner | I10: 1990.7 | J10: 26 | K10: 0 | L10: Dropped | N10: =ROUNDUP(MONTH(B10)/3,0) -> 4 | O10: =YEAR(B10) -> 2025 | P10: =TEXT(B10,"dddd") -> Wednesday | Q10: =IF(K10=5,E10,"")
A11: 40009 | B11: 46016 | C11: Aarav Mehta | D11: Machine Learning Intro | E11: Marketing | F11: Omkar Deshmukh | G11: Web | H11: Beginner | I11: 1990.7 | J11: 100 | K11: 0 | L11: Completed | N11: =ROUNDUP(MONTH(B11)/3,0) -> 4 | O11: =YEAR(B11) -> 2025 | P11: =TEXT(B11,"dddd") -> Thursday | Q11: =IF(K11=5,E11,"")
A12: 40010 | B12: 45716 | C12: Ananya Bose | D12: Advanced SQL | E12: Web Development | F12: Sara Thomas | G12: Mobile App | H12: Beginner | I12: 1814.46 | J12: 59 | K12: 0 | L12: In Progress | N12: =ROUNDUP(MONTH(B12)/3,0) -> 1 | O12: =YEAR(B12) -> 2025 | P12: =TEXT(B12,"dddd") -> Friday | Q12: =IF(K12=5,E12,"")
A13: 40011 | B13: 45780 | C13: Sanjay Verma | D13: Advanced SQL | E13: Web Development | F13: Sara Thomas | G13: Web | H13: Beginner | I13: 1814.46 | J13: 8 | K13: 0 | L13: Dropped | N13: =ROUNDUP(MONTH(B13)/3,0) -> 2 | O13: =YEAR(B13) -> 2025 | P13: =TEXT(B13,"dddd") -> Saturday | Q13: =IF(K13=5,E13,"")
... A161: 40159 | B161: 45917 | C161: Nisha Reddy | D161: Investment Basics | E161: Web Development | F161: Rhea Kapoor | G161: Desktop App | H161: Advanced | I161: 3019.47 | J161: 37 | K161: 0 | L161: In Progress | N161: =ROUNDUP(MONTH(B161)/3,0) -> 3 | O161: =YEAR(B161) -> 2025 | P161: =TEXT(B161,"dddd") -> Wednesday | Q161: =IF(K161=5,E161,"")
