Workbook

Sheet Data
A1: Order ID | B1: Order Date | C1: Product | D1: Category | E1: City | F1: Quantity | G1: Price | H1: Status | J1: helper | K1: revenue | L1: month | M1: duplicate | N1: standardize city | O1: standardize status | P1: check data
A2: 1001 | B2: 45739 | C2: Bluetooth Speaker | D2: Electronics | E2: Delhi | F2: 3 | G2: 899 | H2: Completed | J2: =SUMIF(C2:C63,C2,K2:K63) -> 10487 | K2: =F2*G2 -> 2697 | L2: =MONTH(B2) -> 3 | M2: =IF(COUNTIF($A$2:$A$63,A2)>1,"Duplicate","Unique") -> Unique | N2: =PROPER(TRIM(E2)) -> Delhi | O2: =PROPER(TRIM(H2)) -> Completed | P2: =IF(OR(F2<0,F2=""),"Check Data","")
A3: 1002 | B3: 45675 | C3: Bluetooth Speaker | D3: Electronics | E3: Kolkata | F3: 5 | G3: 399 | H3: Cancelled | J3: =SUMIF(C3:C64,C3,K3:K64) -> 7790 | K3: =F3*G3 -> 1995 | L3: =MONTH(B3) -> 1 | M3: =IF(COUNTIF($A$2:$A$63,A3)>1,"Duplicate","Unique") -> Unique | N3: =PROPER(TRIM(E3)) -> Kolkata | O3: =PROPER(TRIM(H3)) -> Cancelled | P3: =IF(OR(F3<0,F3=""),"Check Data","")
A4: 1003 | B4: 45712 | C4: Wireless Mouse | D4: Electronics | E4: Delhi | F4: 1 | G4: 899 | H4: Completed | J4: =SUMIF(C4:C65,C4,K4:K65) -> 35826 | K4: =F4*G4 -> 899 | L4: =MONTH(B4) -> 2 | M4: =IF(COUNTIF($A$2:$A$63,A4)>1,"Duplicate","Unique") -> Unique | N4: =PROPER(TRIM(E4)) -> Delhi | O4: =PROPER(TRIM(H4)) -> Completed | P4: =IF(OR(F4<0,F4=""),"Check Data","")
A5: 1004 | B5: 45722 | C5: Table Fan | D5: Home | E5: delhi | F5: 5 | G5: 899 | H5: Cancelled | J5: =SUMIF(C5:C66,C5,K5:K66) -> 20728 | K5: =F5*G5 -> 4495 | L5: =MONTH(B5) -> 3 | M5: =IF(COUNTIF($A$2:$A$63,A5)>1,"Duplicate","Unique") -> Unique | N5: =PROPER(TRIM(E5)) -> Delhi | O5: =PROPER(TRIM(H5)) -> Cancelled | P5: =IF(OR(F5<0,F5=""),"Check Data","")
A6: 1005 | B6: 45741 | C6: Study Table | D6: Furniture | E6: Pune | F6: 2 | G6: 3499 | H6: Cancelled | J6: =SUMIF(C6:C67,C6,K6:K67) -> 26882 | K6: =F6*G6 -> 6998 | L6: =MONTH(B6) -> 3 | M6: =IF(COUNTIF($A$2:$A$63,A6)>1,"Duplicate","Unique") -> Unique | N6: =PROPER(TRIM(E6)) -> Pune | O6: =PROPER(TRIM(H6)) -> Cancelled | P6: =IF(OR(F6<0,F6=""),"Check Data","") | R6: {=_xlfn.UNIQUE(C2:C41)} -> Bluetooth Speaker | S6: =SUMIF($C$2:$C$63, R6, $K$2:$K$63) -> 10487 | T6: Backpack
A7: 1006 | B7: 45693 | C7: Wireless Mouse | D7: Electronics | E7: Hyderabad | F7: 2 | G7: 2499 | H7: Pending | J7: =SUMIF(C7:C68,C7,K7:K68) -> 34927 | K7: =F7*G7 -> 4998 | L7: =MONTH(B7) -> 2 | M7: =IF(COUNTIF($A$2:$A$63,A7)>1,"Duplicate","Unique") -> Unique | N7: =PROPER(TRIM(E7)) -> Hyderabad | O7: =PROPER(TRIM(H7)) -> Pending | P7: =IF(OR(F7<0,F7=""),"Check Data","") | R7: Wireless Mouse | S7: =SUMIF($C$2:$C$63, R7, $K$2:$K$63) -> 35826 | T7: Notebook Set
A8: 1007 | B8: 45693 | C8: LED Desk Lamp | D8: Home | E8: Mumbai | F8: 3 | G8: 399 | H8: Completed | J8: =SUMIF(C8:C69,C8,K8:K69) -> 21533 | K8: =F8*G8 -> 1197 | L8: =MONTH(B8) -> 2 | M8: =IF(COUNTIF($A$2:$A$63,A8)>1,"Duplicate","Unique") -> Unique | N8: =PROPER(TRIM(E8)) -> Mumbai | O8: =PROPER(TRIM(H8)) -> Completed | P8: =IF(OR(F8<0,F8=""),"Check Data","") | R8: Table Fan | S8: =SUMIF($C$2:$C$63, R8, $K$2:$K$63) -> 20728 | T8: Yoga Mat
A9: 1008 | B9: 45706 | C9: Bluetooth Speaker | D9: Electronics | E9: Bengaluru | F9: 3 | G9: 1199 | H9: Completed | J9: =SUMIF(C9:C70,C9,K9:K70) -> 5795 | K9: =F9*G9 -> 3597 | L9: =MONTH(B9) -> 2 | M9: =IF(COUNTIF($A$2:$A$63,A9)>1,"Duplicate","Unique") -> Unique | N9: =PROPER(TRIM(E9)) -> Bengaluru | O9: =PROPER(TRIM(H9)) -> Completed | P9: =IF(OR(F9<0,F9=""),"Check Data","") | R9: Study Table | S9: =SUMIF($C$2:$C$63, R9, $K$2:$K$63) -> 26882 | T9: Study Table
A10: 1009 | B10: 45751 | C10: Backpack | D10: Accessories | E10: Chennai | G10: 2499 | H10: Completed | J10: =SUMIF(C10:C71,C10,K10:K71) -> 7895 | K10: =F10*G10 -> 0 | L10: =MONTH(B10) -> 4 | M10: =IF(COUNTIF($A$2:$A$63,A10)>1,"Duplicate","Unique") -> Unique | N10: =PROPER(TRIM(E10)) -> Chennai | O10: =PROPER(TRIM(H10)) -> Completed | P10: =IF(OR(F10<0,F10=""),"Check Data","") -> Check Data | R10: LED Desk Lamp | S10: =SUMIF($C$2:$C$63, R10, $K$2:$K$63) -> 21533 | T10: LED Desk Lamp
A11: 1010 | B11: 45728 | C11: Office Chair | D11: Furniture | E11: Hyderabad | F11: 5 | G11: 1499 | H11: Cancelled | J11: =SUMIF(C11:C72,C11,K11:K72) -> 14785 | K11: =F11*G11 -> 7495 | L11: =MONTH(B11) -> 3 | M11: =IF(COUNTIF($A$2:$A$63,A11)>1,"Duplicate","Unique") -> Unique | N11: =PROPER(TRIM(E11)) -> Hyderabad | O11: =PROPER(TRIM(H11)) -> Cancelled | P11: =IF(OR(F11<0,F11=""),"Check Data","") | R11: Backpack | S11: =SUMIF($C$2:$C$63, R11, $K$2:$K$63) -> 7895 | T11: Wireless Mouse
A12: 1011 | B12: 45682 | C12: Bluetooth Speaker | D12: Electronics | E12: Delhi | F12: 2 | G12: 1199 | H12: Completed | J12: =SUMIF(C12:C73,C12,K12:K73) -> 2198 | K12: =F12*G12 -> 2398 | L12: =MONTH(B12) -> 1 | M12: =IF(COUNTIF($A$2:$A$63,A12)>1,"Duplicate","Unique") -> Unique | N12: =PROPER(TRIM(E12)) -> Delhi | O12: =PROPER(TRIM(H12)) -> Completed | P12: =IF(OR(F12<0,F12=""),"Check Data","") | R12: Office Chair | S12: =SUMIF($C$2:$C$63, R12, $K$2:$K$63) -> 14785 | T12: Office Chair
A13: 1012 | B13: 45767 | C13: Yoga Mat | D13: Sports | E13: Hyderabad | F13: 1 | G13: 2499 | H13: Pending | J13: =SUMIF(C13:C74,C13,K13:K74) -> 36428 | K13: =F13*G13 -> 2499 | L13: =MONTH(B13) -> 4 | M13: =IF(COUNTIF($A$2:$A$63,A13)>1,"Duplicate","Unique") -> Unique | N13: =PROPER(TRIM(E13)) -> Hyderabad | O13: =PROPER(TRIM(H13)) -> Pending | P13: =IF(OR(F13<0,F13=""),"Check Data","") | R13: Yoga Mat | S13: =SUMIF($C$2:$C$63, R13, $K$2:$K$63) -> 36428 | T13: Bluetooth Speaker
A14: 1013 | B14: 45716 | C14: Notebook Set | D14: Stationery | E14: Mumbai | F14: 3 | G14: 1499 | H14: Completed | J14: =SUMIF(C14:C75,C14,K14:K75) -> 12893 | K14: =F14*G14 -> 4497 | L14: =MONTH(B14) -> 2 | M14: =IF(COUNTIF($A$2:$A$63,A14)>1,"Duplicate","Unique") -> Unique | N14: =PROPER(TRIM(E14)) -> Mumbai | O14: =PROPER(TRIM(H14)) -> Completed | P14: =IF(OR(F14<0,F14=""),"Check Data","") | R14: Notebook Set | S14: =SUMIF($C$2:$C$63, R14, $K$2:$K$63) -> 12893 | T14: Water Bottle
A15: 1014 | B15: 45743 | C15: Office Chair | D15: Furniture | E15: Kolkata | F15: 1 | G15: 499 | H15: Cancelled | J15: =SUMIF(C15:C76,C15,K15:K76) -> 7290 | K15: =F15*G15 -> 499 | L15: =MONTH(B15) -> 3 | M15: =IF(COUNTIF($A$2:$A$63,A15)>1,"Duplicate","Unique") -> Unique | N15: =PROPER(TRIM(E15)) -> Kolkata | O15: =PROPER(TRIM(H15)) -> Cancelled | P15: =IF(OR(F15<0,F15=""),"Check Data","") | R15: Water Bottle | S15: =SUMIF($C$2:$C$63, R15, $K$2:$K$63) -> 40978 | T15: Table Fan
A16: 1015 | B16: 45751 | C16: Yoga Mat | D16: Sports | E16: Mumbai | F16: 4 | G16: 2499 | H16: Pending | J16: =SUMIF(C16:C77,C16,K16:K77) -> 33929 | K16: =F16*G16 -> 9996 | L16: =MONTH(B16) -> 4 | M16: =IF(COUNTIF($A$2:$A$63,A16)>1,"Duplicate","Unique") -> Unique | N16: =PROPER(TRIM(E16)) -> Mumbai | O16: =PROPER(TRIM(H16)) -> Pending | P16: =IF(OR(F16<0,F16=""),"Check Data","")
A17: 1016 | B17: 45776 | C17: Study Table | D17: Furniture | E17: Mumbai | F17: 3 | G17: 249 | J17: =SUMIF(C17:C78,C17,K17:K78) -> 19884 | K17: =F17*G17 -> 747 | L17: =MONTH(B17) -> 4 | M17: =IF(COUNTIF($A$2:$A$63,A17)>1,"Duplicate","Unique") -> Unique | N17: =PROPER(TRIM(E17)) -> Mumbai | O17: =PROPER(TRIM(H17)) | P17: =IF(OR(F17<0,F17=""),"Check Data","")
A18: 1017 | B18: 45763 | C18: Wireless Mouse | D18: Electronics | E18: Hyderabad | F18: 3 | G18: 2499 | H18: Pending | J18: =SUMIF(C18:C79,C18,K18:K79) -> 29929 | K18: =F18*G18 -> 7497 | L18: =MONTH(B18) -> 4 | M18: =IF(COUNTIF($A$2:$A$63,A18)>1,"Duplicate","Unique") -> Unique | N18: =PROPER(TRIM(E18)) -> Hyderabad | O18: =PROPER(TRIM(H18)) -> Pending | P18: =IF(OR(F18<0,F18=""),"Check Data","")
A19: 1018 | B19: 45666 | C19: Yoga Mat | D19: Sports | E19: Chennai | F19: 3 | G19: 899 | H19: Cancelled | J19: =SUMIF(C19:C80,C19,K19:K80) -> 23933 | K19: =F19*G19 -> 2697 | L19: =MONTH(B19) -> 1 | M19: =IF(COUNTIF($A$2:$A$63,A19)>1,"Duplicate","Unique") -> Unique | N19: =PROPER(TRIM(E19)) -> Chennai | O19: =PROPER(TRIM(H19)) -> Cancelled | P19: =IF(OR(F19<0,F19=""),"Check Data","")
A20: 1019 | B20: 45721 | C20: Water Bottle | D20: Sports | E20: Kolkata | F20: 4 | G20: 499 | H20: Pending | J20: =SUMIF(C20:C81,C20,K20:K81) -> 40978 | K20: =F20*G20 -> 1996 | L20: =MONTH(B20) -> 3 | M20: =IF(COUNTIF($A$2:$A$63,A20)>1,"Duplicate","Unique") -> Unique | N20: =PROPER(TRIM(E20)) -> Kolkata | O20: =PROPER(TRIM(H20)) -> Pending | P20: =IF(OR(F20<0,F20=""),"Check Data","")
A21: 1020 | B21: 45675 | C21: Yoga Mat | D21: Sports | E21: Kolkata | F21: 5 | G21: 1199 | H21: Cancelled | J21: =SUMIF(C21:C82,C21,K21:K82) -> 21236 | K21: =F21*G21 -> 5995 | L21: =MONTH(B21) -> 1 | M21: =IF(COUNTIF($A$2:$A$63,A21)>1,"Duplicate","Unique") -> Unique | N21: =PROPER(TRIM(E21)) -> Kolkata | O21: =PROPER(TRIM(H21)) -> Cancelled | P21: =IF(OR(F21<0,F21=""),"Check Data","") | Q21: Row Labels | R21: Count of Order ID
A22: 1021 | B22: 45732 | C22: Water Bottle | D22: Sports | E22: MUMBAI | F22: 4 | G22: 1499 | H22: Completed | J22: =SUMIF(C22:C83,C22,K22:K83) -> 38982 | K22: =F22*G22 -> 5996 | L22: =MONTH(B22) -> 3 | M22: =IF(COUNTIF($A$2:$A$63,A22)>1,"Duplicate","Unique") -> Unique | N22: =PROPER(TRIM(E22)) -> Mumbai | O22: =PROPER(TRIM(H22)) -> Completed | P22: =IF(OR(F22<0,F22=""),"Check Data","") | Q22: Cancelled | R22: 19
A23: 1022 | B23: 45675 | C23: Study Table | D23: Furniture | E23: Pune | F23: 1 | G23: 249 | H23: Completed | J23: =SUMIF(C23:C84,C23,K23:K84) -> 19137 | K23: =F23*G23 -> 249 | L23: =MONTH(B23) -> 1 | M23: =IF(COUNTIF($A$2:$A$63,A23)>1,"Duplicate","Unique") -> Unique | N23: =PROPER(TRIM(E23)) -> Pune | O23: =PROPER(TRIM(H23)) -> Completed | P23: =IF(OR(F23<0,F23=""),"Check Data","") | Q23: Completed | R23: 24
A24: 1023 | B24: 45677 | C24: LED Desk Lamp | D24: Home | E24: Hyderabad | F24: 4 | G24: 399 | H24: Pending | J24: =SUMIF(C24:C85,C24,K24:K85) -> 20336 | K24: =F24*G24 -> 1596 | L24: =MONTH(B24) -> 1 | M24: =IF(COUNTIF($A$2:$A$63,A24)>1,"Duplicate","Unique") -> Unique | N24: =PROPER(TRIM(E24)) -> Hyderabad | O24: =PROPER(TRIM(H24)) -> Pending | P24: =IF(OR(F24<0,F24=""),"Check Data","") | Q24: Pending | R24: 16
A25: 1024 | B25: 45706 | C25: Table Fan | D25: Home | E25: Pune | F25: 5 | G25: 1199 | H25: Cancelled | J25: =SUMIF(C25:C86,C25,K25:K86) -> 16233 | K25: =F25*G25 -> 5995 | L25: =MONTH(B25) -> 2 | M25: =IF(COUNTIF($A$2:$A$63,A25)>1,"Duplicate","Unique") -> Unique | N25: =PROPER(TRIM(E25)) -> Pune | O25: =PROPER(TRIM(H25)) -> Cancelled | P25: =IF(OR(F25<0,F25=""),"Check Data","") | Q25: Grand Total | R25: 59
A26: 1025 | B26: 45768 | C26: Wireless Mouse | D26: Electronics | E26: Kolkata | F26: 1 | G26: 1199 | H26: Cancelled | J26: =SUMIF(C26:C87,C26,K26:K87) -> 22432 | K26: =F26*G26 -> 1199 | L26: =MONTH(B26) -> 4 | M26: =IF(COUNTIF($A$2:$A$63,A26)>1,"Duplicate","Unique") -> Unique | N26: =PROPER(TRIM(E26)) -> Kolkata | O26: =PROPER(TRIM(H26)) -> Cancelled | P26: =IF(OR(F26<0,F26=""),"Check Data","")
A27: 1026 | B27: 45701 | C27: Bluetooth Speaker | D27: Electronics | E27: Bengaluru | F27: -2 | G27: 499 | H27: Pending | J27: =SUMIF(C27:C88,C27,K27:K88) -> -200 | K27: =F27*G27 -> -998 | L27: =MONTH(B27) -> 2 | M27: =IF(COUNTIF($A$2:$A$63,A27)>1,"Duplicate","Unique") -> Unique | N27: =PROPER(TRIM(E27)) -> Bengaluru | O27: =PROPER(TRIM(H27)) -> Pending | P27: =IF(OR(F27<0,F27=""),"Check Data","") -> Check Data
A28: 1027 | B28: 45658 | C28: Office Chair | D28: Furniture | E28: Chennai | F28: 2 | G28: 399 | H28: Cancelled | J28: =SUMIF(C28:C89,C28,K28:K89) -> 6791 | K28: =F28*G28 -> 798 | L28: =MONTH(B28) -> 1 | M28: =IF(COUNTIF($A$2:$A$63,A28)>1,"Duplicate","Unique") -> Unique | N28: =PROPER(TRIM(E28)) -> Chennai | O28: =PROPER(TRIM(H28)) -> Cancelled | P28: =IF(OR(F28<0,F28=""),"Check Data","")
A29: 1028 | B29: 45696 | C29: Study Table | D29: Furniture | E29: Chennai | F29: 2 | G29: 499 | H29: Pending | J29: =SUMIF(C29:C90,C29,K29:K90) -> 18888 | K29: =F29*G29 -> 998 | L29: =MONTH(B29) -> 2 | M29: =IF(COUNTIF($A$2:$A$63,A29)>1,"Duplicate","Unique") -> Unique | N29: =PROPER(TRIM(E29)) -> Chennai | O29: =PROPER(TRIM(H29)) -> Pending | P29: =IF(OR(F29<0,F29=""),"Check Data","")
A30: 1029 | B30: 45755 | C30: LED Desk Lamp | D30: Home | E30: Chennai | F30: 5 | G30: 249 | H30: Cancelled | J30: =SUMIF(C30:C91,C30,K30:K91) -> 18740 | K30: =F30*G30 -> 1245 | L30: =MONTH(B30) -> 4 | M30: =IF(COUNTIF($A$2:$A$63,A30)>1,"Duplicate","Unique") -> Unique | N30: =PROPER(TRIM(E30)) -> Chennai | O30: =PROPER(TRIM(H30)) -> Cancelled | P30: =IF(OR(F30<0,F30=""),"Check Data","")
A31: 1030 | B31: 45699 | C31: Backpack | D31: Accessories | E31: Delhi | F31: 1 | G31: 1499 | H31: Pending | J31: =SUMIF(C31:C92,C31,K31:K92) -> 7895 | K31: =F31*G31 -> 1499 | L31: =MONTH(B31) -> 2 | M31: =IF(COUNTIF($A$2:$A$63,A31)>1,"Duplicate","Unique") -> Unique | N31: =PROPER(TRIM(E31)) -> Delhi | O31: =PROPER(TRIM(H31)) -> Pending | P31: =IF(OR(F31<0,F31=""),"Check Data","") | R31: =COUNTIF(O2:O63,"Cancelled")/COUNTA(O2:O63) -> 0.30645161
A32: 1031 | B32: 45688 | C32: Wireless Mouse | D32: Electronics | E32: Mumbai | F32: 5 | G32: 399 | H32: completed | J32: =SUMIF(C32:C93,C32,K32:K93) -> 21233 | K32: =F32*G32 -> 1995 | L32: =MONTH(B32) -> 1 | M32: =IF(COUNTIF($A$2:$A$63,A32)>1,"Duplicate","Unique") -> Unique | N32: =PROPER(TRIM(E32)) -> Mumbai | O32: =PROPER(TRIM(H32)) -> Completed | P32: =IF(OR(F32<0,F32=""),"Check Data","")
A33: 1032 | B33: 45751 | C33: Backpack | D33: Accessories | E33: Hyderabad | F33: 1 | G33: 499 | H33: Completed | J33: =SUMIF(C33:C94,C33,K33:K94) -> 6396 | K33: =F33*G33 -> 499 | L33: =MONTH(B33) -> 4 | M33: =IF(COUNTIF($A$2:$A$63,A33)>1,"Duplicate","Unique") -> Unique | N33: =PROPER(TRIM(E33)) -> Hyderabad | O33: =PROPER(TRIM(H33)) -> Completed | P33: =IF(OR(F33<0,F33=""),"Check Data","")
A34: 1033 | B34: 45742 | C34: Backpack | D34: Accessories | E34: Chennai | F34: 2 | G34: 1199 | H34: Cancelled | J34: =SUMIF(C34:C95,C34,K34:K95) -> 5897 | K34: =F34*G34 -> 2398 | L34: =MONTH(B34) -> 3 | M34: =IF(COUNTIF($A$2:$A$63,A34)>1,"Duplicate","Unique") -> Unique | N34: =PROPER(TRIM(E34)) -> Chennai | O34: =PROPER(TRIM(H34)) -> Cancelled | P34: =IF(OR(F34<0,F34=""),"Check Data","")
A35: 1034 | B35: 45769 | C35: Table Fan | D35: Home | E35: Pune | F35: 2 | G35: 899 | H35: Cancelled | J35: =SUMIF(C35:C96,C35,K35:K96) -> 10238 | K35: =F35*G35 -> 1798 | L35: =MONTH(B35) -> 4 | M35: =IF(COUNTIF($A$2:$A$63,A35)>1,"Duplicate","Unique") -> Unique | N35: =PROPER(TRIM(E35)) -> Pune | O35: =PROPER(TRIM(H35)) -> Cancelled | P35: =IF(OR(F35<0,F35=""),"Check Data","") | Q35: Row Labels | R35: Count of Order ID
A36: 1035 | B36: 45697 | C36: Water Bottle | D36: Sports | E36: Kolkata | F36: 3 | G36: 3499 | H36: Cancelled | J36: =SUMIF(C36:C97,C36,K36:K97) -> 32986 | K36: =F36*G36 -> 10497 | L36: =MONTH(B36) -> 2 | M36: =IF(COUNTIF($A$2:$A$63,A36)>1,"Duplicate","Unique") -> Unique | N36: =PROPER(TRIM(E36)) -> Kolkata | O36: =PROPER(TRIM(H36)) -> Cancelled | P36: =IF(OR(F36<0,F36=""),"Check Data","") | Q36: Mumbai | R36: 13
A37: 1036 | B37: 45715 | C37: Bluetooth Speaker | D37: Electronics | E37: Bengaluru | F37: 2 | G37: 399 | H37: Pending | J37: =SUMIF(C37:C98,C37,K37:K98) -> 798 | K37: =F37*G37 -> 798 | L37: =MONTH(B37) -> 2 | M37: =IF(COUNTIF($A$2:$A$63,A37)>1,"Duplicate","Unique") -> Unique | N37: =PROPER(TRIM(E37)) -> Bengaluru | O37: =PROPER(TRIM(H37)) -> Pending | P37: =IF(OR(F37<0,F37=""),"Check Data","") | Q37: Kolkata | R37: 11
A38: 1037 | B38: 45660 | C38: Table Fan | D38: Home | E38: Chennai | F38: 2 | G38: 899 | H38: Completed | J38: =SUMIF(C38:C99,C38,K38:K99) -> 8440 | K38: =F38*G38 -> 1798 | L38: =MONTH(B38) -> 1 | M38: =IF(COUNTIF($A$2:$A$63,A38)>1,"Duplicate","Unique") -> Unique | N38: =PROPER(TRIM(E38)) -> Chennai | O38: =PROPER(TRIM(H38)) -> Completed | P38: =IF(OR(F38<0,F38=""),"Check Data","") | Q38: Delhi | R38: 9
A39: 1038 | B39: 45667 | C39: Wireless Mouse | D39: Electronics | E39: Mumbai | F39: 1 | G39: 249 | H39: Pending | J39: =SUMIF(C39:C100,C39,K39:K100) -> 19238 | K39: =F39*G39 -> 249 | L39: =MONTH(B39) -> 1 | M39: =IF(COUNTIF($A$2:$A$63,A39)>1,"Duplicate","Unique") -> Unique | N39: =PROPER(TRIM(E39)) -> Mumbai | O39: =PROPER(TRIM(H39)) -> Pending | P39: =IF(OR(F39<0,F39=""),"Check Data","") | Q39: Hyderabad | R39: 9
A40: 1039 | B40: 45667 | C40: Study Table | D40: Furniture | E40: Mumbai | F40: 3 | G40: 3499 | H40: Completed | J40: =SUMIF(C40:C101,C40,K40:K101) -> 17890 | K40: =F40*G40 -> 10497 | L40: =MONTH(B40) -> 1 | M40: =IF(COUNTIF($A$2:$A$63,A40)>1,"Duplicate","Unique") -> Unique | N40: =PROPER(TRIM(E40)) -> Mumbai | O40: =PROPER(TRIM(H40)) -> Completed | P40: =IF(OR(F40<0,F40=""),"Check Data","") | Q40: Chennai | R40: 8
...

Sheet Advanced Excel Questions
A1: # | B1: Question
A2: 1 | B2: Find the total revenue (Quantity x Price) for all orders. | C2: =SUM(Data!K2:K63) -> 232031
A3: 2 | B3: Find the total revenue for the 'Electronics' category only, using SUMIFS/SUMPRODUCT. | C3: =SUMIFS(Data!K2:K63,Data!D2:D63,"Electronics") -> 46313
A4: 3 | B4: Find the total number of orders placed from Delhi (watch out for spacing/case issues in the City column). | C4: =COUNTIF(Data!E2:E63,"*delhi*") -> 9
A5: 4 | B5: Find total sales for Delhi in January only (two conditions: City and Month). | C5: =SUMIFS(Data!K2:K63,Data!E2:E63,"Delhi",Data!L2:L63,1) -> 12394
A6: 5 | B6: Find the top 5 products by total revenue. | C6: done
A7: 6 | B7: Find all duplicate Order IDs in the data. | C7: done
A8: 7 | B8: Find all rows with missing values (blank Quantity, Product, or Status). | C8: done
A9: 8 | B9: Remove duplicate records and list how many duplicates were found. | C9: 2
A10: 9 | B10: Standardize the City column so that values like 'delhi', ' Delhi ', 'DELHI' all read as 'Delhi'. | C10: done
A11: 10 | B11: Standardize the Status column so that 'completed', 'Completed', 'COMPLETED' all read the same. | C11: done
A12: 11 | B12: Add a calculated column 'Revenue' = Quantity x Price. | C12: done
A13: 12 | B13: Find the number of days between the earliest and latest Order Date. | C13: =MAX(Data!B2:B61)-MIN(Data!B2:B61) -> 120
A14: 13 | B14: Create a Pivot Table showing total Revenue by Category. | C14: done
A15: 14 | B15: Create a Pivot Table showing total number of Orders by City. | C15: done
A16: 15 | B16: Create a Pivot Table showing count of Orders by Status (Completed / Pending / Cancelled). | C16: done
A17: 16 | B17: Using conditional formatting rules (describe them, no need to color), how would you highlight orders with negative Quantity? | C17: I go to conditional formatting option , choose values less than 0 and format them with red color fill.
A18: 17 | B18: Write a formula to flag any row where Quantity is negative or blank as 'Check Data'. | C18: done
A19: 18 | B19: Write an XLOOKUP or INDEX+MATCH formula to find the Price of 'Office Chair'. | C19: =_xlfn.XLOOKUP("Office Chair",Data!C2:C61,Data!G2:G61,"not found",0) -> 1499
A20: 19 | B20: Write a formula using TRIM and PROPER/UPPER to clean the City column. | C20: done
A21: 20 | B21: Summarize your findings in 3-4 bullet points as an MIS report would (e.g. highest revenue category, city with most orders, % cancelled orders). | C21: 31% cancelled orders
C22: Mumbai is with most orders
C23: Sports is the highest revenue category
